Workbook

Sheet Dams
A1: Block 04 dams - levels, capacities and reservoir curves (nine dams)
A3: Dam Name | B3: Crest El (m) | C3: FSL (m) | D3: Reservoir Capacity (Mm³) | E3: QPMF (m³/s) | F3: Hmax (m) | G3: C | H3: Spillway Length (m) | I3: Bed level (m) | J3: Dam height crest-bed (m) | K3: Area at FSL (km²) | L3: Volume at FSL (Mm³) | M3: Curve vs capacity (%) | N3: Area at crest (km²) | O3: Volume at crest (Mm³) | P3: PMP peak level, HMS Basin 3 (m) | Q3: Head over FSL at PMP (m) | R3: PMP peak outflow, HMS Basin 3 (m³/s) | S3: PMP peak inflow, HMS Basin 3 (m³/s)
A4: Hawasinah 02 | B4: 149 | C4: 144 | D4: 11 | E4: 17809 | F4: 5 | G4: 2.1 | H4: 759 | I4: ='Hawasinah 02'!K7 -> 129.5 | J4: =B4-I4 -> 19.5 | K4: ='Hawasinah 02'!K9 -> 1.708 | L4: ='Hawasinah 02'!K10 -> 10.412304 | M4: =L4/D4-1 -> -0.053426875 | N4: ='Hawasinah 02'!K13 -> 2.6613 | O4: ='Hawasinah 02'!K14 -> 21.059784 | P4: 148.99 | Q4: =P4-C4 -> 4.99 | R4: 17751 | S4: 17809
A5: Hawasinah 11 | B5: 256 | C5: 251 | D5: 34 | E5: 11767 | F5: 5 | G5: 2.1 | H5: 501 | I5: ='Hawasinah 11'!K7 -> 216 | J5: =B5-I5 -> 40 | K5: ='Hawasinah 11'!K9 -> 2.5416 | L5: ='Hawasinah 11'!K10 -> 33.172843 | M5: =L5/D5-1 -> -0.024328157 | N5: ='Hawasinah 11'!K13 -> 3.2894 | O5: ='Hawasinah 11'!K14 -> 47.688741 | P5: 255.96 | Q5: =P5-C5 -> 4.96 | R5: 11608 | S5: 11767
A6: Hawasinah UP | B6: 65 | C6: 60 | D6: 81 | E6: 34783 | F6: 5 | G6: 2.1 | H6: 1481 | I6: ='Hawasinah EX'!K7 -> 43.5 | J6: =B6-I6 -> 21.5 | K6: ='Hawasinah EX'!K9 -> 10.7747 | L6: ='Hawasinah EX'!K10 -> 79.21578 | M6: =L6/D6-1 -> -0.022027406 | N6: ='Hawasinah EX'!K13 -> 14.711 | O6: ='Hawasinah EX'!K14 -> 142.7751 | P6: 64.82 | Q6: =P6-C6 -> 4.82 | R6: 32933 | S6: 34603
A7: Shafan 02 | B7: 240 | C7: 235 | D7: 43 | E7: 11086 | F7: 5 | G7: 2.1 | H7: 472 | I7: ='Shafan 02'!K7 -> 202 | J7: =B7-I7 -> 38 | K7: ='Shafan 02'!K9 -> 3.6154 | L7: ='Shafan 02'!K10 -> 41.607208 | M7: =L7/D7-1 -> -0.03239051 | N7: ='Shafan 02'!K13 -> 4.5053 | O7: ='Shafan 02'!K14 -> 61.945173 | P7: 239.84 | Q7: =P7-C7 -> 4.84 | R7: 10556 | S7: 11086
A8: Shafan 08 | B8: 173 | C8: 168 | D8: 15 | E8: 15764 | F8: 5 | G8: 2.1 | H8: 671 | I8: ='Shafan 08'!K7 -> 153 | J8: =B8-I8 -> 20 | K8: ='Shafan 08'!K9 -> 2.943 | L8: ='Shafan 08'!K10 -> 13.708941 | M8: =L8/D8-1 -> -0.086070601 | N8: ='Shafan 08'!K13 -> 5.1577 | O8: ='Shafan 08'!K14 -> 33.842288 | P8: 172.7 | Q8: =P8-C8 -> 4.7 | R8: 14380 | S8: 14778
A9: Sarami 03 | B9: 242 | C9: 237 | D9: 45 | E9: 11254 | F9: 5 | G9: 2.1 | H9: 479 | I9: ='Sarami 03'!K7 -> 196.5 | J9: =B9-I9 -> 45.5 | K9: ='Sarami 03'!K9 -> 3.6392 | L9: ='Sarami 03'!K10 -> 42.701356 | M9: =L9/D9-1 -> -0.051080971 | N9: ='Sarami 03'!K13 -> 4.4284 | O9: ='Sarami 03'!K14 -> 62.95578 | P9: 241.84 | Q9: =P9-C9 -> 4.84 | R9: 10732 | S9: 11254
A10: Sarami 05 | B10: 189 | C10: 184 | D10: 15 | E10: 3888 | F10: 5 | G10: 2.1 | H10: 166 | I10: ='Sarami 05'!K7 -> 163 | J10: =B10-I10 -> 26 | K10: ='Sarami 05'!K9 -> 1.722 | L10: ='Sarami 05'!K10 -> 14.523171 | M10: =L10/D10-1 -> -0.03178862 | N10: ='Sarami 05'!K13 -> 2.2069 | O10: ='Sarami 05'!K14 -> 24.341195 | P10: 188.69 | Q10: =P10-C10 -> 4.69 | R10: 3540 | S10: 3888
A11: Sakhin 04 | B11: 127 | C11: 122 | D11: 24 | E11: 7393 | F11: 5 | G11: 2.1 | H11: 315 | I11: ='Sakhin 04'!K7 -> 102 | J11: =B11-I11 -> 25 | K11: ='Sakhin 04'!K9 -> 2.8917 | L11: ='Sakhin 04'!K10 -> 22.605756 | M11: =L11/D11-1 -> -0.058093496 | N11: ='Sakhin 04'!K13 -> 4.1246 | O11: ='Sakhin 04'!K14 -> 40.060516 | P11: 126.78 | Q11: =P11-C11 -> 4.78 | R11: 6919 | S11: 7393
A12: Sakhin 08 (Mehmum) | B12: 144 | C12: 139 | D12: 8 | E12: 4912 | F12: 5 | G12: 2.1 | H12: 209 | I12: ='Sakhin 08'!K7 -> 126.5 | J12: =B12-I12 -> 17.5 | K12: ='Sakhin 08'!K9 -> 1.712 | L12: ='Sakhin 08'!K10 -> 7.462232 | M12: =L12/D12-1 -> -0.067221002 | N12: ='Sakhin 08'!K13 -> 3.0564 | O12: ='Sakhin 08'!K14 -> 19.319114 | P12: 143.84 | Q12: =P12-C12 -> 4.84 | R12: 4681 | S12: 4912
A14: Blue = data. Columns B-H: 'Block 04 Dams.xlsx' / 'Dams updated.shp' (dam design team). Columns I-O: read by formula from the curve sheets.
A15: Columns P, R, S: HEC-HMS 4.12 project HEC_HMS_Block_04, Basin 4 (the hydrology study's dam catchments + nine reservoirs), depth-area analysis 'DA PMP B4', reservoir element at its own analysis point (2026-10-06).
A16: Curves: 10 m DEM 'NSA 5m B04 Res10m' (the HMS terrain) inside the Crest_Level polygon closed by the dam axis; volumes by the conic formula between 0.5 m steps.
A17: Curve volumes at FSL are 2-6 % below the sheet capacities; the sheet values were kept as the reference for the dam team.

Sheet Hawasinah 02
A1: Hawasinah 02 - reservoir elevation-area-volume
A2: Area: 10 m DEM (NSA 5m B04 Res10m) inside the crest polygon, pond connected to the dam axis, 0.5 m steps from bed to crest. Volume: conic formula between steps, dV = dz/3 (A1 + A2 + sqrt(A1 A2)). Column F: volume integrated cell by cell on the DEM (check only). Blue = data.
A3: Elevation (m) | B3: Area (km²) | C3: Area (m²) | D3: ΔV conic (Mm³) | E3: Volume (Mm³) | F3: Volume DEM-integrated (Mm³) | G3: Head above FSL (m) | H3: Head above crest (m) | M3: chart helper: reference lines
A4: 129.5 | B4: 0.0001 | C4: =B4*1000000 -> 100 | D4: 0 | E4: 0 | F4: 0 | G4: =A4-$K$5 -> -14.5 | H4: =A4-$K$6 -> -19.5 | J4: Dam | K4: ="Hawasinah 02" -> Hawasinah 02 | M4: x volume | N4: y FSL | O4: y crest | P4: x area
A5: 130 | B5: 0.0009 | C5: =B5*1000000 -> 900 | D5: =(A5-A4)/3*(C4+C5+SQRT(C4*C5))/1000000 -> 0.00021666667 | E5: =E4+D5 -> 0.00021666667 | F5: 0.0002 | G5: =A5-$K$5 -> -14 | H5: =A5-$K$6 -> -19 | J5: FSL (m) | K5: =Dams!C4 -> 144 | M5: 0 | N5: =K5 -> 144 | O5: =K6 -> 149 | P5: 0
A6: 130.5 | B6: 0.0022 | C6: =B6*1000000 -> 2200 | D6: =(A6-A5)/3*(C5+C6+SQRT(C5*C6))/1000000 -> 0.00075118745 | E6: =E5+D6 -> 0.00096785412 | F6: 0.0011 | G6: =A6-$K$5 -> -13.5 | H6: =A6-$K$6 -> -18.5 | J6: Crest level (m) | K6: =Dams!B4 -> 149 | M6: =K15*1.02 -> 21.48098 | N6: =K5 -> 144 | O6: =K6 -> 149 | P6: =K16*1.02 -> 2.714526
A7: 131 | B7: 0.007 | C7: =B7*1000000 -> 7000 | D7: =(A7-A6)/3*(C6+C7+SQRT(C6*C7))/1000000 -> 0.0021873806 | E7: =E6+D7 -> 0.0031552347 | F7: 0.0032 | G7: =A7-$K$5 -> -13 | H7: =A7-$K$6 -> -18 | J7: Bed level (m) | K7: =A4 -> 129.5 | M7: ="FSL "&TEXT(K5,"0.0")&" m" -> FSL 144.0 m
A8: 131.5 | B8: 0.0224 | C8: =B8*1000000 -> 22400 | D8: =(A8-A7)/3*(C7+C8+SQRT(C7*C8))/1000000 -> 0.0069869968 | E8: =E7+D8 -> 0.010142231 | F8: 0.0103 | G8: =A8-$K$5 -> -12.5 | H8: =A8-$K$6 -> -17.5 | J8: Dam height crest-bed (m) | K8: =K6-K7 -> 19.5 | M8: ="Crest "&TEXT(K6,"0.0")&" m" -> Crest 149.0 m
A9: 132 | B9: 0.0605 | C9: =B9*1000000 -> 60500 | D9: =(A9-A8)/3*(C8+C9+SQRT(C8*C9))/1000000 -> 0.019952174 | E9: =E8+D9 -> 0.030094405 | F9: 0.031 | G9: =A9-$K$5 -> -12 | H9: =A9-$K$6 -> -17 | J9: Area at FSL (km²) | K9: =INDEX(B4:B43,MATCH(K5,A4:A43,0)) -> 1.708 | M9: ="Elevation-volume curve" -> Elevation-volume curve
A10: 132.5 | B10: 0.1278 | C10: =B10*1000000 -> 127800 | D10: =(A10-A9)/3*(C9+C10+SQRT(C9*C10))/1000000 -> 0.046038537 | E10: =E9+D10 -> 0.076132942 | F10: 0.0799 | G10: =A10-$K$5 -> -11.5 | H10: =A10-$K$6 -> -16.5 | J10: Volume at FSL (Mm³) | K10: =INDEX(E4:E43,MATCH(K5,A4:A43,0)) -> 10.412304 | M10: ="Elevation-area curve" -> Elevation-area curve
A11: 133 | B11: 0.2114 | C11: =B11*1000000 -> 211400 | D11: =(A11-A10)/3*(C10+C11+SQRT(C10*C11))/1000000 -> 0.083928041 | E11: =E10+D11 -> 0.16006098 | F11: 0.1665 | G11: =A11-$K$5 -> -11 | H11: =A11-$K$6 -> -16 | J11: Capacity per dams sheet (Mm³) | K11: =Dams!D4 -> 11
A12: 133.5 | B12: 0.2944 | C12: =B12*1000000 -> 294400 | D12: =(A12-A11)/3*(C11+C12+SQRT(C11*C12))/1000000 -> 0.12587863 | E12: =E11+D12 -> 0.28593961 | F12: 0.296 | G12: =A12-$K$5 -> -10.5 | H12: =A12-$K$6 -> -15.5 | J12: Difference (%) | K12: =K10/K11-1 -> -0.053426875
A13: 134 | B13: 0.3725 | C13: =B13*1000000 -> 372500 | D13: =(A13-A12)/3*(C12+C13+SQRT(C12*C13))/1000000 -> 0.16634259 | E13: =E12+D13 -> 0.4522822 | F13: 0.4657 | G13: =A13-$K$5 -> -10 | H13: =A13-$K$6 -> -15 | J13: Area at crest (km²) | K13: =INDEX(B4:B43,MATCH(K6,A4:A43,0)) -> 2.6613
A14: 134.5 | B14: 0.447 | C14: =B14*1000000 -> 447000 | D14: =(A14-A13)/3*(C13+C14+SQRT(C13*C14))/1000000 -> 0.20459222 | E14: =E13+D14 -> 0.65687442 | F14: 0.6722 | G14: =A14-$K$5 -> -9.5 | H14: =A14-$K$6 -> -14.5 | J14: Volume at crest (Mm³) | K14: =INDEX(E4:E43,MATCH(K6,A4:A43,0)) -> 21.059784
A15: 135 | B15: 0.5091 | C15: =B15*1000000 -> 509100 | D15: =(A15-A14)/3*(C14+C15+SQRT(C14*C15))/1000000 -> 0.23885676 | E15: =E14+D15 -> 0.89573118 | F15: 0.9129 | G15: =A15-$K$5 -> -9 | H15: =A15-$K$6 -> -14 | J15: Max volume in table (Mm³) | K15: =MAX(E4:E43) -> 21.059784
A16: 135.5 | B16: 0.5685 | C16: =B16*1000000 -> 568500 | D16: =(A16-A15)/3*(C15+C16+SQRT(C15*C16))/1000000 -> 0.26926347 | E16: =E15+D16 -> 1.1649946 | F16: 1.1843 | G16: =A16-$K$5 -> -8.5 | H16: =A16-$K$6 -> -13.5 | J16: Max area in table (km²) | K16: =MAX(B4:B43) -> 2.6613
A17: 136 | B17: 0.6217 | C17: =B17*1000000 -> 621700 | D17: =(A17-A16)/3*(C16+C17+SQRT(C16*C17))/1000000 -> 0.29745087 | E17: =E16+D17 -> 1.4624455 | F17: 1.4831 | G17: =A17-$K$5 -> -8 | H17: =A17-$K$6 -> -13
A18: 136.5 | B18: 0.6669 | C18: =B18*1000000 -> 666900 | D18: =(A18-A17)/3*(C17+C18+SQRT(C17*C18))/1000000 -> 0.32208392 | E18: =E17+D18 -> 1.7845294 | F18: 1.8053 | G18: =A18-$K$5 -> -7.5 | H18: =A18-$K$6 -> -12.5
A19: 137 | B19: 0.7189 | C19: =B19*1000000 -> 718900 | D19: =(A19-A18)/3*(C18+C19+SQRT(C18*C19))/1000000 -> 0.34636867 | E19: =E18+D19 -> 2.1308981 | F19: 2.1533 | G19: =A19-$K$5 -> -7 | H19: =A19-$K$6 -> -12
A20: 137.5 | B20: 0.7751 | C20: =B20*1000000 -> 775100 | D20: =(A20-A19)/3*(C19+C20+SQRT(C19*C20))/1000000 -> 0.37341188 | E20: =E19+D20 -> 2.50431 | F20: 2.5277 | G20: =A20-$K$5 -> -6.5 | H20: =A20-$K$6 -> -11.5
A21: 138 | B21: 0.8418 | C21: =B21*1000000 -> 841800 | D21: =(A21-A20)/3*(C20+C21+SQRT(C20*C21))/1000000 -> 0.40411031 | E21: =E20+D21 -> 2.9084203 | F21: 2.9332 | G21: =A21-$K$5 -> -6 | H21: =A21-$K$6 -> -11
A22: 138.5 | B22: 0.9074 | C22: =B22*1000000 -> 907400 | D22: =(A22-A21)/3*(C21+C22+SQRT(C21*C22))/1000000 -> 0.43719746 | E22: =E21+D22 -> 3.3456178 | F22: 3.3709 | G22: =A22-$K$5 -> -5.5 | H22: =A22-$K$6 -> -10.5
A23: 139 | B23: 0.9757 | C23: =B23*1000000 -> 975700 | D23: =(A23-A22)/3*(C22+C23+SQRT(C22*C23))/1000000 -> 0.47067175 | E23: =E22+D23 -> 3.8162895 | F23: 3.8439 | G23: =A23-$K$5 -> -5 | H23: =A23-$K$6 -> -10
A24: 139.5 | B24: 1.0332 | C24: =B24*1000000 -> 1033200 | D24: =(A24-A23)/3*(C23+C24+SQRT(C23*C24))/1000000 -> 0.50215641 | E24: =E23+D24 -> 4.3184459 | F24: 4.347 | G24: =A24-$K$5 -> -4.5 | H24: =A24-$K$6 -> -9.5
A25: 140 | B25: 1.0963 | C25: =B25*1000000 -> 1096300 | D25: =(A25-A24)/3*(C24+C25+SQRT(C24*C25))/1000000 -> 0.53229708 | E25: =E24+D25 -> 4.850743 | F25: 4.882 | G25: =A25-$K$5 -> -4 | H25: =A25-$K$6 -> -9
A26: 140.5 | B26: 1.1563 | C26: =B26*1000000 -> 1156300 | D26: =(A26-A25)/3*(C25+C26+SQRT(C25*C26))/1000000 -> 0.5630834 | E26: =E25+D26 -> 5.4138264 | F26: 5.4455 | G26: =A26-$K$5 -> -3.5 | H26: =A26-$K$6 -> -8.5
A27: 141 | B27: 1.2267 | C27: =B27*1000000 -> 1226700 | D27: =(A27-A26)/3*(C26+C27+SQRT(C26*C27))/1000000 -> 0.59566332 | E27: =E26+D27 -> 6.0094897 | F27: 6.0432 | G27: =A27-$K$5 -> -3 | H27: =A27-$K$6 -> -8
A28: 141.5 | B28: 1.2994 | C28: =B28*1000000 -> 1299400 | D28: =(A28-A27)/3*(C27+C28+SQRT(C27*C28))/1000000 -> 0.6314378 | E28: =E27+D28 -> 6.6409275 | F28: 6.6766 | G28: =A28-$K$5 -> -2.5 | H28: =A28-$K$6 -> -7.5
... A43: 149 | B43: 2.6613 | C43: =B43*1000000 -> 2661300 | D43: =(A43-A42)/3*(C42+C43+SQRT(C42*C43))/1000000 -> 1.2966023 | E43: =E42+D43 -> 21.059784 | F43: 21.1259 | G43: =A43-$K$5 -> 5 | H43: =A43-$K$6 -> 0

Sheet Hawasinah 11
A1: Hawasinah 11 - reservoir elevation-area-volume
A2: Area: 10 m DEM (NSA 5m B04 Res10m) inside the crest polygon, pond connected to the dam axis, 0.5 m steps from bed to crest. Volume: conic formula between steps, dV = dz/3 (A1 + A2 + sqrt(A1 A2)). Column F: volume integrated cell by cell on the DEM (check only). Blue = data.
A3: Elevation (m) | B3: Area (km²) | C3: Area (m²) | D3: ΔV conic (Mm³) | E3: Volume (Mm³) | F3: Volume DEM-integrated (Mm³) | G3: Head above FSL (m) | H3: Head above crest (m) | M3: chart helper: reference lines
A4: 216 | B4: 0.0007 | C4: =B4*1000000 -> 700 | D4: 0 | E4: 0 | F4: 0.0001 | G4: =A4-$K$5 -> -35 | H4: =A4-$K$6 -> -40 | J4: Dam | K4: ="Hawasinah 11" -> Hawasinah 11 | M4: x volume | N4: y FSL | O4: y crest | P4: x area
A5: 216.5 | B5: 0.0038 | C5: =B5*1000000 -> 3800 | D5: =(A5-A4)/3*(C4+C5+SQRT(C4*C5))/1000000 -> 0.0010218251 | E5: =E4+D5 -> 0.0010218251 | F5: 0.0011 | G5: =A5-$K$5 -> -34.5 | H5: =A5-$K$6 -> -39.5 | J5: FSL (m) | K5: =Dams!C5 -> 251 | M5: 0 | N5: =K5 -> 251 | O5: =K6 -> 256 | P5: 0
A6: 217 | B6: 0.0113 | C6: =B6*1000000 -> 11300 | D6: =(A6-A5)/3*(C5+C6+SQRT(C5*C6))/1000000 -> 0.0036088103 | E6: =E5+D6 -> 0.0046306354 | F6: 0.005 | G6: =A6-$K$5 -> -34 | H6: =A6-$K$6 -> -39 | J6: Crest level (m) | K6: =Dams!B5 -> 256 | M6: =K15*1.02 -> 48.642516 | N6: =K5 -> 251 | O6: =K6 -> 256 | P6: =K16*1.02 -> 3.355188
A7: 217.5 | B7: 0.0213 | C7: =B7*1000000 -> 21300 | D7: =(A7-A6)/3*(C6+C7+SQRT(C6*C7))/1000000 -> 0.0080190312 | E7: =E6+D7 -> 0.012649667 | F7: 0.0135 | G7: =A7-$K$5 -> -33.5 | H7: =A7-$K$6 -> -38.5 | J7: Bed level (m) | K7: =A4 -> 216 | M7: ="FSL "&TEXT(K5,"0.0")&" m" -> FSL 251.0 m
A8: 218 | B8: 0.031 | C8: =B8*1000000 -> 31000 | D8: =(A8-A7)/3*(C7+C8+SQRT(C7*C8))/1000000 -> 0.012999384 | E8: =E7+D8 -> 0.02564905 | F8: 0.0268 | G8: =A8-$K$5 -> -33 | H8: =A8-$K$6 -> -38 | J8: Dam height crest-bed (m) | K8: =K6-K7 -> 40 | M8: ="Crest "&TEXT(K6,"0.0")&" m" -> Crest 256.0 m
A9: 218.5 | B9: 0.0443 | C9: =B9*1000000 -> 44300 | D9: =(A9-A8)/3*(C8+C9+SQRT(C8*C9))/1000000 -> 0.018726344 | E9: =E8+D9 -> 0.044375394 | F9: 0.0459 | G9: =A9-$K$5 -> -32.5 | H9: =A9-$K$6 -> -37.5 | J9: Area at FSL (km²) | K9: =INDEX(B4:B84,MATCH(K5,A4:A84,0)) -> 2.5416 | M9: ="Elevation-volume curve" -> Elevation-volume curve
A10: 219 | B10: 0.0583 | C10: =B10*1000000 -> 58300 | D10: =(A10-A9)/3*(C9+C10+SQRT(C9*C10))/1000000 -> 0.025570029 | E10: =E9+D10 -> 0.069945423 | F10: 0.0721 | G10: =A10-$K$5 -> -32 | H10: =A10-$K$6 -> -37 | J10: Volume at FSL (Mm³) | K10: =INDEX(E4:E84,MATCH(K5,A4:A84,0)) -> 33.172843 | M10: ="Elevation-area curve" -> Elevation-area curve
A11: 219.5 | B11: 0.0733 | C11: =B11*1000000 -> 73300 | D11: =(A11-A10)/3*(C10+C11+SQRT(C10*C11))/1000000 -> 0.032828529 | E11: =E10+D11 -> 0.10277395 | F11: 0.1054 | G11: =A11-$K$5 -> -31.5 | H11: =A11-$K$6 -> -36.5 | J11: Capacity per dams sheet (Mm³) | K11: =Dams!D5 -> 34
A12: 220 | B12: 0.0909 | C12: =B12*1000000 -> 90900 | D12: =(A12-A11)/3*(C11+C12+SQRT(C11*C12))/1000000 -> 0.04097117 | E12: =E11+D12 -> 0.14374512 | F12: 0.1471 | G12: =A12-$K$5 -> -31 | H12: =A12-$K$6 -> -36 | J12: Difference (%) | K12: =K10/K11-1 -> -0.024328157
A13: 220.5 | B13: 0.1062 | C13: =B13*1000000 -> 106200 | D13: =(A13-A12)/3*(C12+C13+SQRT(C12*C13))/1000000 -> 0.049225439 | E13: =E12+D13 -> 0.19297056 | F13: 0.1965 | G13: =A13-$K$5 -> -30.5 | H13: =A13-$K$6 -> -35.5 | J13: Area at crest (km²) | K13: =INDEX(B4:B84,MATCH(K6,A4:A84,0)) -> 3.2894
A14: 221 | B14: 0.1248 | C14: =B14*1000000 -> 124800 | D14: =(A14-A13)/3*(C13+C14+SQRT(C13*C14))/1000000 -> 0.057687496 | E14: =E13+D14 -> 0.25065806 | F14: 0.2546 | G14: =A14-$K$5 -> -30 | H14: =A14-$K$6 -> -35 | J14: Volume at crest (Mm³) | K14: =INDEX(E4:E84,MATCH(K6,A4:A84,0)) -> 47.688741
A15: 221.5 | B15: 0.141 | C15: =B15*1000000 -> 141000 | D15: =(A15-A14)/3*(C14+C15+SQRT(C14*C15))/1000000 -> 0.066408822 | E15: =E14+D15 -> 0.31706688 | F15: 0.3215 | G15: =A15-$K$5 -> -29.5 | H15: =A15-$K$6 -> -34.5 | J15: Max volume in table (Mm³) | K15: =MAX(E4:E84) -> 47.688741
A16: 222 | B16: 0.1594 | C16: =B16*1000000 -> 159400 | D16: =(A16-A15)/3*(C15+C16+SQRT(C15*C16))/1000000 -> 0.075052996 | E16: =E15+D16 -> 0.39211987 | F16: 0.3968 | G16: =A16-$K$5 -> -29 | H16: =A16-$K$6 -> -34 | J16: Max area in table (km²) | K16: =MAX(B4:B84) -> 3.2894
A17: 222.5 | B17: 0.1788 | C17: =B17*1000000 -> 178800 | D17: =(A17-A16)/3*(C16+C17+SQRT(C16*C17))/1000000 -> 0.084503594 | E17: =E16+D17 -> 0.47662347 | F17: 0.4814 | G17: =A17-$K$5 -> -28.5 | H17: =A17-$K$6 -> -33.5
A18: 223 | B18: 0.1972 | C18: =B18*1000000 -> 197200 | D18: =(A18-A17)/3*(C17+C18+SQRT(C17*C18))/1000000 -> 0.09396246 | E18: =E17+D18 -> 0.57058593 | F18: 0.5758 | G18: =A18-$K$5 -> -28 | H18: =A18-$K$6 -> -33
A19: 223.5 | B19: 0.2153 | C19: =B19*1000000 -> 215300 | D19: =(A19-A18)/3*(C18+C19+SQRT(C18*C19))/1000000 -> 0.10309189 | E19: =E18+D19 -> 0.67367782 | F19: 0.6794 | G19: =A19-$K$5 -> -27.5 | H19: =A19-$K$6 -> -32.5
A20: 224 | B20: 0.2399 | C20: =B20*1000000 -> 239900 | D20: =(A20-A19)/3*(C19+C20+SQRT(C19*C20))/1000000 -> 0.11374457 | E20: =E19+D20 -> 0.78742239 | F20: 0.7937 | G20: =A20-$K$5 -> -27 | H20: =A20-$K$6 -> -32
A21: 224.5 | B21: 0.2624 | C21: =B21*1000000 -> 262400 | D21: =(A21-A20)/3*(C20+C21+SQRT(C20*C21))/1000000 -> 0.12553298 | E21: =E20+D21 -> 0.91295537 | F21: 0.9194 | G21: =A21-$K$5 -> -26.5 | H21: =A21-$K$6 -> -31.5
A22: 225 | B22: 0.2845 | C22: =B22*1000000 -> 284500 | D22: =(A22-A21)/3*(C21+C22+SQRT(C21*C22))/1000000 -> 0.13668777 | E22: =E21+D22 -> 1.0496431 | F22: 1.0564 | G22: =A22-$K$5 -> -26 | H22: =A22-$K$6 -> -31
A23: 225.5 | B23: 0.3069 | C23: =B23*1000000 -> 306900 | D23: =(A23-A22)/3*(C22+C23+SQRT(C22*C23))/1000000 -> 0.14781464 | E23: =E22+D23 -> 1.1974578 | F23: 1.2049 | G23: =A23-$K$5 -> -25.5 | H23: =A23-$K$6 -> -30.5
A24: 226 | B24: 0.3315 | C24: =B24*1000000 -> 331500 | D24: =(A24-A23)/3*(C23+C24+SQRT(C23*C24))/1000000 -> 0.15956049 | E24: =E23+D24 -> 1.3570183 | F24: 1.3657 | G24: =A24-$K$5 -> -25 | H24: =A24-$K$6 -> -30
A25: 226.5 | B25: 0.3574 | C25: =B25*1000000 -> 357400 | D25: =(A25-A24)/3*(C24+C25+SQRT(C24*C25))/1000000 -> 0.17218441 | E25: =E24+D25 -> 1.5292027 | F25: 1.5381 | G25: =A25-$K$5 -> -24.5 | H25: =A25-$K$6 -> -29.5
A26: 227 | B26: 0.3829 | C26: =B26*1000000 -> 382900 | D26: =(A26-A25)/3*(C25+C26+SQRT(C25*C26))/1000000 -> 0.18503839 | E26: =E25+D26 -> 1.7142411 | F26: 1.7237 | G26: =A26-$K$5 -> -24 | H26: =A26-$K$6 -> -29
A27: 227.5 | B27: 0.4093 | C27: =B27*1000000 -> 409300 | D27: =(A27-A26)/3*(C26+C27+SQRT(C26*C27))/1000000 -> 0.19801333 | E27: =E26+D27 -> 1.9122544 | F27: 1.9219 | G27: =A27-$K$5 -> -23.5 | H27: =A27-$K$6 -> -28.5
A28: 228 | B28: 0.4329 | C28: =B28*1000000 -> 432900 | D28: =(A28-A27)/3*(C27+C28+SQRT(C27*C28))/1000000 -> 0.21052244 | E28: =E27+D28 -> 2.1227768 | F28: 2.1326 | G28: =A28-$K$5 -> -23 | H28: =A28-$K$6 -> -28
... A84: 256 | B84: 3.2894 | C84: =B84*1000000 -> 3289400 | D84: =(A84-A83)/3*(C83+C84+SQRT(C83*C84))/1000000 -> 1.6243075 | E84: =E83+D84 -> 47.688741 | F84: 47.7495 | G84: =A84-$K$5 -> 5 | H84: =A84-$K$6 -> 0

Sheet Hawasinah EX
A1: Hawasinah EX - reservoir elevation-area-volume
A2: Area: 10 m DEM (NSA 5m B04 Res10m) inside the crest polygon, pond connected to the dam axis, 0.5 m steps from bed to crest. Volume: conic formula between steps, dV = dz/3 (A1 + A2 + sqrt(A1 A2)). Column F: volume integrated cell by cell on the DEM (check only). Blue = data.
A3: Elevation (m) | B3: Area (km²) | C3: Area (m²) | D3: ΔV conic (Mm³) | E3: Volume (Mm³) | F3: Volume DEM-integrated (Mm³) | G3: Head above FSL (m) | H3: Head above crest (m) | M3: chart helper: reference lines
A4: 43.5 | B4: 0.0002 | C4: =B4*1000000 -> 200 | D4: 0 | E4: 0 | F4: 0 | G4: =A4-$K$5 -> -16.5 | H4: =A4-$K$6 -> -21.5 | J4: Dam | K4: ="Hawasinah EX" -> Hawasinah EX | M4: x volume | N4: y FSL | O4: y crest | P4: x area
A5: 44 | B5: 0.0091 | C5: =B5*1000000 -> 9100 | D5: =(A5-A4)/3*(C4+C5+SQRT(C4*C5))/1000000 -> 0.0017748456 | E5: =E4+D5 -> 0.0017748456 | F5: 0.0015 | G5: =A5-$K$5 -> -16 | H5: =A5-$K$6 -> -21 | J5: FSL (m) | K5: =Dams!C6 -> 60 | M5: 0 | N5: =K5 -> 60 | O5: =K6 -> 65 | P5: 0
A6: 44.5 | B6: 0.025 | C6: =B6*1000000 -> 25000 | D6: =(A6-A5)/3*(C5+C6+SQRT(C5*C6))/1000000 -> 0.0081971839 | E6: =E5+D6 -> 0.0099720295 | F6: 0.0106 | G6: =A6-$K$5 -> -15.5 | H6: =A6-$K$6 -> -20.5 | J6: Crest level (m) | K6: =Dams!B6 -> 65 | M6: =K15*1.02 -> 145.63061 | N6: =K5 -> 60 | O6: =K6 -> 65 | P6: =K16*1.02 -> 15.00522
A7: 45 | B7: 0.0303 | C7: =B7*1000000 -> 30300 | D7: =(A7-A6)/3*(C6+C7+SQRT(C6*C7))/1000000 -> 0.013803786 | E7: =E6+D7 -> 0.023775816 | F7: 0.0247 | G7: =A7-$K$5 -> -15 | H7: =A7-$K$6 -> -20 | J7: Bed level (m) | K7: =A4 -> 43.5 | M7: ="FSL "&TEXT(K5,"0.0")&" m" -> FSL 60.0 m
A8: 45.5 | B8: 0.3051 | C8: =B8*1000000 -> 305100 | D8: =(A8-A7)/3*(C7+C8+SQRT(C7*C8))/1000000 -> 0.071924746 | E8: =E7+D8 -> 0.095700562 | F8: 0.1166 | G8: =A8-$K$5 -> -14.5 | H8: =A8-$K$6 -> -19.5 | J8: Dam height crest-bed (m) | K8: =K6-K7 -> 21.5 | M8: ="Crest "&TEXT(K6,"0.0")&" m" -> Crest 65.0 m
A9: 46 | B9: 0.8178 | C9: =B9*1000000 -> 817800 | D9: =(A9-A8)/3*(C8+C9+SQRT(C8*C9))/1000000 -> 0.27040176 | E9: =E8+D9 -> 0.36610232 | F9: 0.4227 | G9: =A9-$K$5 -> -14 | H9: =A9-$K$6 -> -19 | J9: Area at FSL (km²) | K9: =INDEX(B4:B47,MATCH(K5,A4:A47,0)) -> 10.7747 | M9: ="Elevation-volume curve" -> Elevation-volume curve
A10: 46.5 | B10: 1.1238 | C10: =B10*1000000 -> 1123800 | D10: =(A10-A9)/3*(C9+C10+SQRT(C9*C10))/1000000 -> 0.48337794 | E10: =E9+D10 -> 0.84948026 | F10: 0.9162 | G10: =A10-$K$5 -> -13.5 | H10: =A10-$K$6 -> -18.5 | J10: Volume at FSL (Mm³) | K10: =INDEX(E4:E47,MATCH(K5,A4:A47,0)) -> 79.21578 | M10: ="Elevation-area curve" -> Elevation-area curve
A11: 47 | B11: 1.4402 | C11: =B11*1000000 -> 1440200 | D11: =(A11-A10)/3*(C10+C11+SQRT(C10*C11))/1000000 -> 0.63936692 | E11: =E10+D11 -> 1.4888472 | F11: 1.5682 | G11: =A11-$K$5 -> -13 | H11: =A11-$K$6 -> -18 | J11: Capacity per dams sheet (Mm³) | K11: =Dams!D6 -> 81
A12: 47.5 | B12: 1.7301 | C12: =B12*1000000 -> 1730100 | D12: =(A12-A11)/3*(C11+C12+SQRT(C11*C12))/1000000 -> 0.79146813 | E12: =E11+D12 -> 2.2803153 | F12: 2.3712 | G12: =A12-$K$5 -> -12.5 | H12: =A12-$K$6 -> -17.5 | J12: Difference (%) | K12: =K10/K11-1 -> -0.022027406
A13: 48 | B13: 2.0865 | C13: =B13*1000000 -> 2086500 | D13: =(A13-A12)/3*(C12+C13+SQRT(C12*C13))/1000000 -> 0.95276025 | E13: =E12+D13 -> 3.2330756 | F13: 3.3334 | G13: =A13-$K$5 -> -12 | H13: =A13-$K$6 -> -17 | J13: Area at crest (km²) | K13: =INDEX(B4:B47,MATCH(K6,A4:A47,0)) -> 14.711
A14: 48.5 | B14: 2.4117 | C14: =B14*1000000 -> 2411700 | D14: =(A14-A13)/3*(C13+C14+SQRT(C13*C14))/1000000 -> 1.1235691 | E14: =E13+D14 -> 4.3566447 | F14: 4.4652 | G14: =A14-$K$5 -> -11.5 | H14: =A14-$K$6 -> -16.5 | J14: Volume at crest (Mm³) | K14: =INDEX(E4:E47,MATCH(K6,A4:A47,0)) -> 142.7751
A15: 49 | B15: 2.7399 | C15: =B15*1000000 -> 2739900 | D15: =(A15-A14)/3*(C14+C15+SQRT(C14*C15))/1000000 -> 1.2870279 | E15: =E14+D15 -> 5.6436726 | F15: 5.7603 | G15: =A15-$K$5 -> -11 | H15: =A15-$K$6 -> -16 | J15: Max volume in table (Mm³) | K15: =MAX(E4:E47) -> 142.7751
A16: 49.5 | B16: 3.0892 | C16: =B16*1000000 -> 3089200 | D16: =(A16-A15)/3*(C15+C16+SQRT(C15*C16))/1000000 -> 1.4564021 | E16: =E15+D16 -> 7.1000747 | F16: 7.2262 | G16: =A16-$K$5 -> -10.5 | H16: =A16-$K$6 -> -15.5 | J16: Max area in table (km²) | K16: =MAX(B4:B47) -> 14.711
A17: 50 | B17: 3.4651 | C17: =B17*1000000 -> 3465100 | D17: =(A17-A16)/3*(C16+C17+SQRT(C16*C17))/1000000 -> 1.637676 | E17: =E16+D17 -> 8.7377506 | F17: 8.8738 | G17: =A17-$K$5 -> -10 | H17: =A17-$K$6 -> -15
A18: 50.5 | B18: 3.8285 | C18: =B18*1000000 -> 3828500 | D18: =(A18-A17)/3*(C17+C18+SQRT(C17*C18))/1000000 -> 1.8226451 | E18: =E17+D18 -> 10.560396 | F18: 10.7043 | G18: =A18-$K$5 -> -9.5 | H18: =A18-$K$6 -> -14.5
A19: 51 | B19: 4.1801 | C19: =B19*1000000 -> 4180100 | D19: =(A19-A18)/3*(C18+C19+SQRT(C18*C19))/1000000 -> 2.0015065 | E19: =E18+D19 -> 12.561902 | F19: 12.7153 | G19: =A19-$K$5 -> -9 | H19: =A19-$K$6 -> -14
A20: 51.5 | B20: 4.5281 | C20: =B20*1000000 -> 4528100 | D20: =(A20-A19)/3*(C19+C20+SQRT(C19*C20))/1000000 -> 2.1764703 | E20: =E19+D20 -> 14.738373 | F20: 14.9022 | G20: =A20-$K$5 -> -8.5 | H20: =A20-$K$6 -> -13.5
A21: 52 | B21: 4.8755 | C21: =B21*1000000 -> 4875500 | D21: =(A21-A20)/3*(C20+C21+SQRT(C20*C21))/1000000 -> 2.3503651 | E21: =E20+D21 -> 17.088738 | F21: 17.2615 | G21: =A21-$K$5 -> -8 | H21: =A21-$K$6 -> -13
A22: 52.5 | B22: 5.2061 | C22: =B22*1000000 -> 5206100 | D22: =(A22-A21)/3*(C21+C22+SQRT(C21*C22))/1000000 -> 2.5199482 | E22: =E21+D22 -> 19.608686 | F22: 19.7858 | G22: =A22-$K$5 -> -7.5 | H22: =A22-$K$6 -> -12.5
A23: 53 | B23: 5.5528 | C23: =B23*1000000 -> 5552800 | D23: =(A23-A22)/3*(C22+C23+SQRT(C22*C23))/1000000 -> 2.6892594 | E23: =E22+D23 -> 22.297945 | F23: 22.4852 | G23: =A23-$K$5 -> -7 | H23: =A23-$K$6 -> -12
A24: 53.5 | B24: 5.9211 | C24: =B24*1000000 -> 5921100 | D24: =(A24-A23)/3*(C23+C24+SQRT(C23*C24))/1000000 -> 2.8679823 | E24: =E23+D24 -> 25.165927 | F24: 25.3645 | G24: =A24-$K$5 -> -6.5 | H24: =A24-$K$6 -> -11.5
A25: 54 | B25: 6.2968 | C25: =B25*1000000 -> 6296800 | D25: =(A25-A24)/3*(C24+C25+SQRT(C24*C25))/1000000 -> 3.0539935 | E25: =E24+D25 -> 28.219921 | F25: 28.4291 | G25: =A25-$K$5 -> -6 | H25: =A25-$K$6 -> -11
A26: 54.5 | B26: 6.6464 | C26: =B26*1000000 -> 6646400 | D26: =(A26-A25)/3*(C25+C26+SQRT(C25*C26))/1000000 -> 3.2354065 | E26: =E25+D26 -> 31.455327 | F26: 31.6703 | G26: =A26-$K$5 -> -5.5 | H26: =A26-$K$6 -> -10.5
A27: 55 | B27: 7.0137 | C27: =B27*1000000 -> 7013700 | D27: =(A27-A26)/3*(C26+C27+SQRT(C26*C27))/1000000 -> 3.4146134 | E27: =E26+D27 -> 34.869941 | F27: 35.095 | G27: =A27-$K$5 -> -5 | H27: =A27-$K$6 -> -10
A28: 55.5 | B28: 7.3923 | C28: =B28*1000000 -> 7392300 | D28: =(A28-A27)/3*(C27+C28+SQRT(C27*C28))/1000000 -> 3.6010854 | E28: =E27+D28 -> 38.471026 | F28: 38.7065 | G28: =A28-$K$5 -> -4.5 | H28: =A28-$K$6 -> -9.5
... A47: 65 | B47: 14.711 | C47: =B47*1000000 -> 14711000 | D47: =(A47-A46)/3*(C46+C47+SQRT(C46*C47))/1000000 -> 7.2514272 | E47: =E46+D47 -> 142.7751 | F47: 143.1917 | G47: =A47-$K$5 -> 5 | H47: =A47-$K$6 -> 0

Sheet Shafan 02
A1: Shafan 02 - reservoir elevation-area-volume
A2: Area: 10 m DEM (NSA 5m B04 Res10m) inside the crest polygon, pond connected to the dam axis, 0.5 m steps from bed to crest. Volume: conic formula between steps, dV = dz/3 (A1 + A2 + sqrt(A1 A2)). Column F: volume integrated cell by cell on the DEM (check only). Blue = data.
A3: Elevation (m) | B3: Area (km²) | C3: Area (m²) | D3: ΔV conic (Mm³) | E3: Volume (Mm³) | F3: Volume DEM-integrated (Mm³) | G3: Head above FSL (m) | H3: Head above crest (m) | M3: chart helper: reference lines
A4: 202 | B4: 0.0013 | C4: =B4*1000000 -> 1300 | D4: 0 | E4: 0 | F4: 0.0002 | G4: =A4-$K$5 -> -33 | H4: =A4-$K$6 -> -38 | J4: Dam | K4: ="Shafan 02" -> Shafan 02 | M4: x volume | N4: y FSL | O4: y crest | P4: x area
A5: 202.5 | B5: 0.0047 | C5: =B5*1000000 -> 4700 | D5: =(A5-A4)/3*(C4+C5+SQRT(C4*C5))/1000000 -> 0.0014119736 | E5: =E4+D5 -> 0.0014119736 | F5: 0.0017 | G5: =A5-$K$5 -> -32.5 | H5: =A5-$K$6 -> -37.5 | J5: FSL (m) | K5: =Dams!C7 -> 235 | M5: 0 | N5: =K5 -> 235 | O5: =K6 -> 240 | P5: 0
A6: 203 | B6: 0.009 | C6: =B6*1000000 -> 9000 | D6: =(A6-A5)/3*(C5+C6+SQRT(C5*C6))/1000000 -> 0.0033673075 | E6: =E5+D6 -> 0.0047792811 | F6: 0.0053 | G6: =A6-$K$5 -> -32 | H6: =A6-$K$6 -> -37 | J6: Crest level (m) | K6: =Dams!B7 -> 240 | M6: =K15*1.02 -> 63.184077 | N6: =K5 -> 235 | O6: =K6 -> 240 | P6: =K16*1.02 -> 4.595406
A7: 203.5 | B7: 0.0135 | C7: =B7*1000000 -> 13500 | D7: =(A7-A6)/3*(C6+C7+SQRT(C6*C7))/1000000 -> 0.0055871173 | E7: =E6+D7 -> 0.010366398 | F7: 0.0109 | G7: =A7-$K$5 -> -31.5 | H7: =A7-$K$6 -> -36.5 | J7: Bed level (m) | K7: =A4 -> 202 | M7: ="FSL "&TEXT(K5,"0.0")&" m" -> FSL 235.0 m
A8: 204 | B8: 0.0199 | C8: =B8*1000000 -> 19900 | D8: =(A8-A7)/3*(C7+C8+SQRT(C7*C8))/1000000 -> 0.0082984243 | E8: =E7+D8 -> 0.018664823 | F8: 0.0193 | G8: =A8-$K$5 -> -31 | H8: =A8-$K$6 -> -36 | J8: Dam height crest-bed (m) | K8: =K6-K7 -> 38 | M8: ="Crest "&TEXT(K6,"0.0")&" m" -> Crest 240.0 m
A9: 204.5 | B9: 0.0258 | C9: =B9*1000000 -> 25800 | D9: =(A9-A8)/3*(C8+C9+SQRT(C8*C9))/1000000 -> 0.011393129 | E9: =E8+D9 -> 0.030057952 | F9: 0.0306 | G9: =A9-$K$5 -> -30.5 | H9: =A9-$K$6 -> -35.5 | J9: Area at FSL (km²) | K9: =INDEX(B4:B80,MATCH(K5,A4:A80,0)) -> 3.6154 | M9: ="Elevation-volume curve" -> Elevation-volume curve
A10: 205 | B10: 0.0301 | C10: =B10*1000000 -> 30100 | D10: =(A10-A9)/3*(C9+C10+SQRT(C9*C10))/1000000 -> 0.013961198 | E10: =E9+D10 -> 0.044019149 | F10: 0.0447 | G10: =A10-$K$5 -> -30 | H10: =A10-$K$6 -> -35 | J10: Volume at FSL (Mm³) | K10: =INDEX(E4:E80,MATCH(K5,A4:A80,0)) -> 41.607208 | M10: ="Elevation-area curve" -> Elevation-area curve
A11: 205.5 | B11: 0.0362 | C11: =B11*1000000 -> 36200 | D11: =(A11-A10)/3*(C10+C11+SQRT(C10*C11))/1000000 -> 0.016551565 | E11: =E10+D11 -> 0.060570715 | F11: 0.0612 | G11: =A11-$K$5 -> -29.5 | H11: =A11-$K$6 -> -34.5 | J11: Capacity per dams sheet (Mm³) | K11: =Dams!D7 -> 43
A12: 206 | B12: 0.0454 | C12: =B12*1000000 -> 45400 | D12: =(A12-A11)/3*(C11+C12+SQRT(C11*C12))/1000000 -> 0.020356643 | E12: =E11+D12 -> 0.080927357 | F12: 0.0815 | G12: =A12-$K$5 -> -29 | H12: =A12-$K$6 -> -34 | J12: Difference (%) | K12: =K10/K11-1 -> -0.03239051
A13: 206.5 | B13: 0.0627 | C13: =B13*1000000 -> 62700 | D13: =(A13-A12)/3*(C12+C13+SQRT(C12*C13))/1000000 -> 0.026908892 | E13: =E12+D13 -> 0.10783625 | F13: 0.1091 | G13: =A13-$K$5 -> -28.5 | H13: =A13-$K$6 -> -33.5 | J13: Area at crest (km²) | K13: =INDEX(B4:B80,MATCH(K6,A4:A80,0)) -> 4.5053
A14: 207 | B14: 0.0789 | C14: =B14*1000000 -> 78900 | D14: =(A14-A13)/3*(C13+C14+SQRT(C13*C14))/1000000 -> 0.035322521 | E14: =E13+D14 -> 0.14315877 | F14: 0.1446 | G14: =A14-$K$5 -> -28 | H14: =A14-$K$6 -> -33 | J14: Volume at crest (Mm³) | K14: =INDEX(E4:E80,MATCH(K6,A4:A80,0)) -> 61.945173
A15: 207.5 | B15: 0.1007 | C15: =B15*1000000 -> 100700 | D15: =(A15-A14)/3*(C14+C15+SQRT(C14*C15))/1000000 -> 0.044789337 | E15: =E14+D15 -> 0.18794811 | F15: 0.1899 | G15: =A15-$K$5 -> -27.5 | H15: =A15-$K$6 -> -32.5 | J15: Max volume in table (Mm³) | K15: =MAX(E4:E80) -> 61.945173
A16: 208 | B16: 0.1211 | C16: =B16*1000000 -> 121100 | D16: =(A16-A15)/3*(C15+C16+SQRT(C15*C16))/1000000 -> 0.055371655 | E16: =E15+D16 -> 0.24331976 | F16: 0.2457 | G16: =A16-$K$5 -> -27 | H16: =A16-$K$6 -> -32 | J16: Max area in table (km²) | K16: =MAX(B4:B80) -> 4.5053
A17: 208.5 | B17: 0.1416 | C17: =B17*1000000 -> 141600 | D17: =(A17-A16)/3*(C16+C17+SQRT(C16*C17))/1000000 -> 0.065608243 | E17: =E16+D17 -> 0.308928 | F17: 0.3116 | G17: =A17-$K$5 -> -26.5 | H17: =A17-$K$6 -> -31.5
A18: 209 | B18: 0.1618 | C18: =B18*1000000 -> 161800 | D18: =(A18-A17)/3*(C17+C18+SQRT(C17*C18))/1000000 -> 0.075793901 | E18: =E17+D18 -> 0.38472191 | F18: 0.3877 | G18: =A18-$K$5 -> -26 | H18: =A18-$K$6 -> -31
A19: 209.5 | B19: 0.1834 | C19: =B19*1000000 -> 183400 | D19: =(A19-A18)/3*(C18+C19+SQRT(C18*C19))/1000000 -> 0.08624363 | E19: =E18+D19 -> 0.47096554 | F19: 0.4742 | G19: =A19-$K$5 -> -25.5 | H19: =A19-$K$6 -> -30.5
A20: 210 | B20: 0.2041 | C20: =B20*1000000 -> 204100 | D20: =(A20-A19)/3*(C19+C20+SQRT(C19*C20))/1000000 -> 0.096828893 | E20: =E19+D20 -> 0.56779443 | F20: 0.571 | G20: =A20-$K$5 -> -25 | H20: =A20-$K$6 -> -30
A21: 210.5 | B21: 0.2291 | C21: =B21*1000000 -> 229100 | D21: =(A21-A20)/3*(C20+C21+SQRT(C20*C21))/1000000 -> 0.10823984 | E21: =E20+D21 -> 0.67603426 | F21: 0.6796 | G21: =A21-$K$5 -> -24.5 | H21: =A21-$K$6 -> -29.5
A22: 211 | B22: 0.2529 | C22: =B22*1000000 -> 252900 | D22: =(A22-A21)/3*(C21+C22+SQRT(C21*C22))/1000000 -> 0.120451 | E22: =E21+D22 -> 0.79648527 | F22: 0.8011 | G22: =A22-$K$5 -> -24 | H22: =A22-$K$6 -> -29
A23: 211.5 | B23: 0.277 | C23: =B23*1000000 -> 277000 | D23: =(A23-A22)/3*(C22+C23+SQRT(C22*C23))/1000000 -> 0.13242931 | E23: =E22+D23 -> 0.92891457 | F23: 0.9341 | G23: =A23-$K$5 -> -23.5 | H23: =A23-$K$6 -> -28.5
A24: 212 | B24: 0.3007 | C24: =B24*1000000 -> 300700 | D24: =(A24-A23)/3*(C23+C24+SQRT(C23*C24))/1000000 -> 0.14438447 | E24: =E23+D24 -> 1.073299 | F24: 1.0792 | G24: =A24-$K$5 -> -23 | H24: =A24-$K$6 -> -28
A25: 212.5 | B25: 0.323 | C25: =B25*1000000 -> 323000 | D25: =(A25-A24)/3*(C24+C25+SQRT(C24*C25))/1000000 -> 0.15589177 | E25: =E24+D25 -> 1.2291908 | F25: 1.2355 | G25: =A25-$K$5 -> -22.5 | H25: =A25-$K$6 -> -27.5
A26: 213 | B26: 0.3522 | C26: =B26*1000000 -> 352200 | D26: =(A26-A25)/3*(C25+C26+SQRT(C25*C26))/1000000 -> 0.16874736 | E26: =E25+D26 -> 1.3979382 | F26: 1.4043 | G26: =A26-$K$5 -> -22 | H26: =A26-$K$6 -> -27
A27: 213.5 | B27: 0.3771 | C27: =B27*1000000 -> 377100 | D27: =(A27-A26)/3*(C26+C27+SQRT(C26*C27))/1000000 -> 0.18228957 | E27: =E26+D27 -> 1.5802277 | F27: 1.5873 | G27: =A27-$K$5 -> -21.5 | H27: =A27-$K$6 -> -26.5
A28: 214 | B28: 0.4048 | C28: =B28*1000000 -> 404800 | D28: =(A28-A27)/3*(C27+C28+SQRT(C27*C28))/1000000 -> 0.1954341 | E28: =E27+D28 -> 1.7756618 | F28: 1.7829 | G28: =A28-$K$5 -> -21 | H28: =A28-$K$6 -> -26
... A80: 240 | B80: 4.5053 | C80: =B80*1000000 -> 4505300 | D80: =(A80-A79)/3*(C79+C80+SQRT(C79*C80))/1000000 -> 2.2326703 | E80: =E79+D80 -> 61.945173 | F80: 62.018 | G80: =A80-$K$5 -> 5 | H80: =A80-$K$6 -> 0

Sheet Shafan 08
A1: Shafan 08 - reservoir elevation-area-volume
A2: Area: 10 m DEM (NSA 5m B04 Res10m) inside the crest polygon, pond connected to the dam axis, 0.5 m steps from bed to crest. Volume: conic formula between steps, dV = dz/3 (A1 + A2 + sqrt(A1 A2)). Column F: volume integrated cell by cell on the DEM (check only). Blue = data.
A3: Elevation (m) | B3: Area (km²) | C3: Area (m²) | D3: ΔV conic (Mm³) | E3: Volume (Mm³) | F3: Volume DEM-integrated (Mm³) | G3: Head above FSL (m) | H3: Head above crest (m) | M3: chart helper: reference lines
A4: 153 | B4: 0.0016 | C4: =B4*1000000 -> 1600 | D4: 0 | E4: 0 | F4: 0.0004 | G4: =A4-$K$5 -> -15 | H4: =A4-$K$6 -> -20 | J4: Dam | K4: ="Shafan 08" -> Shafan 08 | M4: x volume | N4: y FSL | O4: y crest | P4: x area
A5: 153.5 | B5: 0.0044 | C5: =B5*1000000 -> 4400 | D5: =(A5-A4)/3*(C4+C5+SQRT(C4*C5))/1000000 -> 0.0014422166 | E5: =E4+D5 -> 0.0014422166 | F5: 0.0018 | G5: =A5-$K$5 -> -14.5 | H5: =A5-$K$6 -> -19.5 | J5: FSL (m) | K5: =Dams!C8 -> 168 | M5: 0 | N5: =K5 -> 168 | O5: =K6 -> 173 | P5: 0
A6: 154 | B6: 0.0095 | C6: =B6*1000000 -> 9500 | D6: =(A6-A5)/3*(C5+C6+SQRT(C5*C6))/1000000 -> 0.0033942153 | E6: =E5+D6 -> 0.004836432 | F6: 0.0053 | G6: =A6-$K$5 -> -14 | H6: =A6-$K$6 -> -19 | J6: Crest level (m) | K6: =Dams!B8 -> 173 | M6: =K15*1.02 -> 34.519134 | N6: =K5 -> 168 | O6: =K6 -> 173 | P6: =K16*1.02 -> 5.260854
A7: 154.5 | B7: 0.0232 | C7: =B7*1000000 -> 23200 | D7: =(A7-A6)/3*(C6+C7+SQRT(C6*C7))/1000000 -> 0.0079243125 | E7: =E6+D7 -> 0.012760744 | F7: 0.0133 | G7: =A7-$K$5 -> -13.5 | H7: =A7-$K$6 -> -18.5 | J7: Bed level (m) | K7: =A4 -> 153 | M7: ="FSL "&TEXT(K5,"0.0")&" m" -> FSL 168.0 m
A8: 155 | B8: 0.0402 | C8: =B8*1000000 -> 40200 | D8: =(A8-A7)/3*(C7+C8+SQRT(C7*C8))/1000000 -> 0.015656526 | E8: =E7+D8 -> 0.02841727 | F8: 0.0293 | G8: =A8-$K$5 -> -13 | H8: =A8-$K$6 -> -18 | J8: Dam height crest-bed (m) | K8: =K6-K7 -> 20 | M8: ="Crest "&TEXT(K6,"0.0")&" m" -> Crest 173.0 m
A9: 155.5 | B9: 0.0604 | C9: =B9*1000000 -> 60400 | D9: =(A9-A8)/3*(C8+C9+SQRT(C8*C9))/1000000 -> 0.024979259 | E9: =E8+D9 -> 0.053396529 | F9: 0.055 | G9: =A9-$K$5 -> -12.5 | H9: =A9-$K$6 -> -17.5 | J9: Area at FSL (km²) | K9: =INDEX(B4:B44,MATCH(K5,A4:A44,0)) -> 2.943 | M9: ="Elevation-volume curve" -> Elevation-volume curve
A10: 156 | B10: 0.0916 | C10: =B10*1000000 -> 91600 | D10: =(A10-A9)/3*(C9+C10+SQRT(C9*C10))/1000000 -> 0.037730286 | E10: =E9+D10 -> 0.091126815 | F10: 0.094 | G10: =A10-$K$5 -> -12 | H10: =A10-$K$6 -> -17 | J10: Volume at FSL (Mm³) | K10: =INDEX(E4:E44,MATCH(K5,A4:A44,0)) -> 13.708941 | M10: ="Elevation-area curve" -> Elevation-area curve
A11: 156.5 | B11: 0.1237 | C11: =B11*1000000 -> 123700 | D11: =(A11-A10)/3*(C10+C11+SQRT(C10*C11))/1000000 -> 0.053624466 | E11: =E10+D11 -> 0.14475128 | F11: 0.1481 | G11: =A11-$K$5 -> -11.5 | H11: =A11-$K$6 -> -16.5 | J11: Capacity per dams sheet (Mm³) | K11: =Dams!D8 -> 15
A12: 157 | B12: 0.1605 | C12: =B12*1000000 -> 160500 | D12: =(A12-A11)/3*(C11+C12+SQRT(C11*C12))/1000000 -> 0.070850615 | E12: =E11+D12 -> 0.2156019 | F12: 0.2196 | G12: =A12-$K$5 -> -11 | H12: =A12-$K$6 -> -16 | J12: Difference (%) | K12: =K10/K11-1 -> -0.086070601
A13: 157.5 | B13: 0.2039 | C13: =B13*1000000 -> 203900 | D13: =(A13-A12)/3*(C12+C13+SQRT(C12*C13))/1000000 -> 0.090883858 | E13: =E12+D13 -> 0.30648575 | F13: 0.3116 | G13: =A13-$K$5 -> -10.5 | H13: =A13-$K$6 -> -15.5 | J13: Area at crest (km²) | K13: =INDEX(B4:B44,MATCH(K6,A4:A44,0)) -> 5.1577
A14: 158 | B14: 0.2552 | C14: =B14*1000000 -> 255200 | D14: =(A14-A13)/3*(C13+C14+SQRT(C13*C14))/1000000 -> 0.1145354 | E14: =E13+D14 -> 0.42102116 | F14: 0.4269 | G14: =A14-$K$5 -> -10 | H14: =A14-$K$6 -> -15 | J14: Volume at crest (Mm³) | K14: =INDEX(E4:E44,MATCH(K6,A4:A44,0)) -> 33.842288
A15: 158.5 | B15: 0.3145 | C15: =B15*1000000 -> 314500 | D15: =(A15-A14)/3*(C14+C15+SQRT(C14*C15))/1000000 -> 0.14216711 | E15: =E14+D15 -> 0.56318827 | F15: 0.5696 | G15: =A15-$K$5 -> -9.5 | H15: =A15-$K$6 -> -14.5 | J15: Max volume in table (Mm³) | K15: =MAX(E4:E44) -> 33.842288
A16: 159 | B16: 0.3823 | C16: =B16*1000000 -> 382300 | D16: =(A16-A15)/3*(C15+C16+SQRT(C15*C16))/1000000 -> 0.17392447 | E16: =E15+D16 -> 0.73711274 | F16: 0.745 | G16: =A16-$K$5 -> -9 | H16: =A16-$K$6 -> -14 | J16: Max area in table (km²) | K16: =MAX(B4:B44) -> 5.1577
A17: 159.5 | B17: 0.4559 | C17: =B17*1000000 -> 455900 | D17: =(A17-A16)/3*(C16+C17+SQRT(C16*C17))/1000000 -> 0.2092802 | E17: =E16+D17 -> 0.94639294 | F17: 0.9558 | G17: =A17-$K$5 -> -8.5 | H17: =A17-$K$6 -> -13.5
A18: 160 | B18: 0.54 | C18: =B18*1000000 -> 540000 | D18: =(A18-A17)/3*(C17+C18+SQRT(C17*C18))/1000000 -> 0.24867856 | E18: =E17+D18 -> 1.1950715 | F18: 1.2062 | G18: =A18-$K$5 -> -8 | H18: =A18-$K$6 -> -13
A19: 160.5 | B19: 0.626 | C19: =B19*1000000 -> 626000 | D19: =(A19-A18)/3*(C18+C19+SQRT(C18*C19))/1000000 -> 0.29123535 | E19: =E18+D19 -> 1.4863068 | F19: 1.4984 | G19: =A19-$K$5 -> -7.5 | H19: =A19-$K$6 -> -12.5
A20: 161 | B20: 0.7236 | C20: =B20*1000000 -> 723600 | D20: =(A20-A19)/3*(C19+C20+SQRT(C19*C20))/1000000 -> 0.33710552 | E20: =E19+D20 -> 1.8234124 | F20: 1.8377 | G20: =A20-$K$5 -> -7 | H20: =A20-$K$6 -> -12
A21: 161.5 | B21: 0.8308 | C21: =B21*1000000 -> 830800 | D21: =(A21-A20)/3*(C20+C21+SQRT(C20*C21))/1000000 -> 0.38829159 | E21: =E20+D21 -> 2.211704 | F21: 2.2285 | G21: =A21-$K$5 -> -6.5 | H21: =A21-$K$6 -> -11.5
A22: 162 | B22: 0.9326 | C22: =B22*1000000 -> 932600 | D22: =(A22-A21)/3*(C21+C22+SQRT(C21*C22))/1000000 -> 0.44060493 | E22: =E21+D22 -> 2.6523089 | F22: 2.6704 | G22: =A22-$K$5 -> -6 | H22: =A22-$K$6 -> -11
A23: 162.5 | B23: 1.0444 | C23: =B23*1000000 -> 1044400 | D23: =(A23-A22)/3*(C22+C23+SQRT(C22*C23))/1000000 -> 0.49398636 | E23: =E22+D23 -> 3.1462952 | F23: 3.1664 | G23: =A23-$K$5 -> -5.5 | H23: =A23-$K$6 -> -10.5
A24: 163 | B24: 1.1679 | C24: =B24*1000000 -> 1167900 | D24: =(A24-A23)/3*(C23+C24+SQRT(C23*C24))/1000000 -> 0.55278751 | E24: =E23+D24 -> 3.6990828 | F24: 3.7225 | G24: =A24-$K$5 -> -5 | H24: =A24-$K$6 -> -10
A25: 163.5 | B25: 1.3046 | C25: =B25*1000000 -> 1304600 | D25: =(A25-A24)/3*(C24+C25+SQRT(C24*C25))/1000000 -> 0.61780985 | E25: =E24+D25 -> 4.3168926 | F25: 4.3434 | G25: =A25-$K$5 -> -4.5 | H25: =A25-$K$6 -> -9.5
A26: 164 | B26: 1.4704 | C26: =B26*1000000 -> 1470400 | D26: =(A26-A25)/3*(C25+C26+SQRT(C25*C26))/1000000 -> 0.69333687 | E26: =E25+D26 -> 5.0102295 | F26: 5.0411 | G26: =A26-$K$5 -> -4 | H26: =A26-$K$6 -> -9
A27: 164.5 | B27: 1.6394 | C27: =B27*1000000 -> 1639400 | D27: =(A27-A26)/3*(C26+C27+SQRT(C26*C27))/1000000 -> 0.77706704 | E27: =E26+D27 -> 5.7872965 | F27: 5.8207 | G27: =A27-$K$5 -> -3.5 | H27: =A27-$K$6 -> -8.5
A28: 165 | B28: 1.802 | C28: =B28*1000000 -> 1802000 | D28: =(A28-A27)/3*(C27+C28+SQRT(C27*C28))/1000000 -> 0.86002971 | E28: =E27+D28 -> 6.6473262 | F28: 6.685 | G28: =A28-$K$5 -> -3 | H28: =A28-$K$6 -> -8
... A44: 173 | B44: 5.1577 | C44: =B44*1000000 -> 5157700 | D44: =(A44-A43)/3*(C43+C44+SQRT(C43*C44))/1000000 -> 2.5219123 | E44: =E43+D44 -> 33.842288 | F44: 33.9476 | G44: =A44-$K$5 -> 5 | H44: =A44-$K$6 -> 0

Sheet Sarami 03
A1: Sarami 03 - reservoir elevation-area-volume
A2: Area: 10 m DEM (NSA 5m B04 Res10m) inside the crest polygon, pond connected to the dam axis, 0.5 m steps from bed to crest. Volume: conic formula between steps, dV = dz/3 (A1 + A2 + sqrt(A1 A2)). Column F: volume integrated cell by cell on the DEM (check only). Blue = data.
A3: Elevation (m) | B3: Area (km²) | C3: Area (m²) | D3: ΔV conic (Mm³) | E3: Volume (Mm³) | F3: Volume DEM-integrated (Mm³) | G3: Head above FSL (m) | H3: Head above crest (m) | M3: chart helper: reference lines
A4: 196.5 | B4: 0.0023 | C4: =B4*1000000 -> 2300 | D4: 0 | E4: 0 | F4: 0.0005 | G4: =A4-$K$5 -> -40.5 | H4: =A4-$K$6 -> -45.5 | J4: Dam | K4: ="Sarami 03" -> Sarami 03 | M4: x volume | N4: y FSL | O4: y crest | P4: x area
A5: 197 | B5: 0.005 | C5: =B5*1000000 -> 5000 | D5: =(A5-A4)/3*(C4+C5+SQRT(C4*C5))/1000000 -> 0.0017818608 | E5: =E4+D5 -> 0.0017818608 | F5: 0.0025 | G5: =A5-$K$5 -> -40 | H5: =A5-$K$6 -> -45 | J5: FSL (m) | K5: =Dams!C9 -> 237 | M5: 0 | N5: =K5 -> 237 | O5: =K6 -> 242 | P5: 0
A6: 197.5 | B6: 0.0095 | C6: =B6*1000000 -> 9500 | D6: =(A6-A5)/3*(C5+C6+SQRT(C5*C6))/1000000 -> 0.0035653374 | E6: =E5+D6 -> 0.0053471982 | F6: 0.0061 | G6: =A6-$K$5 -> -39.5 | H6: =A6-$K$6 -> -44.5 | J6: Crest level (m) | K6: =Dams!B9 -> 242 | M6: =K15*1.02 -> 64.214896 | N6: =K5 -> 237 | O6: =K6 -> 242 | P6: =K16*1.02 -> 4.516968
A7: 198 | B7: 0.0167 | C7: =B7*1000000 -> 16700 | D7: =(A7-A6)/3*(C6+C7+SQRT(C6*C7))/1000000 -> 0.006465939 | E7: =E6+D7 -> 0.011813137 | F7: 0.0133 | G7: =A7-$K$5 -> -39 | H7: =A7-$K$6 -> -44 | J7: Bed level (m) | K7: =A4 -> 196.5 | M7: ="FSL "&TEXT(K5,"0.0")&" m" -> FSL 237.0 m
A8: 198.5 | B8: 0.0206 | C8: =B8*1000000 -> 20600 | D8: =(A8-A7)/3*(C7+C8+SQRT(C7*C8))/1000000 -> 0.0093079627 | E8: =E7+D8 -> 0.0211211 | F8: 0.0225 | G8: =A8-$K$5 -> -38.5 | H8: =A8-$K$6 -> -43.5 | J8: Dam height crest-bed (m) | K8: =K6-K7 -> 45.5 | M8: ="Crest "&TEXT(K6,"0.0")&" m" -> Crest 242.0 m
A9: 199 | B9: 0.0248 | C9: =B9*1000000 -> 24800 | D9: =(A9-A8)/3*(C8+C9+SQRT(C8*C9))/1000000 -> 0.011333776 | E9: =E8+D9 -> 0.032454876 | F9: 0.034 | G9: =A9-$K$5 -> -38 | H9: =A9-$K$6 -> -43 | J9: Area at FSL (km²) | K9: =INDEX(B4:B95,MATCH(K5,A4:A95,0)) -> 3.6392 | M9: ="Elevation-volume curve" -> Elevation-volume curve
A10: 199.5 | B10: 0.0323 | C10: =B10*1000000 -> 32300 | D10: =(A10-A9)/3*(C9+C10+SQRT(C9*C10))/1000000 -> 0.014233775 | E10: =E9+D10 -> 0.046688651 | F10: 0.0484 | G10: =A10-$K$5 -> -37.5 | H10: =A10-$K$6 -> -42.5 | J10: Volume at FSL (Mm³) | K10: =INDEX(E4:E95,MATCH(K5,A4:A95,0)) -> 42.701356 | M10: ="Elevation-area curve" -> Elevation-area curve
A11: 200 | B11: 0.041 | C11: =B11*1000000 -> 41000 | D11: =(A11-A10)/3*(C10+C11+SQRT(C10*C11))/1000000 -> 0.018281822 | E11: =E10+D11 -> 0.064970473 | F11: 0.067 | G11: =A11-$K$5 -> -37 | H11: =A11-$K$6 -> -42 | J11: Capacity per dams sheet (Mm³) | K11: =Dams!D9 -> 45
A12: 200.5 | B12: 0.0449 | C12: =B12*1000000 -> 44900 | D12: =(A12-A11)/3*(C11+C12+SQRT(C11*C12))/1000000 -> 0.021467618 | E12: =E11+D12 -> 0.086438091 | F12: 0.0886 | G12: =A12-$K$5 -> -36.5 | H12: =A12-$K$6 -> -41.5 | J12: Difference (%) | K12: =K10/K11-1 -> -0.051080971
A13: 201 | B13: 0.0483 | C13: =B13*1000000 -> 48300 | D13: =(A13-A12)/3*(C12+C13+SQRT(C12*C13))/1000000 -> 0.02329483 | E13: =E12+D13 -> 0.10973292 | F13: 0.1118 | G13: =A13-$K$5 -> -36 | H13: =A13-$K$6 -> -41 | J13: Area at crest (km²) | K13: =INDEX(B4:B95,MATCH(K6,A4:A95,0)) -> 4.4284
A14: 201.5 | B14: 0.0558 | C14: =B14*1000000 -> 55800 | D14: =(A14-A13)/3*(C13+C14+SQRT(C13*C14))/1000000 -> 0.026002456 | E14: =E13+D14 -> 0.13573538 | F14: 0.138 | G14: =A14-$K$5 -> -35.5 | H14: =A14-$K$6 -> -40.5 | J14: Volume at crest (Mm³) | K14: =INDEX(E4:E95,MATCH(K6,A4:A95,0)) -> 62.95578
A15: 202 | B15: 0.0599 | C15: =B15*1000000 -> 59900 | D15: =(A15-A14)/3*(C14+C15+SQRT(C14*C15))/1000000 -> 0.028918944 | E15: =E14+D15 -> 0.16465432 | F15: 0.1671 | G15: =A15-$K$5 -> -35 | H15: =A15-$K$6 -> -40 | J15: Max volume in table (Mm³) | K15: =MAX(E4:E95) -> 62.95578
A16: 202.5 | B16: 0.0664 | C16: =B16*1000000 -> 66400 | D16: =(A16-A15)/3*(C15+C16+SQRT(C15*C16))/1000000 -> 0.031561052 | E16: =E15+D16 -> 0.19621537 | F16: 0.1989 | G16: =A16-$K$5 -> -34.5 | H16: =A16-$K$6 -> -39.5 | J16: Max area in table (km²) | K16: =MAX(B4:B95) -> 4.4284
A17: 203 | B17: 0.0711 | C17: =B17*1000000 -> 71100 | D17: =(A17-A16)/3*(C16+C17+SQRT(C16*C17))/1000000 -> 0.034368304 | E17: =E16+D17 -> 0.23058368 | F17: 0.2334 | G17: =A17-$K$5 -> -34 | H17: =A17-$K$6 -> -39
A18: 203.5 | B18: 0.0763 | C18: =B18*1000000 -> 76300 | D18: =(A18-A17)/3*(C17+C18+SQRT(C17*C18))/1000000 -> 0.036842354 | E18: =E17+D18 -> 0.26742603 | F18: 0.2704 | G18: =A18-$K$5 -> -33.5 | H18: =A18-$K$6 -> -38.5
A19: 204 | B19: 0.0831 | C19: =B19*1000000 -> 83100 | D19: =(A19-A18)/3*(C18+C19+SQRT(C18*C19))/1000000 -> 0.039837908 | E19: =E18+D19 -> 0.30726394 | F19: 0.3103 | G19: =A19-$K$5 -> -33 | H19: =A19-$K$6 -> -38
A20: 204.5 | B20: 0.0903 | C20: =B20*1000000 -> 90300 | D20: =(A20-A19)/3*(C19+C20+SQRT(C19*C20))/1000000 -> 0.043337538 | E20: =E19+D20 -> 0.35060148 | F20: 0.3539 | G20: =A20-$K$5 -> -32.5 | H20: =A20-$K$6 -> -37.5
A21: 205 | B21: 0.098 | C21: =B21*1000000 -> 98000 | D21: =(A21-A20)/3*(C20+C21+SQRT(C20*C21))/1000000 -> 0.047061875 | E21: =E20+D21 -> 0.39766335 | F21: 0.4011 | G21: =A21-$K$5 -> -32 | H21: =A21-$K$6 -> -37
A22: 205.5 | B22: 0.1035 | C22: =B22*1000000 -> 103500 | D22: =(A22-A21)/3*(C21+C22+SQRT(C21*C22))/1000000 -> 0.050368744 | E22: =E21+D22 -> 0.4480321 | F22: 0.4515 | G22: =A22-$K$5 -> -31.5 | H22: =A22-$K$6 -> -36.5
A23: 206 | B23: 0.1115 | C23: =B23*1000000 -> 111500 | D23: =(A23-A22)/3*(C22+C23+SQRT(C22*C23))/1000000 -> 0.053737593 | E23: =E22+D23 -> 0.50176969 | F23: 0.5056 | G23: =A23-$K$5 -> -31 | H23: =A23-$K$6 -> -36
A24: 206.5 | B24: 0.1195 | C24: =B24*1000000 -> 119500 | D24: =(A24-A23)/3*(C23+C24+SQRT(C23*C24))/1000000 -> 0.057738453 | E24: =E23+D24 -> 0.55950814 | F24: 0.5635 | G24: =A24-$K$5 -> -30.5 | H24: =A24-$K$6 -> -35.5
A25: 207 | B25: 0.1281 | C25: =B25*1000000 -> 128100 | D25: =(A25-A24)/3*(C24+C25+SQRT(C24*C25))/1000000 -> 0.06188755 | E25: =E24+D25 -> 0.62139569 | F25: 0.6258 | G25: =A25-$K$5 -> -30 | H25: =A25-$K$6 -> -35
A26: 207.5 | B26: 0.1383 | C26: =B26*1000000 -> 138300 | D26: =(A26-A25)/3*(C25+C26+SQRT(C25*C26))/1000000 -> 0.066583722 | E26: =E25+D26 -> 0.68797941 | F26: 0.6925 | G26: =A26-$K$5 -> -29.5 | H26: =A26-$K$6 -> -34.5
A27: 208 | B27: 0.1495 | C27: =B27*1000000 -> 149500 | D27: =(A27-A26)/3*(C26+C27+SQRT(C26*C27))/1000000 -> 0.071931832 | E27: =E26+D27 -> 0.75991125 | F27: 0.7651 | G27: =A27-$K$5 -> -29 | H27: =A27-$K$6 -> -34
A28: 208.5 | B28: 0.1612 | C28: =B28*1000000 -> 161200 | D28: =(A28-A27)/3*(C27+C28+SQRT(C27*C28))/1000000 -> 0.077656636 | E28: =E27+D28 -> 0.83756788 | F28: 0.843 | G28: =A28-$K$5 -> -28.5 | H28: =A28-$K$6 -> -33.5
... A95: 242 | B95: 4.4284 | C95: =B95*1000000 -> 4428400 | D95: =(A95-A94)/3*(C94+C95+SQRT(C94*C95))/1000000 -> 2.1978047 | E95: =E94+D95 -> 62.95578 | F95: 63.0481 | G95: =A95-$K$5 -> 5 | H95: =A95-$K$6 -> 0

Sheet Sarami 05
A1: Sarami 05 - reservoir elevation-area-volume
A2: Area: 10 m DEM (NSA 5m B04 Res10m) inside the crest polygon, pond connected to the dam axis, 0.5 m steps from bed to crest. Volume: conic formula between steps, dV = dz/3 (A1 + A2 + sqrt(A1 A2)). Column F: volume integrated cell by cell on the DEM (check only). Blue = data.
A3: Elevation (m) | B3: Area (km²) | C3: Area (m²) | D3: ΔV conic (Mm³) | E3: Volume (Mm³) | F3: Volume DEM-integrated (Mm³) | G3: Head above FSL (m) | H3: Head above crest (m) | M3: chart helper: reference lines
A4: 163 | B4: 0.0006 | C4: =B4*1000000 -> 600 | D4: 0 | E4: 0 | F4: 0.0001 | G4: =A4-$K$5 -> -21 | H4: =A4-$K$6 -> -26 | J4: Dam | K4: ="Sarami 05" -> Sarami 05 | M4: x volume | N4: y FSL | O4: y crest | P4: x area
A5: 163.5 | B5: 0.0035 | C5: =B5*1000000 -> 3500 | D5: =(A5-A4)/3*(C4+C5+SQRT(C4*C5))/1000000 -> 0.00092485628 | E5: =E4+D5 -> 0.00092485628 | F5: 0.0011 | G5: =A5-$K$5 -> -20.5 | H5: =A5-$K$6 -> -25.5 | J5: FSL (m) | K5: =Dams!C10 -> 184 | M5: 0 | N5: =K5 -> 184 | O5: =K6 -> 189 | P5: 0
A6: 164 | B6: 0.0089 | C6: =B6*1000000 -> 8900 | D6: =(A6-A5)/3*(C5+C6+SQRT(C5*C6))/1000000 -> 0.0029968698 | E6: =E5+D6 -> 0.003921726 | F6: 0.0042 | G6: =A6-$K$5 -> -20 | H6: =A6-$K$6 -> -25 | J6: Crest level (m) | K6: =Dams!B10 -> 189 | M6: =K15*1.02 -> 24.828019 | N6: =K5 -> 184 | O6: =K6 -> 189 | P6: =K16*1.02 -> 2.251038
A7: 164.5 | B7: 0.0169 | C7: =B7*1000000 -> 16900 | D7: =(A7-A6)/3*(C6+C7+SQRT(C6*C7))/1000000 -> 0.0063440292 | E7: =E6+D7 -> 0.010265755 | F7: 0.0105 | G7: =A7-$K$5 -> -19.5 | H7: =A7-$K$6 -> -24.5 | J7: Bed level (m) | K7: =A4 -> 163 | M7: ="FSL "&TEXT(K5,"0.0")&" m" -> FSL 184.0 m
A8: 165 | B8: 0.0362 | C8: =B8*1000000 -> 36200 | D8: =(A8-A7)/3*(C7+C8+SQRT(C7*C8))/1000000 -> 0.012972364 | E8: =E7+D8 -> 0.02323812 | F8: 0.0238 | G8: =A8-$K$5 -> -19 | H8: =A8-$K$6 -> -24 | J8: Dam height crest-bed (m) | K8: =K6-K7 -> 26 | M8: ="Crest "&TEXT(K6,"0.0")&" m" -> Crest 189.0 m
A9: 165.5 | B9: 0.0602 | C9: =B9*1000000 -> 60200 | D9: =(A9-A8)/3*(C8+C9+SQRT(C8*C9))/1000000 -> 0.023847055 | E9: =E8+D9 -> 0.047085175 | F9: 0.0486 | G9: =A9-$K$5 -> -18.5 | H9: =A9-$K$6 -> -23.5 | J9: Area at FSL (km²) | K9: =INDEX(B4:B56,MATCH(K5,A4:A56,0)) -> 1.722 | M9: ="Elevation-volume curve" -> Elevation-volume curve
A10: 166 | B10: 0.0821 | C10: =B10*1000000 -> 82100 | D10: =(A10-A9)/3*(C9+C10+SQRT(C9*C10))/1000000 -> 0.035433725 | E10: =E9+D10 -> 0.082518899 | F10: 0.0847 | G10: =A10-$K$5 -> -18 | H10: =A10-$K$6 -> -23 | J10: Volume at FSL (Mm³) | K10: =INDEX(E4:E56,MATCH(K5,A4:A56,0)) -> 14.523171 | M10: ="Elevation-area curve" -> Elevation-area curve
A11: 166.5 | B11: 0.1046 | C11: =B11*1000000 -> 104600 | D11: =(A11-A10)/3*(C10+C11+SQRT(C10*C11))/1000000 -> 0.046561605 | E11: =E10+D11 -> 0.1290805 | F11: 0.1318 | G11: =A11-$K$5 -> -17.5 | H11: =A11-$K$6 -> -22.5 | J11: Capacity per dams sheet (Mm³) | K11: =Dams!D10 -> 15
A12: 167 | B12: 0.1265 | C12: =B12*1000000 -> 126500 | D12: =(A12-A11)/3*(C11+C12+SQRT(C11*C12))/1000000 -> 0.057688333 | E12: =E11+D12 -> 0.18676884 | F12: 0.1904 | G12: =A12-$K$5 -> -17 | H12: =A12-$K$6 -> -22 | J12: Difference (%) | K12: =K10/K11-1 -> -0.03178862
A13: 167.5 | B13: 0.1486 | C13: =B13*1000000 -> 148600 | D13: =(A13-A12)/3*(C12+C13+SQRT(C12*C13))/1000000 -> 0.068700906 | E13: =E12+D13 -> 0.25546974 | F13: 0.26 | G13: =A13-$K$5 -> -16.5 | H13: =A13-$K$6 -> -21.5 | J13: Area at crest (km²) | K13: =INDEX(B4:B56,MATCH(K6,A4:A56,0)) -> 2.2069
A14: 168 | B14: 0.1724 | C14: =B14*1000000 -> 172400 | D14: =(A14-A13)/3*(C13+C14+SQRT(C13*C14))/1000000 -> 0.080176373 | E14: =E13+D14 -> 0.33564612 | F14: 0.3409 | G14: =A14-$K$5 -> -16 | H14: =A14-$K$6 -> -21 | J14: Volume at crest (Mm³) | K14: =INDEX(E4:E56,MATCH(K6,A4:A56,0)) -> 24.341195
A15: 168.5 | B15: 0.1961 | C15: =B15*1000000 -> 196100 | D15: =(A15-A14)/3*(C14+C15+SQRT(C14*C15))/1000000 -> 0.092061423 | E15: =E14+D15 -> 0.42770754 | F15: 0.4333 | G15: =A15-$K$5 -> -15.5 | H15: =A15-$K$6 -> -20.5 | J15: Max volume in table (Mm³) | K15: =MAX(E4:E56) -> 24.341195
A16: 169 | B16: 0.2269 | C16: =B16*1000000 -> 226900 | D16: =(A16-A15)/3*(C15+C16+SQRT(C15*C16))/1000000 -> 0.10565643 | E16: =E15+D16 -> 0.53336397 | F16: 0.5395 | G16: =A16-$K$5 -> -15 | H16: =A16-$K$6 -> -20 | J16: Max area in table (km²) | K16: =MAX(B4:B56) -> 2.2069
A17: 169.5 | B17: 0.2646 | C17: =B17*1000000 -> 264600 | D17: =(A17-A16)/3*(C16+C17+SQRT(C16*C17))/1000000 -> 0.12275433 | E17: =E16+D17 -> 0.6561183 | F17: 0.6628 | G17: =A17-$K$5 -> -14.5 | H17: =A17-$K$6 -> -19.5
A18: 170 | B18: 0.3044 | C18: =B18*1000000 -> 304400 | D18: =(A18-A17)/3*(C17+C18+SQRT(C17*C18))/1000000 -> 0.14213386 | E18: =E17+D18 -> 0.79825217 | F18: 0.8063 | G18: =A18-$K$5 -> -14 | H18: =A18-$K$6 -> -19
A19: 170.5 | B19: 0.3454 | C19: =B19*1000000 -> 345400 | D19: =(A19-A18)/3*(C18+C19+SQRT(C18*C19))/1000000 -> 0.1623421 | E19: =E18+D19 -> 0.96059427 | F19: 0.9687 | G19: =A19-$K$5 -> -13.5 | H19: =A19-$K$6 -> -18.5
A20: 171 | B20: 0.3892 | C20: =B20*1000000 -> 389200 | D20: =(A20-A19)/3*(C19+C20+SQRT(C19*C20))/1000000 -> 0.18354109 | E20: =E19+D20 -> 1.1441354 | F20: 1.1529 | G20: =A20-$K$5 -> -13 | H20: =A20-$K$6 -> -18
A21: 171.5 | B21: 0.4334 | C21: =B21*1000000 -> 433400 | D21: =(A21-A20)/3*(C20+C21+SQRT(C20*C21))/1000000 -> 0.20555097 | E21: =E20+D21 -> 1.3496863 | F21: 1.3594 | G21: =A21-$K$5 -> -12.5 | H21: =A21-$K$6 -> -17.5
A22: 172 | B22: 0.4767 | C22: =B22*1000000 -> 476700 | D22: =(A22-A21)/3*(C21+C22+SQRT(C21*C22))/1000000 -> 0.22743911 | E22: =E21+D22 -> 1.5771254 | F22: 1.5871 | G22: =A22-$K$5 -> -12 | H22: =A22-$K$6 -> -17
A23: 172.5 | B23: 0.5269 | C23: =B23*1000000 -> 526900 | D23: =(A23-A22)/3*(C22+C23+SQRT(C22*C23))/1000000 -> 0.25079531 | E23: =E22+D23 -> 1.8279208 | F23: 1.8385 | G23: =A23-$K$5 -> -11.5 | H23: =A23-$K$6 -> -16.5
A24: 173 | B24: 0.5803 | C24: =B24*1000000 -> 580300 | D24: =(A24-A23)/3*(C23+C24+SQRT(C23*C24))/1000000 -> 0.27669263 | E24: =E23+D24 -> 2.1046134 | F24: 2.1162 | G24: =A24-$K$5 -> -11 | H24: =A24-$K$6 -> -16
A25: 173.5 | B25: 0.6328 | C25: =B25*1000000 -> 632800 | D25: =(A25-A24)/3*(C24+C25+SQRT(C24*C25))/1000000 -> 0.30318029 | E25: =E24+D25 -> 2.4077937 | F25: 2.4209 | G25: =A25-$K$5 -> -10.5 | H25: =A25-$K$6 -> -15.5
A26: 174 | B26: 0.6838 | C26: =B26*1000000 -> 683800 | D26: =(A26-A25)/3*(C25+C26+SQRT(C25*C26))/1000000 -> 0.32906765 | E26: =E25+D26 -> 2.7368613 | F26: 2.7512 | G26: =A26-$K$5 -> -10 | H26: =A26-$K$6 -> -15
A27: 174.5 | B27: 0.7303 | C27: =B27*1000000 -> 730300 | D27: =(A27-A26)/3*(C26+C27+SQRT(C26*C27))/1000000 -> 0.35346127 | E27: =E26+D27 -> 3.0903226 | F27: 3.1054 | G27: =A27-$K$5 -> -9.5 | H27: =A27-$K$6 -> -14.5
A28: 175 | B28: 0.7756 | C28: =B28*1000000 -> 775600 | D28: =(A28-A27)/3*(C27+C28+SQRT(C27*C28))/1000000 -> 0.37641821 | E28: =E27+D28 -> 3.4667408 | F28: 3.4822 | G28: =A28-$K$5 -> -9 | H28: =A28-$K$6 -> -14
... A56: 189 | B56: 2.2069 | C56: =B56*1000000 -> 2206900 | D56: =(A56-A55)/3*(C55+C56+SQRT(C55*C56))/1000000 -> 1.0916789 | E56: =E55+D56 -> 24.341195 | F56: 24.3774 | G56: =A56-$K$5 -> 5 | H56: =A56-$K$6 -> 0

Sheet Sakhin 04
A1: Sakhin 04 - reservoir elevation-area-volume
A2: Area: 10 m DEM (NSA 5m B04 Res10m) inside the crest polygon, pond connected to the dam axis, 0.5 m steps from bed to crest. Volume: conic formula between steps, dV = dz/3 (A1 + A2 + sqrt(A1 A2)). Column F: volume integrated cell by cell on the DEM (check only). Blue = data.
A3: Elevation (m) | B3: Area (km²) | C3: Area (m²) | D3: ΔV conic (Mm³) | E3: Volume (Mm³) | F3: Volume DEM-integrated (Mm³) | G3: Head above FSL (m) | H3: Head above crest (m) | M3: chart helper: reference lines
A4: 102 | B4: 0.0059 | C4: =B4*1000000 -> 5900 | D4: 0 | E4: 0 | F4: 0.0012 | G4: =A4-$K$5 -> -20 | H4: =A4-$K$6 -> -25 | J4: Dam | K4: ="Sakhin 04" -> Sakhin 04 | M4: x volume | N4: y FSL | O4: y crest | P4: x area
A5: 102.5 | B5: 0.0182 | C5: =B5*1000000 -> 18200 | D5: =(A5-A4)/3*(C4+C5+SQRT(C4*C5))/1000000 -> 0.0057437387 | E5: =E4+D5 -> 0.0057437387 | F5: 0.0071 | G5: =A5-$K$5 -> -19.5 | H5: =A5-$K$6 -> -24.5 | J5: FSL (m) | K5: =Dams!C11 -> 122 | M5: 0 | N5: =K5 -> 122 | O5: =K6 -> 127 | P5: 0
A6: 103 | B6: 0.0391 | C6: =B6*1000000 -> 39100 | D6: =(A6-A5)/3*(C5+C6+SQRT(C5*C6))/1000000 -> 0.013996034 | E6: =E5+D6 -> 0.019739773 | F6: 0.0215 | G6: =A6-$K$5 -> -19 | H6: =A6-$K$6 -> -24 | J6: Crest level (m) | K6: =Dams!B11 -> 127 | M6: =K15*1.02 -> 40.861726 | N6: =K5 -> 122 | O6: =K6 -> 127 | P6: =K16*1.02 -> 4.207092
A7: 103.5 | B7: 0.067 | C7: =B7*1000000 -> 67000 | D7: =(A7-A6)/3*(C6+C7+SQRT(C6*C7))/1000000 -> 0.026213834 | E7: =E6+D7 -> 0.045953607 | F7: 0.0481 | G7: =A7-$K$5 -> -18.5 | H7: =A7-$K$6 -> -23.5 | J7: Bed level (m) | K7: =A4 -> 102 | M7: ="FSL "&TEXT(K5,"0.0")&" m" -> FSL 122.0 m
A8: 104 | B8: 0.1001 | C8: =B8*1000000 -> 100100 | D8: =(A8-A7)/3*(C7+C8+SQRT(C7*C8))/1000000 -> 0.041499074 | E8: =E7+D8 -> 0.087452681 | F8: 0.0902 | G8: =A8-$K$5 -> -18 | H8: =A8-$K$6 -> -23 | J8: Dam height crest-bed (m) | K8: =K6-K7 -> 25 | M8: ="Crest "&TEXT(K6,"0.0")&" m" -> Crest 127.0 m
A9: 104.5 | B9: 0.137 | C9: =B9*1000000 -> 137000 | D9: =(A9-A8)/3*(C8+C9+SQRT(C8*C9))/1000000 -> 0.059034251 | E9: =E8+D9 -> 0.14648693 | F9: 0.1494 | G9: =A9-$K$5 -> -17.5 | H9: =A9-$K$6 -> -22.5 | J9: Area at FSL (km²) | K9: =INDEX(B4:B54,MATCH(K5,A4:A54,0)) -> 2.8917 | M9: ="Elevation-volume curve" -> Elevation-volume curve
A10: 105 | B10: 0.1839 | C10: =B10*1000000 -> 183900 | D10: =(A10-A9)/3*(C9+C10+SQRT(C9*C10))/1000000 -> 0.079937854 | E10: =E9+D10 -> 0.22642479 | F10: 0.2312 | G10: =A10-$K$5 -> -17 | H10: =A10-$K$6 -> -22 | J10: Volume at FSL (Mm³) | K10: =INDEX(E4:E54,MATCH(K5,A4:A54,0)) -> 22.605756 | M10: ="Elevation-area curve" -> Elevation-area curve
A11: 105.5 | B11: 0.2234 | C11: =B11*1000000 -> 223400 | D11: =(A11-A10)/3*(C10+C11+SQRT(C10*C11))/1000000 -> 0.10166501 | E11: =E10+D11 -> 0.3280898 | F11: 0.3338 | G11: =A11-$K$5 -> -16.5 | H11: =A11-$K$6 -> -21.5 | J11: Capacity per dams sheet (Mm³) | K11: =Dams!D11 -> 24
A12: 106 | B12: 0.2659 | C12: =B12*1000000 -> 265900 | D12: =(A12-A11)/3*(C11+C12+SQRT(C11*C12))/1000000 -> 0.1221709 | E12: =E11+D12 -> 0.45026069 | F12: 0.4565 | G12: =A12-$K$5 -> -16 | H12: =A12-$K$6 -> -21 | J12: Difference (%) | K12: =K10/K11-1 -> -0.058093496
A13: 106.5 | B13: 0.3198 | C13: =B13*1000000 -> 319800 | D13: =(A13-A12)/3*(C12+C13+SQRT(C12*C13))/1000000 -> 0.14621788 | E13: =E12+D13 -> 0.59647858 | F13: 0.6038 | G13: =A13-$K$5 -> -15.5 | H13: =A13-$K$6 -> -20.5 | J13: Area at crest (km²) | K13: =INDEX(B4:B54,MATCH(K6,A4:A54,0)) -> 4.1246
A14: 107 | B14: 0.3632 | C14: =B14*1000000 -> 363200 | D14: =(A14-A13)/3*(C13+C14+SQRT(C13*C14))/1000000 -> 0.17063498 | E14: =E13+D14 -> 0.76711355 | F14: 0.7756 | G14: =A14-$K$5 -> -15 | H14: =A14-$K$6 -> -20 | J14: Volume at crest (Mm³) | K14: =INDEX(E4:E54,MATCH(K6,A4:A54,0)) -> 40.060516
A15: 107.5 | B15: 0.4059 | C15: =B15*1000000 -> 405900 | D15: =(A15-A14)/3*(C14+C15+SQRT(C14*C15))/1000000 -> 0.19217615 | E15: =E14+D15 -> 0.9592897 | F15: 0.969 | G15: =A15-$K$5 -> -14.5 | H15: =A15-$K$6 -> -19.5 | J15: Max volume in table (Mm³) | K15: =MAX(E4:E54) -> 40.060516
A16: 108 | B16: 0.4533 | C16: =B16*1000000 -> 453300 | D16: =(A16-A15)/3*(C15+C16+SQRT(C15*C16))/1000000 -> 0.21469096 | E16: =E15+D16 -> 1.1739807 | F16: 1.1843 | G16: =A16-$K$5 -> -14 | H16: =A16-$K$6 -> -19 | J16: Max area in table (km²) | K16: =MAX(B4:B54) -> 4.1246
A17: 108.5 | B17: 0.5015 | C17: =B17*1000000 -> 501500 | D17: =(A17-A16)/3*(C16+C17+SQRT(C16*C17))/1000000 -> 0.23859855 | E17: =E16+D17 -> 1.4125792 | F17: 1.4237 | G17: =A17-$K$5 -> -13.5 | H17: =A17-$K$6 -> -18.5
A18: 109 | B18: 0.5566 | C18: =B18*1000000 -> 556600 | D18: =(A18-A17)/3*(C17+C18+SQRT(C17*C18))/1000000 -> 0.26440536 | E18: =E17+D18 -> 1.6769846 | F18: 1.6895 | G18: =A18-$K$5 -> -13 | H18: =A18-$K$6 -> -18
A19: 109.5 | B19: 0.6104 | C19: =B19*1000000 -> 610400 | D19: =(A19-A18)/3*(C18+C19+SQRT(C18*C19))/1000000 -> 0.2916466 | E19: =E18+D19 -> 1.9686312 | F19: 1.9821 | G19: =A19-$K$5 -> -12.5 | H19: =A19-$K$6 -> -17.5
A20: 110 | B20: 0.6728 | C20: =B20*1000000 -> 672800 | D20: =(A20-A19)/3*(C19+C20+SQRT(C19*C20))/1000000 -> 0.32067349 | E20: =E19+D20 -> 2.2893047 | F20: 2.3045 | G20: =A20-$K$5 -> -12 | H20: =A20-$K$6 -> -17
A21: 110.5 | B21: 0.7347 | C21: =B21*1000000 -> 734700 | D21: =(A21-A20)/3*(C20+C21+SQRT(C20*C21))/1000000 -> 0.35176152 | E21: =E20+D21 -> 2.6410662 | F21: 2.6564 | G21: =A21-$K$5 -> -11.5 | H21: =A21-$K$6 -> -16.5
A22: 111 | B22: 0.791 | C22: =B22*1000000 -> 791000 | D22: =(A22-A21)/3*(C21+C22+SQRT(C21*C22))/1000000 -> 0.38133841 | E22: =E21+D22 -> 3.0224046 | F22: 3.0384 | G22: =A22-$K$5 -> -11 | H22: =A22-$K$6 -> -16
