Workbook

Sheet Hydrographs
A1: datetime | B1: Hawasinah 02 Reservoir Inflow (2yr) | C1: Hawasinah 02 Reservoir Outflow (2yr) | D1: Hawasinah 11 Reservoir Inflow (2yr) | E1: Hawasinah 11 Reservoir Outflow (2yr) | F1: Hawasinah UP Reservoir Inflow (2yr) | G1: Hawasinah UP Reservoir Outflow (2yr) | H1: Shafan 02 Reservoir Inflow (2yr) | I1: Shafan 02 Reservoir Outflow (2yr) | J1: Shafan 08 Reservoir Inflow (2yr) | K1: Shafan 08 Reservoir Outflow (2yr) | L1: Sarami 03 Reservoir Inflow (2yr) | M1: Sarami 03 Reservoir Outflow (2yr) | N1: Sarami 05 Reservoir Inflow (2yr) | O1: Sarami 05 Reservoir Outflow (2yr) | P1: Sakhin 04 Reservoir Inflow (2yr) | Q1: Sakhin 04 Reservoir Outflow (2yr) | R1: Sakhin 08 (Mehmum) Reservoir Inflow (2yr) | S1: Sakhin 08 (Mehmum) Reservoir Outflow (2yr) | T1: Hawasinah 02 Reservoir Inflow (5yr) | U1: Hawasinah 02 Reservoir Outflow (5yr) | V1: Hawasinah 11 Reservoir Inflow (5yr) | W1: Hawasinah 11 Reservoir Outflow (5yr) | X1: Hawasinah UP Reservoir Inflow (5yr) | Y1: Hawasinah UP Reservoir Outflow (5yr) | Z1: Shafan 02 Reservoir Inflow (5yr) | AA1: Shafan 02 Reservoir Outflow (5yr) | AB1: Shafan 08 Reservoir Inflow (5yr) | AC1: Shafan 08 Reservoir Outflow (5yr) | AD1: Sarami 03 Reservoir Inflow (5yr) | AE1: Sarami 03 Reservoir Outflow (5yr) | AF1: Sarami 05 Reservoir Inflow (5yr) | AG1: Sarami 05 Reservoir Outflow (5yr) | AH1: Sakhin 04 Reservoir Inflow (5yr) | AI1: Sakhin 04 Reservoir Outflow (5yr) | AJ1: Sakhin 08 (Mehmum) Reservoir Inflow (5yr) | AK1: Sakhin 08 (Mehmum) Reservoir Outflow (5yr) | AL1: Hawasinah 02 Reservoir Inflow (10yr) | AM1: Hawasinah 02 Reservoir Outflow (10yr) | AN1: Hawasinah 11 Reservoir Inflow (10yr) | AO1: Hawasinah 11 Reservoir Outflow (10yr) | AP1: Hawasinah UP Reservoir Inflow (10yr) | AQ1: Hawasinah UP Reservoir Outflow (10yr) | AR1: Shafan 02 Reservoir Inflow (10yr) | AS1: Shafan 02 Reservoir Outflow (10yr) | AT1: Shafan 08 Reservoir Inflow (10yr) | AU1: Shafan 08 Reservoir Outflow (10yr) | AV1: Sarami 03 Reservoir Inflow (10yr) | AW1: Sarami 03 Reservoir Outflow (10yr) | AX1: Sarami 05 Reservoir Inflow (10yr) | AY1: Sarami 05 Reservoir Outflow (10yr) | AZ1: Sakhin 04 Reservoir Inflow (10yr) | BA1: Sakhin 04 Reservoir Outflow (10yr) | BB1: Sakhin 08 (Mehmum) Reservoir Inflow (10yr) | BC1: Sakhin 08 (Mehmum) Reservoir Outflow (10yr) | BD1: Hawasinah 02 Reservoir Inflow (25yr) | BE1: Hawasinah 02 Reservoir Outflow (25yr) | BF1: Hawasinah 11 Reservoir Inflow (25yr) | BG1: Hawasinah 11 Reservoir Outflow (25yr) | BH1: Hawasinah UP Reservoir Inflow (25yr) | BI1: Hawasinah UP Reservoir Outflow (25yr) | BJ1: Shafan 02 Reservoir Inflow (25yr) | BK1: Shafan 02 Reservoir Outflow (25yr) | BL1: Shafan 08 Reservoir Inflow (25yr) | BM1: Shafan 08 Reservoir Outflow (25yr) | BN1: Sarami 03 Reservoir Inflow (25yr) | BO1: Sarami 03 Reservoir Outflow (25yr) | BP1: Sarami 05 Reservoir Inflow (25yr) | BQ1: Sarami 05 Reservoir Outflow (25yr) | BR1: Sakhin 04 Reservoir Inflow (25yr) | BS1: Sakhin 04 Reservoir Outflow (25yr) | BT1: Sakhin 08 (Mehmum) Reservoir Inflow (25yr) | BU1: Sakhin 08 (Mehmum) Reservoir Outflow (25yr) | BV1: Hawasinah 02 Reservoir Inflow (50yr) | BW1: Hawasinah 02 Reservoir Outflow (50yr) | BX1: Hawasinah 11 Reservoir Inflow (50yr) | BY1: Hawasinah 11 Reservoir Outflow (50yr) | BZ1: Hawasinah UP Reservoir Inflow (50yr) | CA1: Hawasinah UP Reservoir Outflow (50yr) | CB1: Shafan 02 Reservoir Inflow (50yr) | CC1: Shafan 02 Reservoir Outflow (50yr) | CD1: Shafan 08 Reservoir Inflow (50yr) | CE1: Shafan 08 Reservoir Outflow (50yr) | CF1: Sarami 03 Reservoir Inflow (50yr) | CG1: Sarami 03 Reservoir Outflow (50yr) | CH1: Sarami 05 Reservoir Inflow (50yr) | CI1: Sarami 05 Reservoir Outflow (50yr) | CJ1: Sakhin 04 Reservoir Inflow (50yr) | CK1: Sakhin 04 Reservoir Outflow (50yr) | CL1: Sakhin 08 (Mehmum) Reservoir Inflow (50yr) | CM1: Sakhin 08 (Mehmum) Reservoir Outflow (50yr) | CN1: Hawasinah 02 Reservoir Inflow (100yr) | CO1: Hawasinah 02 Reservoir Outflow (100yr) | CP1: Hawasinah 11 Reservoir Inflow (100yr) | CQ1: Hawasinah 11 Reservoir Outflow (100yr) | CR1: Hawasinah UP Reservoir Inflow (100yr) | CS1: Hawasinah UP Reservoir Outflow (100yr) | CT1: Shafan 02 Reservoir Inflow (100yr) | CU1: Shafan 02 Reservoir Outflow (100yr) | CV1: Shafan 08 Reservoir Inflow (100yr) | CW1: Shafan 08 Reservoir Outflow (100yr) | CX1: Sarami 03 Reservoir Inflow (100yr) | CY1: Sarami 03 Reservoir Outflow (100yr) | CZ1: Sarami 05 Reservoir Inflow (100yr) | DA1: Sarami 05 Reservoir Outflow (100yr) | DB1: Sakhin 04 Reservoir Inflow (100yr) | DC1: Sakhin 04 Reservoir Outflow (100yr) | DD1: Sakhin 08 (Mehmum) Reservoir Inflow (100yr) | DE1: Sakhin 08 (Mehmum) Reservoir Outflow (100yr) | DF1: Hawasinah 02 Reservoir Inflow (200yr) | DG1: Hawasinah 02 Reservoir Outflow (200yr) | DH1: Hawasinah 11 Reservoir Inflow (200yr) | DI1: Hawasinah 11 Reservoir Outflow (200yr) | DJ1: Hawasinah UP Reservoir Inflow (200yr) | DK1: Hawasinah UP Reservoir Outflow (200yr) | DL1: Shafan 02 Reservoir Inflow (200yr) | DM1: Shafan 02 Reservoir Outflow (200yr) | DN1: Shafan 08 Reservoir Inflow (200yr) | DO1: Shafan 08 Reservoir Outflow (200yr) | DP1: Sarami 03 Reservoir Inflow (200yr) | DQ1: Sarami 03 Reservoir Outflow (200yr) | DR1: Sarami 05 Reservoir Inflow (200yr) | DS1: Sarami 05 Reservoir Outflow (200yr) | DT1: Sakhin 04 Reservoir Inflow (200yr) | DU1: Sakhin 04 Reservoir Outflow (200yr) | DV1: Sakhin 08 (Mehmum) Reservoir Inflow (200yr) | DW1: Sakhin 08 (Mehmum) Reservoir Outflow (200yr) | DX1: Hawasinah 02 Reservoir Inflow (500yr) | DY1: Hawasinah 02 Reservoir Outflow (500yr) | DZ1: Hawasinah 11 Reservoir Inflow (500yr) | EA1: Hawasinah 11 Reservoir Outflow (500yr) | EB1: Hawasinah UP Reservoir Inflow (500yr) | EC1: Hawasinah UP Reservoir Outflow (500yr) | ED1: Shafan 02 Reservoir Inflow (500yr) | EE1: Shafan 02 Reservoir Outflow (500yr) | EF1: Shafan 08 Reservoir Inflow (500yr) | EG1: Shafan 08 Reservoir Outflow (500yr) | EH1: Sarami 03 Reservoir Inflow (500yr) | EI1: Sarami 03 Reservoir Outflow (500yr) | EJ1: Sarami 05 Reservoir Inflow (500yr) | EK1: Sarami 05 Reservoir Outflow (500yr) | EL1: Sakhin 04 Reservoir Inflow (500yr) | EM1: Sakhin 04 Reservoir Outflow (500yr) | EN1: Sakhin 08 (Mehmum) Reservoir Inflow (500yr) | EO1: Sakhin 08 (Mehmum) Reservoir Outflow (500yr) | EP1: Hawasinah 02 Reservoir Inflow (1000yr) | EQ1: Hawasinah 02 Reservoir Outflow (1000yr) | ER1: Hawasinah 11 Reservoir Inflow (1000yr) | ES1: Hawasinah 11 Reservoir Outflow (1000yr) | ET1: Hawasinah UP Reservoir Inflow (1000yr) | EU1: Hawasinah UP Reservoir Outflow (1000yr) | EV1: Shafan 02 Reservoir Inflow (1000yr) | EW1: Shafan 02 Reservoir Outflow (1000yr) | EX1: Shafan 08 Reservoir Inflow (1000yr) | EY1: Shafan 08 Reservoir Outflow (1000yr) | EZ1: Sarami 03 Reservoir Inflow (1000yr) | FA1: Sarami 03 Reservoir Outflow (1000yr) | FB1: Sarami 05 Reservoir Inflow (1000yr) | FC1: Sarami 05 Reservoir Outflow (1000yr) | FD1: Sakhin 04 Reservoir Inflow (1000yr) | FE1: Sakhin 04 Reservoir Outflow (1000yr) | FF1: Sakhin 08 (Mehmum) Reservoir Inflow (1000yr) | FG1: Sakhin 08 (Mehmum) Reservoir Outflow (1000yr) | FH1: Hawasinah 02 Reservoir Inflow (2000yr) | FI1: Hawasinah 02 Reservoir Outflow (2000yr) | FJ1: Hawasinah 11 Reservoir Inflow (2000yr) | FK1: Hawasinah 11 Reservoir Outflow (2000yr) | FL1: Hawasinah UP Reservoir Inflow (2000yr) | FM1: Hawasinah UP Reservoir Outflow (2000yr) | FN1: Shafan 02 Reservoir Inflow (2000yr) | FO1: Shafan 02 Reservoir Outflow (2000yr) | FP1: Shafan 08 Reservoir Inflow (2000yr) | FQ1: Shafan 08 Reservoir Outflow (2000yr) | FR1: Sarami 03 Reservoir Inflow (2000yr) | FS1: Sarami 03 Reservoir Outflow (2000yr) | FT1: Sarami 05 Reservoir Inflow (2000yr) | FU1: Sarami 05 Reservoir Outflow (2000yr) | FV1: Sakhin 04 Reservoir Inflow (2000yr) | FW1: Sakhin 04 Reservoir Outflow (2000yr) | FX1: Sakhin 08 (Mehmum) Reservoir Inflow (2000yr) | FY1: Sakhin 08 (Mehmum) Reservoir Outflow (2000yr) | FZ1: Hawasinah 02 Reservoir Inflow (5000yr) | GA1: Hawasinah 02 Reservoir Outflow (5000yr) | GB1: Hawasinah 11 Reservoir Inflow (5000yr) | GC1: Hawasinah 11 Reservoir Outflow (5000yr) | GD1: Hawasinah UP Reservoir Inflow (5000yr) | GE1: Hawasinah UP Reservoir Outflow (5000yr) | GF1: Shafan 02 Reservoir Inflow (5000yr) | GG1: Shafan 02 Reservoir Outflow (5000yr) | GH1: Shafan 08 Reservoir Inflow (5000yr) | GI1: Shafan 08 Reservoir Outflow (5000yr) | GJ1: Sarami 03 Reservoir Inflow (5000yr) | GK1: Sarami 03 Reservoir Outflow (5000yr) | GL1: Sarami 05 Reservoir Inflow (5000yr) | GM1: Sarami 05 Reservoir Outflow (5000yr) | GN1: Sakhin 04 Reservoir Inflow (5000yr) | GO1: Sakhin 04 Reservoir Outflow (5000yr) | GP1: Sakhin 08 (Mehmum) Reservoir Inflow (5000yr) | GQ1: Sakhin 08 (Mehmum) Reservoir Outflow (5000yr) | GR1: Hawasinah 02 Reservoir Inflow (10000yr) | GS1: Hawasinah 02 Reservoir Outflow (10000yr) | GT1: Hawasinah 11 Reservoir Inflow (10000yr) | GU1: Hawasinah 11 Reservoir Outflow (10000yr) | GV1: Hawasinah UP Reservoir Inflow (10000yr) | GW1: Hawasinah UP Reservoir Outflow (10000yr) | GX1: Shafan 02 Reservoir Inflow (10000yr) | GY1: Shafan 02 Reservoir Outflow (10000yr) | GZ1: Shafan 08 Reservoir Inflow (10000yr) | HA1: Shafan 08 Reservoir Outflow (10000yr) | HB1: Sarami 03 Reservoir Inflow (10000yr) | HC1: Sarami 03 Reservoir Outflow (10000yr) | HD1: Sarami 05 Reservoir Inflow (10000yr) | HE1: Sarami 05 Reservoir Outflow (10000yr) | HF1: Sakhin 04 Reservoir Inflow (10000yr) | HG1: Sakhin 04 Reservoir Outflow (10000yr) | HH1: Sakhin 08 (Mehmum) Reservoir Inflow (10000yr) | HI1: Sakhin 08 (Mehmum) Reservoir Outflow (10000yr) | HJ1: Hawasinah 02 Reservoir Inflow (PMP) | HK1: Hawasinah 02 Reservoir Outflow (PMP) | HL1: Hawasinah 11 Reservoir Inflow (PMP) | HM1: Hawasinah 11 Reservoir Outflow (PMP) | HN1: Hawasinah UP Reservoir Inflow (PMP) | HO1: Hawasinah UP Reservoir Outflow (PMP) | HP1: Shafan 02 Reservoir Inflow (PMP) | HQ1: Shafan 02 Reservoir Outflow (PMP) | HR1: Shafan 08 Reservoir Inflow (PMP) | HS1: Shafan 08 Reservoir Outflow (PMP) | HT1: Sarami 03 Reservoir Inflow (PMP) | HU1: Sarami 03 Reservoir Outflow (PMP) | HV1: Sarami 05 Reservoir Inflow (PMP) | HW1: Sarami 05 Reservoir Outflow (PMP) | HX1: Sakhin 04 Reservoir Inflow (PMP) | HY1: Sakhin 04 Reservoir Outflow (PMP) | HZ1: Sakhin 08 (Mehmum) Reservoir Inflow (PMP) | IA1: Sakhin 08 (Mehmum) Reservoir Outflow (PMP)
A2: 36526 | B2: 0 | C2: 0 | D2: 0 | E2: 0 | F2: 0 | G2: 0 | H2: 0 | I2: 0 | J2: 0 | K2: 0 | L2: 0 | M2: 0 | N2: 0 | O2: 0 | P2: 0 | Q2: 0 | R2: 0 | S2: 0 | T2: 0 | U2: 0 | V2: 0 | W2: 0 | X2: 0 | Y2: 0 | Z2: 0 | AA2: 0 | AB2: 0 | AC2: 0 | AD2: 0 | AE2: 0 | AF2: 0 | AG2: 0 | AH2: 0 | AI2: 0 | AJ2: 0 | AK2: 0 | AL2: 0 | AM2: 0 | AN2: 0 | AO2: 0 | AP2: 0 | AQ2: 0 | AR2: 0 | AS2: 0 | AT2: 0 | AU2: 0 | AV2: 0 | AW2: 0 | AX2: 0 | AY2: 0 | AZ2: 0 | BA2: 0 | BB2: 0 | BC2: 0 | BD2: 0 | BE2: 0 | BF2: 0 | BG2: 0 | BH2: 0 | BI2: 0 | BJ2: 0 | BK2: 0 | BL2: 0 | BM2: 0 | BN2: 0 | BO2: 0 | BP2: 0 | BQ2: 0 | BR2: 0 | BS2: 0 | BT2: 0 | BU2: 0 | BV2: 0 | BW2: 0 | BX2: 0 | BY2: 0 | BZ2: 0 | CA2: 0 | CB2: 0 | CC2: 0 | CD2: 0 | CE2: 0 | CF2: 0 | CG2: 0 | CH2: 0 | CI2: 0 | CJ2: 0 | CK2: 0 | CL2: 0 | CM2: 0 | CN2: 0 | CO2: 0 | CP2: 0 | CQ2: 0 | CR2: 0 | CS2: 0 | CT2: 0 | CU2: 0 | CV2: 0 | CW2: 0 | CX2: 0 | CY2: 0 | CZ2: 0 | DA2: 0 | DB2: 0 | DC2: 0 | DD2: 0 | DE2: 0 | DF2: 0 | DG2: 0 | DH2: 0 | DI2: 0 | DJ2: 0 | DK2: 0 | DL2: 0 | DM2: 0 | DN2: 0 | DO2: 0 | DP2: 0 | DQ2: 0 | DR2: 0 | DS2: 0 | DT2: 0 | DU2: 0 | DV2: 0 | DW2: 0 | DX2: 0 | DY2: 0 | DZ2: 0 | EA2: 0 | EB2: 0 | EC2: 0 | ED2: 0 | EE2: 0 | EF2: 0 | EG2: 0 | EH2: 0 | EI2: 0 | EJ2: 0 | EK2: 0 | EL2: 0 | EM2: 0 | EN2: 0 | EO2: 0 | EP2: 0 | EQ2: 0 | ER2: 0 | ES2: 0 | ET2: 0 | EU2: 0 | EV2: 0 | EW2: 0 | EX2: 0 | EY2: 0 | EZ2: 0 | FA2: 0 | FB2: 0 | FC2: 0 | FD2: 0 | FE2: 0 | FF2: 0 | FG2: 0 | FH2: 0 | FI2: 0 | FJ2: 0 | FK2: 0 | FL2: 0 | FM2: 0 | FN2: 0 | FO2: 0 | FP2: 0 | FQ2: 0 | FR2: 0 | FS2: 0 | FT2: 0 | FU2: 0 | FV2: 0 | FW2: 0 | FX2: 0 | FY2: 0 | FZ2: 0 | GA2: 0 | GB2: 0 | GC2: 0 | GD2: 0 | GE2: 0 | GF2: 0 | GG2: 0 | GH2: 0 | GI2: 0 | GJ2: 0 | GK2: 0 | GL2: 0 | GM2: 0 | GN2: 0 | GO2: 0 | GP2: 0 | GQ2: 0 | GR2: 0 | GS2: 0 | GT2: 0 | GU2: 0 | GV2: 0 | GW2: 0 | GX2: 0 | GY2: 0 | GZ2: 0 | HA2: 0 | HB2: 0 | HC2: 0 | HD2: 0 | HE2: 0 | HF2: 0 | HG2: 0 | HH2: 0 | HI2: 0 | HJ2: 0 | HK2: 0 | HL2: 0 | HM2: 0 | HN2: 0 | HO2: 0 | HP2: 0 | HQ2: 0 | HR2: 0 | HS2: 0 | HT2: 0 | HU2: 0 | HV2: 0 | HW2: 0 | HX2: 0 | HY2: 0 | HZ2: 0 | IA2: 0
A3: 36526.003 | B3: 0 | C3: 0 | D3: 0 | E3: 0 | F3: 0 | G3: 0 | H3: 0 | I3: 0 | J3: 0 | K3: 0 | L3: 0 | M3: 0 | N3: 0 | O3: 0 | P3: 0 | Q3: 0 | R3: 0 | S3: 0 | T3: 0 | U3: 0 | V3: 0 | W3: 0 | X3: 0 | Y3: 0 | Z3: 0 | AA3: 0 | AB3: 0 | AC3: 0 | AD3: 0 | AE3: 0 | AF3: 0 | AG3: 0 | AH3: 0 | AI3: 0 | AJ3: 0 | AK3: 0 | AL3: 0 | AM3: 0 | AN3: 0 | AO3: 0 | AP3: 0 | AQ3: 0 | AR3: 0 | AS3: 0 | AT3: 0 | AU3: 0 | AV3: 0 | AW3: 0 | AX3: 0 | AY3: 0 | AZ3: 0 | BA3: 0 | BB3: 0 | BC3: 0 | BD3: 0 | BE3: 0 | BF3: 0 | BG3: 0 | BH3: 0 | BI3: 0 | BJ3: 0 | BK3: 0 | BL3: 0 | BM3: 0 | BN3: 0 | BO3: 0 | BP3: 0 | BQ3: 0 | BR3: 0 | BS3: 0 | BT3: 0 | BU3: 0 | BV3: 0 | BW3: 0 | BX3: 0 | BY3: 0 | BZ3: 0 | CA3: 0 | CB3: 0 | CC3: 0 | CD3: 0 | CE3: 0 | CF3: 0 | CG3: 0 | CH3: 0 | CI3: 0 | CJ3: 0 | CK3: 0 | CL3: 0 | CM3: 0 | CN3: 0 | CO3: 0 | CP3: 0 | CQ3: 0 | CR3: 0 | CS3: 0 | CT3: 0 | CU3: 0 | CV3: 0 | CW3: 0 | CX3: 0 | CY3: 0 | CZ3: 0 | DA3: 0 | DB3: 0 | DC3: 0 | DD3: 0 | DE3: 0 | DF3: 0 | DG3: 0 | DH3: 0 | DI3: 0 | DJ3: 0 | DK3: 0 | DL3: 0 | DM3: 0 | DN3: 0 | DO3: 0 | DP3: 0 | DQ3: 0 | DR3: 0 | DS3: 0 | DT3: 0 | DU3: 0 | DV3: 0 | DW3: 0 | DX3: 0 | DY3: 0 | DZ3: 0 | EA3: 0 | EB3: 0 | EC3: 0 | ED3: 0 | EE3: 0 | EF3: 0 | EG3: 0 | EH3: 0 | EI3: 0 | EJ3: 0 | EK3: 0 | EL3: 0 | EM3: 0 | EN3: 0 | EO3: 0 | EP3: 0 | EQ3: 0 | ER3: 0 | ES3: 0 | ET3: 0 | EU3: 0 | EV3: 0 | EW3: 0 | EX3: 0 | EY3: 0 | EZ3: 0 | FA3: 0 | FB3: 0 | FC3: 0 | FD3: 0 | FE3: 0 | FF3: 0 | FG3: 0 | FH3: 0 | FI3: 0 | FJ3: 0 | FK3: 0 | FL3: 0 | FM3: 0 | FN3: 0 | FO3: 0 | FP3: 0 | FQ3: 0 | FR3: 0 | FS3: 0 | FT3: 0 | FU3: 0 | FV3: 0 | FW3: 0 | FX3: 0 | FY3: 0 | FZ3: 0 | GA3: 0 | GB3: 0 | GC3: 0 | GD3: 0 | GE3: 0 | GF3: 0 | GG3: 0 | GH3: 0 | GI3: 0 | GJ3: 0 | GK3: 0 | GL3: 0 | GM3: 0 | GN3: 0 | GO3: 0 | GP3: 0 | GQ3: 0 | GR3: 0 | GS3: 0 | GT3: 0 | GU3: 0 | GV3: 0 | GW3: 0 | GX3: 0 | GY3: 0 | GZ3: 0 | HA3: 0 | HB3: 0 | HC3: 0 | HD3: 0 | HE3: 0 | HF3: 0 | HG3: 0 | HH3: 0 | HI3: 0 | HJ3: 0 | HK3: 0 | HL3: 0 | HM3: 0 | HN3: 0 | HO3: 0 | HP3: 0 | HQ3: 0 | HR3: 0 | HS3: 0 | HT3: 0 | HU3: 0 | HV3: 0 | HW3: 0 | HX3: 0 | HY3: 0 | HZ3: 0 | IA3: 0
A4: 36526.007 | B4: 0 | C4: 0 | D4: 0 | E4: 0 | F4: 0 | G4: 0 | H4: 0 | I4: 0 | J4: 0 | K4: 0 | L4: 0 | M4: 0 | N4: 0 | O4: 0 | P4: 0 | Q4: 0 | R4: 0 | S4: 0 | T4: 0 | U4: 0 | V4: 0 | W4: 0 | X4: 0 | Y4: 0 | Z4: 0 | AA4: 0 | AB4: 0 | AC4: 0 | AD4: 0 | AE4: 0 | AF4: 0 | AG4: 0 | AH4: 0 | AI4: 0 | AJ4: 0 | AK4: 0 | AL4: 0 | AM4: 0 | AN4: 0 | AO4: 0 | AP4: 0 | AQ4: 0 | AR4: 0 | AS4: 0 | AT4: 0 | AU4: 0 | AV4: 0 | AW4: 0 | AX4: 0 | AY4: 0 | AZ4: 0 | BA4: 0 | BB4: 0 | BC4: 0 | BD4: 0 | BE4: 0 | BF4: 0 | BG4: 0 | BH4: 0 | BI4: 0 | BJ4: 0 | BK4: 0 | BL4: 0 | BM4: 0 | BN4: 0 | BO4: 0 | BP4: 0 | BQ4: 0 | BR4: 0 | BS4: 0 | BT4: 0 | BU4: 0 | BV4: 0 | BW4: 0 | BX4: 0 | BY4: 0 | BZ4: 0 | CA4: 0 | CB4: 0 | CC4: 0 | CD4: 0 | CE4: 0 | CF4: 0 | CG4: 0 | CH4: 0 | CI4: 0 | CJ4: 0 | CK4: 0 | CL4: 0 | CM4: 0 | CN4: 0 | CO4: 0 | CP4: 0 | CQ4: 0 | CR4: 0 | CS4: 0 | CT4: 0 | CU4: 0 | CV4: 0 | CW4: 0 | CX4: 0 | CY4: 0 | CZ4: 0 | DA4: 0 | DB4: 0 | DC4: 0 | DD4: 0 | DE4: 0 | DF4: 0 | DG4: 0 | DH4: 0 | DI4: 0 | DJ4: 0 | DK4: 0 | DL4: 0 | DM4: 0 | DN4: 0 | DO4: 0 | DP4: 0 | DQ4: 0 | DR4: 0 | DS4: 0 | DT4: 0 | DU4: 0 | DV4: 0 | DW4: 0 | DX4: 0 | DY4: 0 | DZ4: 0 | EA4: 0 | EB4: 0 | EC4: 0 | ED4: 0 | EE4: 0 | EF4: 0 | EG4: 0 | EH4: 0 | EI4: 0 | EJ4: 0 | EK4: 0 | EL4: 0 | EM4: 0 | EN4: 0 | EO4: 0 | EP4: 0 | EQ4: 0 | ER4: 0 | ES4: 0 | ET4: 0 | EU4: 0 | EV4: 0 | EW4: 0 | EX4: 0 | EY4: 0 | EZ4: 0 | FA4: 0 | FB4: 0 | FC4: 0 | FD4: 0 | FE4: 0 | FF4: 0 | FG4: 0 | FH4: 0 | FI4: 0 | FJ4: 0 | FK4: 0 | FL4: 0 | FM4: 0 | FN4: 0 | FO4: 0 | FP4: 0 | FQ4: 0 | FR4: 0 | FS4: 0 | FT4: 0 | FU4: 0 | FV4: 0 | FW4: 0 | FX4: 0 | FY4: 0 | FZ4: 0 | GA4: 0 | GB4: 0 | GC4: 0 | GD4: 0 | GE4: 0 | GF4: 0 | GG4: 0 | GH4: 0 | GI4: 0 | GJ4: 0 | GK4: 0 | GL4: 0 | GM4: 0 | GN4: 0 | GO4: 0 | GP4: 0 | GQ4: 0 | GR4: 0 | GS4: 0 | GT4: 0 | GU4: 0 | GV4: 0 | GW4: 0 | GX4: 0 | GY4: 0 | GZ4: 0 | HA4: 0 | HB4: 0 | HC4: 0 | HD4: 0 | HE4: 0 | HF4: 0 | HG4: 0 | HH4: 0 | HI4: 0 | HJ4: 0 | HK4: 0 | HL4: 0 | HM4: 0 | HN4: 0 | HO4: 0 | HP4: 0 | HQ4: 0 | HR4: 0 | HS4: 0 | HT4: 0 | HU4: 0 | HV4: 0 | HW4: 0 | HX4: 0 | HY4: 0 | HZ4: 0 | IA4: 0
A5: 36526.01 | B5: 0 | C5: 0 | D5: 0 | E5: 0 | F5: 0 | G5: 0 | H5: 0 | I5: 0 | J5: 0 | K5: 0 | L5: 0 | M5: 0 | N5: 0 | O5: 0 | P5: 0 | Q5: 0 | R5: 0 | S5: 0 | T5: 0 | U5: 0 | V5: 0 | W5: 0 | X5: 0 | Y5: 0 | Z5: 0 | AA5: 0 | AB5: 0 | AC5: 0 | AD5: 0 | AE5: 0 | AF5: 0 | AG5: 0 | AH5: 0 | AI5: 0 | AJ5: 0 | AK5: 0 | AL5: 0 | AM5: 0 | AN5: 0 | AO5: 0 | AP5: 0 | AQ5: 0 | AR5: 0 | AS5: 0 | AT5: 0 | AU5: 0 | AV5: 0 | AW5: 0 | AX5: 0 | AY5: 0 | AZ5: 0 | BA5: 0 | BB5: 0 | BC5: 0 | BD5: 0 | BE5: 0 | BF5: 0 | BG5: 0 | BH5: 0 | BI5: 0 | BJ5: 0 | BK5: 0 | BL5: 0 | BM5: 0 | BN5: 0 | BO5: 0 | BP5: 0 | BQ5: 0 | BR5: 0 | BS5: 0 | BT5: 0 | BU5: 0 | BV5: 0 | BW5: 0 | BX5: 0 | BY5: 0 | BZ5: 0 | CA5: 0 | CB5: 0 | CC5: 0 | CD5: 0 | CE5: 0 | CF5: 0 | CG5: 0 | CH5: 0 | CI5: 0 | CJ5: 0 | CK5: 0 | CL5: 0 | CM5: 0 | CN5: 0 | CO5: 0 | CP5: 0 | CQ5: 0 | CR5: 0 | CS5: 0 | CT5: 0 | CU5: 0 | CV5: 0 | CW5: 0 | CX5: 0 | CY5: 0 | CZ5: 0 | DA5: 0 | DB5: 0 | DC5: 0 | DD5: 0 | DE5: 0 | DF5: 0 | DG5: 0 | DH5: 0 | DI5: 0 | DJ5: 0 | DK5: 0 | DL5: 0 | DM5: 0 | DN5: 0 | DO5: 0 | DP5: 0 | DQ5: 0 | DR5: 0 | DS5: 0 | DT5: 0 | DU5: 0 | DV5: 0 | DW5: 0 | DX5: 0 | DY5: 0 | DZ5: 0 | EA5: 0 | EB5: 0 | EC5: 0 | ED5: 0 | EE5: 0 | EF5: 0 | EG5: 0 | EH5: 0 | EI5: 0 | EJ5: 0 | EK5: 0 | EL5: 0 | EM5: 0 | EN5: 0 | EO5: 0 | EP5: 0 | EQ5: 0 | ER5: 0 | ES5: 0 | ET5: 0 | EU5: 0 | EV5: 0 | EW5: 0 | EX5: 0 | EY5: 0 | EZ5: 0 | FA5: 0 | FB5: 0 | FC5: 0 | FD5: 0 | FE5: 0 | FF5: 0 | FG5: 0 | FH5: 0 | FI5: 0 | FJ5: 0 | FK5: 0 | FL5: 0 | FM5: 0 | FN5: 0 | FO5: 0 | FP5: 0 | FQ5: 0 | FR5: 0 | FS5: 0 | FT5: 0 | FU5: 0 | FV5: 0 | FW5: 0 | FX5: 0 | FY5: 0 | FZ5: 0 | GA5: 0 | GB5: 0 | GC5: 0 | GD5: 0 | GE5: 0 | GF5: 0 | GG5: 0 | GH5: 0 | GI5: 0 | GJ5: 0 | GK5: 0 | GL5: 0 | GM5: 0 | GN5: 0 | GO5: 0 | GP5: 0 | GQ5: 0 | GR5: 0 | GS5: 0 | GT5: 0 | GU5: 0 | GV5: 0 | GW5: 0 | GX5: 0 | GY5: 0 | GZ5: 0 | HA5: 0 | HB5: 0 | HC5: 0 | HD5: 0 | HE5: 0 | HF5: 0 | HG5: 0 | HH5: 0 | HI5: 0 | HJ5: 0 | HK5: 0 | HL5: 0 | HM5: 0 | HN5: 0 | HO5: 0 | HP5: 0 | HQ5: 0 | HR5: 0 | HS5: 0 | HT5: 0 | HU5: 0 | HV5: 0 | HW5: 0 | HX5: 0 | HY5: 0 | HZ5: 0 | IA5: 0
A6: 36526.014 | B6: 0 | C6: 0 | D6: 0 | E6: 0 | F6: 0 | G6: 0 | H6: 0 | I6: 0 | J6: 0 | K6: 0 | L6: 0 | M6: 0 | N6: 0 | O6: 0 | P6: 0 | Q6: 0 | R6: 0 | S6: 0 | T6: 0 | U6: 0 | V6: 0 | W6: 0 | X6: 0 | Y6: 0 | Z6: 0 | AA6: 0 | AB6: 0 | AC6: 0 | AD6: 0 | AE6: 0 | AF6: 0 | AG6: 0 | AH6: 0 | AI6: 0 | AJ6: 0 | AK6: 0 | AL6: 0 | AM6: 0 | AN6: 0 | AO6: 0 | AP6: 0 | AQ6: 0 | AR6: 0 | AS6: 0 | AT6: 0 | AU6: 0 | AV6: 0 | AW6: 0 | AX6: 0 | AY6: 0 | AZ6: 0 | BA6: 0 | BB6: 0 | BC6: 0 | BD6: 0 | BE6: 0 | BF6: 0 | BG6: 0 | BH6: 0 | BI6: 0 | BJ6: 0 | BK6: 0 | BL6: 0 | BM6: 0 | BN6: 0 | BO6: 0 | BP6: 0 | BQ6: 0 | BR6: 0 | BS6: 0 | BT6: 0 | BU6: 0 | BV6: 0 | BW6: 0 | BX6: 0 | BY6: 0 | BZ6: 0 | CA6: 0 | CB6: 0 | CC6: 0 | CD6: 0 | CE6: 0 | CF6: 0 | CG6: 0 | CH6: 0 | CI6: 0 | CJ6: 0 | CK6: 0 | CL6: 0 | CM6: 0 | CN6: 0 | CO6: 0 | CP6: 0 | CQ6: 0 | CR6: 0 | CS6: 0 | CT6: 0 | CU6: 0 | CV6: 0 | CW6: 0 | CX6: 0 | CY6: 0 | CZ6: 0 | DA6: 0 | DB6: 0 | DC6: 0 | DD6: 0 | DE6: 0 | DF6: 0 | DG6: 0 | DH6: 0 | DI6: 0 | DJ6: 0 | DK6: 0 | DL6: 0 | DM6: 0 | DN6: 0 | DO6: 0 | DP6: 0 | DQ6: 0 | DR6: 0 | DS6: 0 | DT6: 0 | DU6: 0 | DV6: 0 | DW6: 0 | DX6: 0 | DY6: 0 | DZ6: 0 | EA6: 0 | EB6: 0 | EC6: 0 | ED6: 0 | EE6: 0 | EF6: 0 | EG6: 0 | EH6: 0 | EI6: 0 | EJ6: 0 | EK6: 0 | EL6: 0 | EM6: 0 | EN6: 0 | EO6: 0 | EP6: 0 | EQ6: 0 | ER6: 0 | ES6: 0 | ET6: 0 | EU6: 0 | EV6: 0 | EW6: 0 | EX6: 0 | EY6: 0 | EZ6: 0 | FA6: 0 | FB6: 0 | FC6: 0 | FD6: 0 | FE6: 0 | FF6: 0 | FG6: 0 | FH6: 0 | FI6: 0 | FJ6: 0 | FK6: 0 | FL6: 0 | FM6: 0 | FN6: 0 | FO6: 0 | FP6: 0 | FQ6: 0 | FR6: 0 | FS6: 0 | FT6: 0 | FU6: 0 | FV6: 0 | FW6: 0 | FX6: 0 | FY6: 0 | FZ6: 0 | GA6: 0 | GB6: 0 | GC6: 0 | GD6: 0 | GE6: 0 | GF6: 0 | GG6: 0 | GH6: 0 | GI6: 0 | GJ6: 0 | GK6: 0 | GL6: 0 | GM6: 0 | GN6: 0 | GO6: 0 | GP6: 0 | GQ6: 0 | GR6: 0 | GS6: 0 | GT6: 0 | GU6: 0 | GV6: 0 | GW6: 0 | GX6: 0 | GY6: 0 | GZ6: 0 | HA6: 0 | HB6: 0 | HC6: 0 | HD6: 0 | HE6: 0 | HF6: 0 | HG6: 0 | HH6: 0 | HI6: 0 | HJ6: 0 | HK6: 0 | HL6: 0 | HM6: 0 | HN6: 0 | HO6: 0 | HP6: 0 | HQ6: 0 | HR6: 0 | HS6: 0 | HT6: 0 | HU6: 0 | HV6: 0 | HW6: 0 | HX6: 0 | HY6: 0 | HZ6: 0 | IA6: 0
A7: 36526.017 | B7: 0 | C7: 0 | D7: 0 | E7: 0 | F7: 0 | G7: 0 | H7: 0 | I7: 0 | J7: 0 | K7: 0 | L7: 0 | M7: 0 | N7: 0 | O7: 0 | P7: 0 | Q7: 0 | R7: 0 | S7: 0 | T7: 0 | U7: 0 | V7: 0 | W7: 0 | X7: 0 | Y7: 0 | Z7: 0 | AA7: 0 | AB7: 0 | AC7: 0 | AD7: 0 | AE7: 0 | AF7: 0 | AG7: 0 | AH7: 0 | AI7: 0 | AJ7: 0 | AK7: 0 | AL7: 0 | AM7: 0 | AN7: 0 | AO7: 0 | AP7: 0 | AQ7: 0 | AR7: 0 | AS7: 0 | AT7: 0 | AU7: 0 | AV7: 0 | AW7: 0 | AX7: 0 | AY7: 0 | AZ7: 0 | BA7: 0 | BB7: 0 | BC7: 0 | BD7: 0 | BE7: 0 | BF7: 0 | BG7: 0 | BH7: 0 | BI7: 0 | BJ7: 0 | BK7: 0 | BL7: 0 | BM7: 0 | BN7: 0 | BO7: 0 | BP7: 0 | BQ7: 0 | BR7: 0 | BS7: 0 | BT7: 0 | BU7: 0 | BV7: 0 | BW7: 0 | BX7: 0 | BY7: 0 | BZ7: 0 | CA7: 0 | CB7: 0 | CC7: 0 | CD7: 0 | CE7: 0 | CF7: 0 | CG7: 0 | CH7: 0 | CI7: 0 | CJ7: 0 | CK7: 0 | CL7: 0 | CM7: 0 | CN7: 0 | CO7: 0 | CP7: 0 | CQ7: 0 | CR7: 0 | CS7: 0 | CT7: 0 | CU7: 0 | CV7: 0 | CW7: 0 | CX7: 0 | CY7: 0 | CZ7: 0 | DA7: 0 | DB7: 0 | DC7: 0 | DD7: 0 | DE7: 0 | DF7: 0 | DG7: 0 | DH7: 0 | DI7: 0 | DJ7: 0 | DK7: 0 | DL7: 0 | DM7: 0 | DN7: 0 | DO7: 0 | DP7: 0 | DQ7: 0 | DR7: 0 | DS7: 0 | DT7: 0 | DU7: 0 | DV7: 0 | DW7: 0 | DX7: 0 | DY7: 0 | DZ7: 0 | EA7: 0 | EB7: 0 | EC7: 0 | ED7: 0 | EE7: 0 | EF7: 0 | EG7: 0 | EH7: 0 | EI7: 0 | EJ7: 0 | EK7: 0 | EL7: 0 | EM7: 0 | EN7: 0 | EO7: 0 | EP7: 0 | EQ7: 0 | ER7: 0 | ES7: 0 | ET7: 0 | EU7: 0 | EV7: 0 | EW7: 0 | EX7: 0 | EY7: 0 | EZ7: 0 | FA7: 0 | FB7: 0 | FC7: 0 | FD7: 0 | FE7: 0 | FF7: 0 | FG7: 0 | FH7: 0 | FI7: 0 | FJ7: 0 | FK7: 0 | FL7: 0 | FM7: 0 | FN7: 0 | FO7: 0 | FP7: 0 | FQ7: 0 | FR7: 0 | FS7: 0 | FT7: 0 | FU7: 0 | FV7: 0 | FW7: 0 | FX7: 0 | FY7: 0 | FZ7: 0 | GA7: 0 | GB7: 0 | GC7: 0 | GD7: 0 | GE7: 0 | GF7: 0 | GG7: 0 | GH7: 0 | GI7: 0 | GJ7: 0 | GK7: 0 | GL7: 0 | GM7: 0 | GN7: 0 | GO7: 0 | GP7: 0 | GQ7: 0 | GR7: 0 | GS7: 0 | GT7: 0 | GU7: 0 | GV7: 0 | GW7: 0 | GX7: 0 | GY7: 0 | GZ7: 0 | HA7: 0 | HB7: 0 | HC7: 0 | HD7: 0 | HE7: 0 | HF7: 0 | HG7: 0 | HH7: 0 | HI7: 0 | HJ7: 0 | HK7: 0 | HL7: 0 | HM7: 0 | HN7: 0 | HO7: 0 | HP7: 0 | HQ7: 0 | HR7: 0 | HS7: 0 | HT7: 0 | HU7: 0 | HV7: 0 | HW7: 0 | HX7: 0 | HY7: 0 | HZ7: 0 | IA7: 0
A8: 36526.021 | B8: 0 | C8: 0 | D8: 0 | E8: 0 | F8: 0 | G8: 0 | H8: 0 | I8: 0 | J8: 0 | K8: 0 | L8: 0 | M8: 0 | N8: 0 | O8: 0 | P8: 0 | Q8: 0 | R8: 0 | S8: 0 | T8: 0 | U8: 0 | V8: 0 | W8: 0 | X8: 0 | Y8: 0 | Z8: 0 | AA8: 0 | AB8: 0 | AC8: 0 | AD8: 0 | AE8: 0 | AF8: 0 | AG8: 0 | AH8: 0 | AI8: 0 | AJ8: 0 | AK8: 0 | AL8: 0 | AM8: 0 | AN8: 0 | AO8: 0 | AP8: 0 | AQ8: 0 | AR8: 0 | AS8: 0 | AT8: 0 | AU8: 0 | AV8: 0 | AW8: 0 | AX8: 0 | AY8: 0 | AZ8: 0 | BA8: 0 | BB8: 0 | BC8: 0 | BD8: 0 | BE8: 0 | BF8: 0 | BG8: 0 | BH8: 0 | BI8: 0 | BJ8: 0 | BK8: 0 | BL8: 0 | BM8: 0 | BN8: 0 | BO8: 0 | BP8: 0 | BQ8: 0 | BR8: 0 | BS8: 0 | BT8: 0 | BU8: 0 | BV8: 0 | BW8: 0 | BX8: 0 | BY8: 0 | BZ8: 0 | CA8: 0 | CB8: 0 | CC8: 0 | CD8: 0 | CE8: 0 | CF8: 0 | CG8: 0 | CH8: 0 | CI8: 0 | CJ8: 0 | CK8: 0 | CL8: 0 | CM8: 0 | CN8: 0 | CO8: 0 | CP8: 0 | CQ8: 0 | CR8: 0 | CS8: 0 | CT8: 0 | CU8: 0 | CV8: 0 | CW8: 0 | CX8: 0 | CY8: 0 | CZ8: 0 | DA8: 0 | DB8: 0 | DC8: 0 | DD8: 0 | DE8: 0 | DF8: 0 | DG8: 0 | DH8: 0 | DI8: 0 | DJ8: 0 | DK8: 0 | DL8: 0 | DM8: 0 | DN8: 0 | DO8: 0 | DP8: 0 | DQ8: 0 | DR8: 0 | DS8: 0 | DT8: 0 | DU8: 0 | DV8: 0 | DW8: 0 | DX8: 0 | DY8: 0 | DZ8: 0 | EA8: 0 | EB8: 0 | EC8: 0 | ED8: 0 | EE8: 0 | EF8: 0 | EG8: 0 | EH8: 0 | EI8: 0 | EJ8: 0 | EK8: 0 | EL8: 0 | EM8: 0 | EN8: 0 | EO8: 0 | EP8: 0 | EQ8: 0 | ER8: 0 | ES8: 0 | ET8: 0 | EU8: 0 | EV8: 0 | EW8: 0 | EX8: 0 | EY8: 0 | EZ8: 0 | FA8: 0 | FB8: 0 | FC8: 0 | FD8: 0 | FE8: 0 | FF8: 0 | FG8: 0 | FH8: 0 | FI8: 0 | FJ8: 0 | FK8: 0 | FL8: 0 | FM8: 0 | FN8: 0 | FO8: 0 | FP8: 0 | FQ8: 0 | FR8: 0 | FS8: 0 | FT8: 0 | FU8: 0 | FV8: 0 | FW8: 0 | FX8: 0 | FY8: 0 | FZ8: 0 | GA8: 0 | GB8: 0 | GC8: 0 | GD8: 0 | GE8: 0 | GF8: 0 | GG8: 0 | GH8: 0 | GI8: 0 | GJ8: 0 | GK8: 0 | GL8: 0 | GM8: 0 | GN8: 0 | GO8: 0 | GP8: 0 | GQ8: 0 | GR8: 0 | GS8: 0 | GT8: 0 | GU8: 0 | GV8: 0 | GW8: 0 | GX8: 0 | GY8: 0 | GZ8: 0 | HA8: 0 | HB8: 0 | HC8: 0 | HD8: 0 | HE8: 0 | HF8: 0 | HG8: 0 | HH8: 0 | HI8: 0 | HJ8: 0 | HK8: 0 | HL8: 0 | HM8: 0 | HN8: 0 | HO8: 0 | HP8: 0 | HQ8: 0 | HR8: 0 | HS8: 0 | HT8: 0 | HU8: 0 | HV8: 0 | HW8: 0 | HX8: 0 | HY8: 0 | HZ8: 0 | IA8: 0
A9: 36526.024 | B9: 0 | C9: 0 | D9: 0 | E9: 0 | F9: 0 | G9: 0 | H9: 0 | I9: 0 | J9: 0 | K9: 0 | L9: 0 | M9: 0 | N9: 0 | O9: 0 | P9: 0 | Q9: 0 | R9: 0 | S9: 0 | T9: 0 | U9: 0 | V9: 0 | W9: 0 | X9: 0 | Y9: 0 | Z9: 0 | AA9: 0 | AB9: 0 | AC9: 0 | AD9: 0 | AE9: 0 | AF9: 0 | AG9: 0 | AH9: 0 | AI9: 0 | AJ9: 0 | AK9: 0 | AL9: 0 | AM9: 0 | AN9: 0 | AO9: 0 | AP9: 0 | AQ9: 0 | AR9: 0 | AS9: 0 | AT9: 0 | AU9: 0 | AV9: 0 | AW9: 0 | AX9: 0 | AY9: 0 | AZ9: 0 | BA9: 0 | BB9: 0 | BC9: 0 | BD9: 0 | BE9: 0 | BF9: 0 | BG9: 0 | BH9: 0 | BI9: 0 | BJ9: 0 | BK9: 0 | BL9: 0 | BM9: 0 | BN9: 0 | BO9: 0 | BP9: 0 | BQ9: 0 | BR9: 0 | BS9: 0 | BT9: 0 | BU9: 0 | BV9: 0 | BW9: 0 | BX9: 0 | BY9: 0 | BZ9: 0 | CA9: 0 | CB9: 0 | CC9: 0 | CD9: 0 | CE9: 0 | CF9: 0 | CG9: 0 | CH9: 0 | CI9: 0 | CJ9: 0 | CK9: 0 | CL9: 0 | CM9: 0 | CN9: 0 | CO9: 0 | CP9: 0 | CQ9: 0 | CR9: 0 | CS9: 0 | CT9: 0 | CU9: 0 | CV9: 0 | CW9: 0 | CX9: 0 | CY9: 0 | CZ9: 0 | DA9: 0 | DB9: 0 | DC9: 0 | DD9: 0 | DE9: 0 | DF9: 0 | DG9: 0 | DH9: 0 | DI9: 0 | DJ9: 0 | DK9: 0 | DL9: 0 | DM9: 0 | DN9: 0 | DO9: 0 | DP9: 0 | DQ9: 0 | DR9: 0 | DS9: 0 | DT9: 0 | DU9: 0 | DV9: 0 | DW9: 0 | DX9: 0 | DY9: 0 | DZ9: 0 | EA9: 0 | EB9: 0 | EC9: 0 | ED9: 0 | EE9: 0 | EF9: 0 | EG9: 0 | EH9: 0 | EI9: 0 | EJ9: 0 | EK9: 0 | EL9: 0 | EM9: 0 | EN9: 0 | EO9: 0 | EP9: 0 | EQ9: 0 | ER9: 0 | ES9: 0 | ET9: 0 | EU9: 0 | EV9: 0 | EW9: 0 | EX9: 0 | EY9: 0 | EZ9: 0 | FA9: 0 | FB9: 0 | FC9: 0 | FD9: 0 | FE9: 0 | FF9: 0 | FG9: 0 | FH9: 0 | FI9: 0 | FJ9: 0 | FK9: 0 | FL9: 0 | FM9: 0 | FN9: 0 | FO9: 0 | FP9: 0 | FQ9: 0 | FR9: 0 | FS9: 0 | FT9: 0 | FU9: 0 | FV9: 0 | FW9: 0 | FX9: 0 | FY9: 0 | FZ9: 0 | GA9: 0 | GB9: 0 | GC9: 0 | GD9: 0 | GE9: 0 | GF9: 0 | GG9: 0 | GH9: 0 | GI9: 0 | GJ9: 0 | GK9: 0 | GL9: 0 | GM9: 0 | GN9: 0 | GO9: 0 | GP9: 0 | GQ9: 0 | GR9: 0 | GS9: 0 | GT9: 0 | GU9: 0 | GV9: 0 | GW9: 0 | GX9: 0 | GY9: 0 | GZ9: 0 | HA9: 0 | HB9: 0 | HC9: 0 | HD9: 0 | HE9: 0 | HF9: 0 | HG9: 0 | HH9: 0 | HI9: 0 | HJ9: 0 | HK9: 0 | HL9: 0 | HM9: 0 | HN9: 0 | HO9: 0 | HP9: 0 | HQ9: 0 | HR9: 0 | HS9: 0 | HT9: 0 | HU9: 0 | HV9: 0 | HW9: 0 | HX9: 0 | HY9: 0 | HZ9: 0 | IA9: 0
A10: 36526.028 | B10: 0 | C10: 0 | D10: 0 | E10: 0 | F10: 0 | G10: 0 | H10: 0 | I10: 0 | J10: 0 | K10: 0 | L10: 0 | M10: 0 | N10: 0 | O10: 0 | P10: 0 | Q10: 0 | R10: 0 | S10: 0 | T10: 0 | U10: 0 | V10: 0 | W10: 0 | X10: 0 | Y10: 0 | Z10: 0 | AA10: 0 | AB10: 0 | AC10: 0 | AD10: 0 | AE10: 0 | AF10: 0 | AG10: 0 | AH10: 0 | AI10: 0 | AJ10: 0 | AK10: 0 | AL10: 0 | AM10: 0 | AN10: 0 | AO10: 0 | AP10: 0 | AQ10: 0 | AR10: 0 | AS10: 0 | AT10: 0 | AU10: 0 | AV10: 0 | AW10: 0 | AX10: 0 | AY10: 0 | AZ10: 0 | BA10: 0 | BB10: 0 | BC10: 0 | BD10: 0 | BE10: 0 | BF10: 0 | BG10: 0 | BH10: 0 | BI10: 0 | BJ10: 0 | BK10: 0 | BL10: 0 | BM10: 0 | BN10: 0 | BO10: 0 | BP10: 0 | BQ10: 0 | BR10: 0 | BS10: 0 | BT10: 0 | BU10: 0 | BV10: 0 | BW10: 0 | BX10: 0 | BY10: 0 | BZ10: 0 | CA10: 0 | CB10: 0 | CC10: 0 | CD10: 0 | CE10: 0 | CF10: 0 | CG10: 0 | CH10: 0 | CI10: 0 | CJ10: 0 | CK10: 0 | CL10: 0 | CM10: 0 | CN10: 0 | CO10: 0 | CP10: 0 | CQ10: 0 | CR10: 0 | CS10: 0 | CT10: 0 | CU10: 0 | CV10: 0 | CW10: 0 | CX10: 0 | CY10: 0 | CZ10: 0 | DA10: 0 | DB10: 0 | DC10: 0 | DD10: 0 | DE10: 0 | DF10: 0 | DG10: 0 | DH10: 0 | DI10: 0 | DJ10: 0 | DK10: 0 | DL10: 0 | DM10: 0 | DN10: 0 | DO10: 0 | DP10: 0 | DQ10: 0 | DR10: 0 | DS10: 0 | DT10: 0 | DU10: 0 | DV10: 0 | DW10: 0 | DX10: 0 | DY10: 0 | DZ10: 0 | EA10: 0 | EB10: 0 | EC10: 0 | ED10: 0 | EE10: 0 | EF10: 0 | EG10: 0 | EH10: 0 | EI10: 0 | EJ10: 0 | EK10: 0 | EL10: 0 | EM10: 0 | EN10: 0 | EO10: 0 | EP10: 0 | EQ10: 0 | ER10: 0 | ES10: 0 | ET10: 0 | EU10: 0 | EV10: 0 | EW10: 0 | EX10: 0 | EY10: 0 | EZ10: 0 | FA10: 0 | FB10: 0 | FC10: 0 | FD10: 0 | FE10: 0 | FF10: 0 | FG10: 0 | FH10: 0 | FI10: 0 | FJ10: 0 | FK10: 0 | FL10: 0 | FM10: 0 | FN10: 0 | FO10: 0 | FP10: 0 | FQ10: 0 | FR10: 0 | FS10: 0 | FT10: 0 | FU10: 0 | FV10: 0 | FW10: 0 | FX10: 0 | FY10: 0 | FZ10: 0 | GA10: 0 | GB10: 0 | GC10: 0 | GD10: 0 | GE10: 0 | GF10: 0 | GG10: 0 | GH10: 0 | GI10: 0 | GJ10: 0 | GK10: 0 | GL10: 0 | GM10: 0 | GN10: 0 | GO10: 0 | GP10: 0 | GQ10: 0 | GR10: 0 | GS10: 0 | GT10: 0 | GU10: 0 | GV10: 0 | GW10: 0 | GX10: 0 | GY10: 0 | GZ10: 0 | HA10: 0 | HB10: 0 | HC10: 0 | HD10: 0 | HE10: 0 | HF10: 0 | HG10: 0 | HH10: 0 | HI10: 0 | HJ10: 0 | HK10: 0 | HL10: 0 | HM10: 0 | HN10: 0 | HO10: 0 | HP10: 0 | HQ10: 0 | HR10: 0 | HS10: 0 | HT10: 0 | HU10: 0 | HV10: 0 | HW10: 0 | HX10: 0 | HY10: 0 | HZ10: 0 | IA10: 0
A11: 36526.031 | B11: 0 | C11: 0 | D11: 0 | E11: 0 | F11: 0 | G11: 0 | H11: 0 | I11: 0 | J11: 0 | K11: 0 | L11: 0 | M11: 0 | N11: 0 | O11: 0 | P11: 0 | Q11: 0 | R11: 0 | S11: 0 | T11: 0 | U11: 0 | V11: 0 | W11: 0 | X11: 0 | Y11: 0 | Z11: 0 | AA11: 0 | AB11: 0 | AC11: 0 | AD11: 0 | AE11: 0 | AF11: 0 | AG11: 0 | AH11: 0 | AI11: 0 | AJ11: 0 | AK11: 0 | AL11: 0 | AM11: 0 | AN11: 0 | AO11: 0 | AP11: 0 | AQ11: 0 | AR11: 0 | AS11: 0 | AT11: 0 | AU11: 0 | AV11: 0 | AW11: 0 | AX11: 0 | AY11: 0 | AZ11: 0 | BA11: 0 | BB11: 0 | BC11: 0 | BD11: 0 | BE11: 0 | BF11: 0 | BG11: 0 | BH11: 0 | BI11: 0 | BJ11: 0 | BK11: 0 | BL11: 0 | BM11: 0 | BN11: 0 | BO11: 0 | BP11: 0 | BQ11: 0 | BR11: 0 | BS11: 0 | BT11: 0 | BU11: 0 | BV11: 0 | BW11: 0 | BX11: 0 | BY11: 0 | BZ11: 0 | CA11: 0 | CB11: 0 | CC11: 0 | CD11: 0 | CE11: 0 | CF11: 0 | CG11: 0 | CH11: 0 | CI11: 0 | CJ11: 0 | CK11: 0 | CL11: 0 | CM11: 0 | CN11: 0 | CO11: 0 | CP11: 0 | CQ11: 0 | CR11: 0 | CS11: 0 | CT11: 0 | CU11: 0 | CV11: 0 | CW11: 0 | CX11: 0 | CY11: 0 | CZ11: 0 | DA11: 0 | DB11: 0 | DC11: 0 | DD11: 0 | DE11: 0 | DF11: 0 | DG11: 0 | DH11: 0 | DI11: 0 | DJ11: 0 | DK11: 0 | DL11: 0 | DM11: 0 | DN11: 0 | DO11: 0 | DP11: 0 | DQ11: 0 | DR11: 0 | DS11: 0 | DT11: 0 | DU11: 0 | DV11: 0 | DW11: 0 | DX11: 0 | DY11: 0 | DZ11: 0 | EA11: 0 | EB11: 0 | EC11: 0 | ED11: 0 | EE11: 0 | EF11: 0 | EG11: 0 | EH11: 0 | EI11: 0 | EJ11: 0 | EK11: 0 | EL11: 0 | EM11: 0 | EN11: 0 | EO11: 0 | EP11: 0 | EQ11: 0 | ER11: 0 | ES11: 0 | ET11: 0 | EU11: 0 | EV11: 0 | EW11: 0 | EX11: 0 | EY11: 0 | EZ11: 0 | FA11: 0 | FB11: 0 | FC11: 0 | FD11: 0 | FE11: 0 | FF11: 0 | FG11: 0 | FH11: 0 | FI11: 0 | FJ11: 0 | FK11: 0 | FL11: 0 | FM11: 0 | FN11: 0 | FO11: 0 | FP11: 0 | FQ11: 0 | FR11: 0 | FS11: 0 | FT11: 0 | FU11: 0 | FV11: 0 | FW11: 0 | FX11: 0 | FY11: 0 | FZ11: 0 | GA11: 0 | GB11: 0 | GC11: 0 | GD11: 0 | GE11: 0 | GF11: 0 | GG11: 0 | GH11: 0 | GI11: 0 | GJ11: 0 | GK11: 0 | GL11: 0 | GM11: 0 | GN11: 0 | GO11: 0 | GP11: 0 | GQ11: 0 | GR11: 0 | GS11: 0 | GT11: 0 | GU11: 0 | GV11: 0 | GW11: 0 | GX11: 0 | GY11: 0 | GZ11: 0 | HA11: 0 | HB11: 0 | HC11: 0 | HD11: 0 | HE11: 0 | HF11: 0 | HG11: 0 | HH11: 0 | HI11: 0 | HJ11: 0 | HK11: 0 | HL11: 0 | HM11: 0 | HN11: 0 | HO11: 0 | HP11: 0 | HQ11: 0 | HR11: 0 | HS11: 0 | HT11: 0 | HU11: 0 | HV11: 0 | HW11: 0 | HX11: 0 | HY11: 0 | HZ11: 0 | IA11: 0
A12: 36526.035 | B12: 0 | C12: 0 | D12: 0 | E12: 0 | F12: 0 | G12: 0 | H12: 0 | I12: 0 | J12: 0 | K12: 0 | L12: 0 | M12: 0 | N12: 0 | O12: 0 | P12: 0 | Q12: 0 | R12: 0 | S12: 0 | T12: 0 | U12: 0 | V12: 0 | W12: 0 | X12: 0 | Y12: 0 | Z12: 0 | AA12: 0 | AB12: 0 | AC12: 0 | AD12: 0 | AE12: 0 | AF12: 0 | AG12: 0 | AH12: 0 | AI12: 0 | AJ12: 0 | AK12: 0 | AL12: 0 | AM12: 0 | AN12: 0 | AO12: 0 | AP12: 0 | AQ12: 0 | AR12: 0 | AS12: 0 | AT12: 0 | AU12: 0 | AV12: 0 | AW12: 0 | AX12: 0 | AY12: 0 | AZ12: 0 | BA12: 0 | BB12: 0 | BC12: 0 | BD12: 0 | BE12: 0 | BF12: 0 | BG12: 0 | BH12: 0 | BI12: 0 | BJ12: 0 | BK12: 0 | BL12: 0 | BM12: 0 | BN12: 0 | BO12: 0 | BP12: 0 | BQ12: 0 | BR12: 0 | BS12: 0 | BT12: 0 | BU12: 0 | BV12: 0 | BW12: 0 | BX12: 0 | BY12: 0 | BZ12: 0 | CA12: 0 | CB12: 0 | CC12: 0 | CD12: 0 | CE12: 0 | CF12: 0 | CG12: 0 | CH12: 0 | CI12: 0 | CJ12: 0 | CK12: 0 | CL12: 0 | CM12: 0 | CN12: 0 | CO12: 0 | CP12: 0 | CQ12: 0 | CR12: 0 | CS12: 0 | CT12: 0 | CU12: 0 | CV12: 0 | CW12: 0 | CX12: 0 | CY12: 0 | CZ12: 0 | DA12: 0 | DB12: 0 | DC12: 0 | DD12: 0 | DE12: 0 | DF12: 0 | DG12: 0 | DH12: 0 | DI12: 0 | DJ12: 0 | DK12: 0 | DL12: 0 | DM12: 0 | DN12: 0 | DO12: 0 | DP12: 0 | DQ12: 0 | DR12: 0 | DS12: 0 | DT12: 0 | DU12: 0 | DV12: 0 | DW12: 0 | DX12: 0 | DY12: 0 | DZ12: 0 | EA12: 0 | EB12: 0 | EC12: 0 | ED12: 0 | EE12: 0 | EF12: 0 | EG12: 0 | EH12: 0 | EI12: 0 | EJ12: 0 | EK12: 0 | EL12: 0 | EM12: 0 | EN12: 0 | EO12: 0 | EP12: 0 | EQ12: 0 | ER12: 0 | ES12: 0 | ET12: 0 | EU12: 0 | EV12: 0 | EW12: 0 | EX12: 0 | EY12: 0 | EZ12: 0 | FA12: 0 | FB12: 0 | FC12: 0 | FD12: 0 | FE12: 0 | FF12: 0 | FG12: 0 | FH12: 0 | FI12: 0 | FJ12: 0 | FK12: 0 | FL12: 0 | FM12: 0 | FN12: 0 | FO12: 0 | FP12: 0 | FQ12: 0 | FR12: 0 | FS12: 0 | FT12: 0 | FU12: 0 | FV12: 0 | FW12: 0 | FX12: 0 | FY12: 0 | FZ12: 0 | GA12: 0 | GB12: 0 | GC12: 0 | GD12: 0 | GE12: 0 | GF12: 0 | GG12: 0 | GH12: 0 | GI12: 0 | GJ12: 0 | GK12: 0 | GL12: 0 | GM12: 0 | GN12: 0 | GO12: 0 | GP12: 0 | GQ12: 0 | GR12: 0 | GS12: 0 | GT12: 0 | GU12: 0 | GV12: 0 | GW12: 0 | GX12: 0 | GY12: 0 | GZ12: 0 | HA12: 0 | HB12: 0 | HC12: 0 | HD12: 0 | HE12: 0 | HF12: 0 | HG12: 0 | HH12: 0 | HI12: 0 | HJ12: 0 | HK12: 0 | HL12: 0 | HM12: 0 | HN12: 0 | HO12: 0 | HP12: 0 | HQ12: 0 | HR12: 0 | HS12: 0 | HT12: 0 | HU12: 0 | HV12: 0 | HW12: 0 | HX12: 0 | HY12: 0 | HZ12: 0 | IA12: 0
A13: 36526.038 | B13: 0 | C13: 0 | D13: 0 | E13: 0 | F13: 0 | G13: 0 | H13: 0 | I13: 0 | J13: 0 | K13: 0 | L13: 0 | M13: 0 | N13: 0 | O13: 0 | P13: 0 | Q13: 0 | R13: 0 | S13: 0 | T13: 0 | U13: 0 | V13: 0 | W13: 0 | X13: 0 | Y13: 0 | Z13: 0 | AA13: 0 | AB13: 0 | AC13: 0 | AD13: 0 | AE13: 0 | AF13: 0 | AG13: 0 | AH13: 0 | AI13: 0 | AJ13: 0 | AK13: 0 | AL13: 0 | AM13: 0 | AN13: 0 | AO13: 0 | AP13: 0 | AQ13: 0 | AR13: 0 | AS13: 0 | AT13: 0 | AU13: 0 | AV13: 0 | AW13: 0 | AX13: 0 | AY13: 0 | AZ13: 0 | BA13: 0 | BB13: 0 | BC13: 0 | BD13: 0 | BE13: 0 | BF13: 0 | BG13: 0 | BH13: 0 | BI13: 0 | BJ13: 0 | BK13: 0 | BL13: 0 | BM13: 0 | BN13: 0 | BO13: 0 | BP13: 0 | BQ13: 0 | BR13: 0 | BS13: 0 | BT13: 0 | BU13: 0 | BV13: 0 | BW13: 0 | BX13: 0 | BY13: 0 | BZ13: 0 | CA13: 0 | CB13: 0 | CC13: 0 | CD13: 0 | CE13: 0 | CF13: 0 | CG13: 0 | CH13: 0 | CI13: 0 | CJ13: 0 | CK13: 0 | CL13: 0 | CM13: 0 | CN13: 0 | CO13: 0 | CP13: 0 | CQ13: 0 | CR13: 0 | CS13: 0 | CT13: 0 | CU13: 0 | CV13: 0 | CW13: 0 | CX13: 0 | CY13: 0 | CZ13: 0 | DA13: 0 | DB13: 0 | DC13: 0 | DD13: 0 | DE13: 0 | DF13: 0 | DG13: 0 | DH13: 0 | DI13: 0 | DJ13: 0 | DK13: 0 | DL13: 0 | DM13: 0 | DN13: 0 | DO13: 0 | DP13: 0 | DQ13: 0 | DR13: 0 | DS13: 0 | DT13: 0 | DU13: 0 | DV13: 0 | DW13: 0 | DX13: 0 | DY13: 0 | DZ13: 0 | EA13: 0 | EB13: 0 | EC13: 0 | ED13: 0 | EE13: 0 | EF13: 0 | EG13: 0 | EH13: 0 | EI13: 0 | EJ13: 0 | EK13: 0 | EL13: 0 | EM13: 0 | EN13: 0 | EO13: 0 | EP13: 0 | EQ13: 0 | ER13: 0 | ES13: 0 | ET13: 0 | EU13: 0 | EV13: 0 | EW13: 0 | EX13: 0 | EY13: 0 | EZ13: 0 | FA13: 0 | FB13: 0 | FC13: 0 | FD13: 0 | FE13: 0 | FF13: 0 | FG13: 0 | FH13: 0 | FI13: 0 | FJ13: 0 | FK13: 0 | FL13: 0 | FM13: 0 | FN13: 0 | FO13: 0 | FP13: 0 | FQ13: 0 | FR13: 0 | FS13: 0 | FT13: 0 | FU13: 0 | FV13: 0 | FW13: 0 | FX13: 0 | FY13: 0 | FZ13: 0 | GA13: 0 | GB13: 0 | GC13: 0 | GD13: 0 | GE13: 0 | GF13: 0 | GG13: 0 | GH13: 0 | GI13: 0 | GJ13: 0 | GK13: 0 | GL13: 0 | GM13: 0 | GN13: 0 | GO13: 0 | GP13: 0 | GQ13: 0 | GR13: 0 | GS13: 0 | GT13: 0 | GU13: 0 | GV13: 0 | GW13: 0 | GX13: 0 | GY13: 0 | GZ13: 0 | HA13: 0 | HB13: 0 | HC13: 0 | HD13: 0 | HE13: 0 | HF13: 0 | HG13: 0 | HH13: 0 | HI13: 0 | HJ13: 0 | HK13: 0 | HL13: 0 | HM13: 0 | HN13: 0 | HO13: 0 | HP13: 0 | HQ13: 0 | HR13: 0 | HS13: 0 | HT13: 0 | HU13: 0 | HV13: 0 | HW13: 0 | HX13: 0 | HY13: 0 | HZ13: 0 | IA13: 0
... A578: 36528 | B578: 0 | C578: 0 | D578: 0 | E578: 0 | F578: 0 | G578: 0 | H578: 0 | I578: 0 | J578: 0 | K578: 0 | L578: 0 | M578: 0 | N578: 0 | O578: 0 | P578: 0 | Q578: 0 | R578: 0 | S578: 0 | T578: 0 | U578: 0 | V578: 0 | W578: 0 | X578: 0 | Y578: 0 | Z578: 0 | AA578: 0 | AB578: 0 | AC578: 0 | AD578: 0 | AE578: 0 | AF578: 0 | AG578: 0 | AH578: 0 | AI578: 0 | AJ578: 0 | AK578: 0 | AL578: 0 | AM578: 0.001 | AN578: 0 | AO578: 0 | AP578: 0.433 | AQ578: 0 | AR578: 0 | AS578: 0 | AT578: 0 | AU578: 0 | AV578: 0 | AW578: 0 | AX578: 0 | AY578: 0 | AZ578: 0 | BA578: 0 | BB578: 0 | BC578: 0 | BD578: 0 | BE578: 0.002 | BF578: 0 | BG578: 0 | BH578: 0.498 | BI578: 0 | BJ578: 0 | BK578: 0 | BL578: 0 | BM578: 0 | BN578: 0 | BO578: 0 | BP578: 0 | BQ578: 0 | BR578: 0 | BS578: 0 | BT578: 0 | BU578: 0 | BV578: 0 | BW578: 0.003 | BX578: 0 | BY578: 0 | BZ578: 0.55 | CA578: 0 | CB578: 0 | CC578: 0 | CD578: 0 | CE578: 0 | CF578: 0 | CG578: 0 | CH578: 0 | CI578: 0 | CJ578: 0 | CK578: 0 | CL578: 0 | CM578: 0 | CN578: 0 | CO578: 0.003 | CP578: 0 | CQ578: 0 | CR578: 0.607 | CS578: 0 | CT578: 0 | CU578: 0 | CV578: 0 | CW578: 0 | CX578: 0 | CY578: 0 | CZ578: 0 | DA578: 0 | DB578: 0 | DC578: 0 | DD578: 0 | DE578: 0 | DF578: 0 | DG578: 0.005 | DH578: 0 | DI578: 0 | DJ578: 0.781 | DK578: 2.399 | DL578: 0 | DM578: 0 | DN578: 0 | DO578: 0 | DP578: 0 | DQ578: 0 | DR578: 0 | DS578: 0 | DT578: 0 | DU578: 0 | DV578: 0 | DW578: 0 | DX578: 0 | DY578: 0.007 | DZ578: 0 | EA578: 0 | EB578: 0.882 | EC578: 2.722 | ED578: 0 | EE578: 0.005 | EF578: 0.02 | EG578: 0.046 | EH578: 0 | EI578: 0.017 | EJ578: 0 | EK578: 0 | EL578: 0 | EM578: 0.001 | EN578: 0 | EO578: 0 | EP578: 0 | EQ578: 0.009 | ER578: 0 | ES578: 0 | ET578: 0.965 | EU578: 2.979 | EV578: 0 | EW578: 0.005 | EX578: 0.022 | EY578: 0.051 | EZ578: 0 | FA578: 0.018 | FB578: 0 | FC578: 0.001 | FD578: 0 | FE578: 0.001 | FF578: 0 | FG578: 0 | FH578: 0 | FI578: 0.016 | FJ578: 0 | FK578: 0 | FL578: 1.143 | FM578: 3.532 | FN578: 0 | FO578: 0.006 | FP578: 0.027 | FQ578: 0.061 | FR578: 0 | FS578: 0.021 | FT578: 0 | FU578: 0.001 | FV578: 0 | FW578: 0.002 | FX578: 0 | FY578: 0.001 | FZ578: 0 | GA578: 0.021 | GB578: 0 | GC578: 0 | GD578: 1.28 | GE578: 3.958 | GF578: 0 | GG578: 0.007 | GH578: 0.031 | GI578: 0.069 | GJ578: 0 | GK578: 0.024 | GL578: 0 | GM578: 0.001 | GN578: 0 | GO578: 0.003 | GP578: 0 | GQ578: 0.001 | GR578: 0 | GS578: 0.024 | GT578: 0 | GU578: 0 | GV578: 1.317 | GW578: 4.075 | GX578: 0 | GY578: 0.007 | GZ578: 0.032 | HA578: 0.071 | HB578: 0 | HC578: 0.025 | HD578: 0 | HE578: 0.001 | HF578: 0 | HG578: 0.003 | HH578: 0 | HI578: 0.001 | HJ578: 0 | HK578: 0 | HL578: 0 | HM578: 0 | HN578: 0.189 | HO578: 0.802 | HP578: 0 | HQ578: 0.001 | HR578: 0.002 | HS578: 0.006 | HT578: 0 | HU578: 0.003 | HV578: 0 | HW578: 0 | HX578: 0 | HY578: 0.001 | HZ578: 0 | IA578: 0

Sheet Peak Inflow Outflow
A1: return_period | B1: Hawasinah 02 Reservoir Inflow Max (m3/s) | C1: Hawasinah 02 Reservoir Outflow Max (m3/s) | D1: Hawasinah 11 Reservoir Inflow Max (m3/s) | E1: Hawasinah 11 Reservoir Outflow Max (m3/s) | F1: Hawasinah UP Reservoir Inflow Max (m3/s) | G1: Hawasinah UP Reservoir Outflow Max (m3/s) | H1: Shafan 02 Reservoir Inflow Max (m3/s) | I1: Shafan 02 Reservoir Outflow Max (m3/s) | J1: Shafan 08 Reservoir Inflow Max (m3/s) | K1: Shafan 08 Reservoir Outflow Max (m3/s) | L1: Sarami 03 Reservoir Inflow Max (m3/s) | M1: Sarami 03 Reservoir Outflow Max (m3/s) | N1: Sarami 05 Reservoir Inflow Max (m3/s) | O1: Sarami 05 Reservoir Outflow Max (m3/s) | P1: Sakhin 04 Reservoir Inflow Max (m3/s) | Q1: Sakhin 04 Reservoir Outflow Max (m3/s) | R1: Sakhin 08 (Mehmum) Reservoir Inflow Max (m3/s) | S1: Sakhin 08 (Mehmum) Reservoir Outflow Max (m3/s)
A2: 2yr | B2: =MAX(Hydrographs!B2:B578) -> 98.004 | C2: =MAX(Hydrographs!C2:C578) -> 0 | D2: =MAX(Hydrographs!D2:D578) -> 98.545 | E2: =MAX(Hydrographs!E2:E578) -> 0 | F2: =MAX(Hydrographs!F2:F578) -> 22.72 | G2: =MAX(Hydrographs!G2:G578) -> 0 | H2: =MAX(Hydrographs!H2:H578) -> 85.635 | I2: =MAX(Hydrographs!I2:I578) -> 0 | ... S2: =MAX(Hydrographs!S2:S578) -> 0
A3: 5yr | B3: =MAX(Hydrographs!T2:T578) -> 412.132 | C3: =MAX(Hydrographs!U2:U578) -> 0 | D3: =MAX(Hydrographs!V2:V578) -> 370.385 | E3: =MAX(Hydrographs!W2:W578) -> 0 | F3: =MAX(Hydrographs!X2:X578) -> 120.29 | G3: =MAX(Hydrographs!Y2:Y578) -> 0 | H3: =MAX(Hydrographs!Z2:Z578) -> 318.828 | I3: =MAX(Hydrographs!AA2:AA578) -> 0 | ... S3: =MAX(Hydrographs!AK2:AK578) -> 0
A4: 10yr | B4: =MAX(Hydrographs!AL2:AL578) -> 1213.95 | C4: =MAX(Hydrographs!AM2:AM578) -> 725.462 | D4: =MAX(Hydrographs!AN2:AN578) -> 862.027 | E4: =MAX(Hydrographs!AO2:AO578) -> 0 | F4: =MAX(Hydrographs!AP2:AP578) -> 569.685 | G4: =MAX(Hydrographs!AQ2:AQ578) -> 0 | H4: =MAX(Hydrographs!AR2:AR578) -> 912.717 | I4: =MAX(Hydrographs!AS2:AS578) -> 0 | ... S4: =MAX(Hydrographs!BC2:BC578) -> 0
A5: 25yr | B5: =MAX(Hydrographs!BD2:BD578) -> 1801.097 | C5: =MAX(Hydrographs!BE2:BE578) -> 1428.879 | D5: =MAX(Hydrographs!BF2:BF578) -> 1231.241 | E5: =MAX(Hydrographs!BG2:BG578) -> 0 | F5: =MAX(Hydrographs!BH2:BH578) -> 1239.652 | G5: =MAX(Hydrographs!BI2:BI578) -> 0 | H5: =MAX(Hydrographs!BJ2:BJ578) -> 1347.764 | I5: =MAX(Hydrographs!BK2:BK578) -> 0 | ... S5: =MAX(Hydrographs!BU2:BU578) -> 17.758
A6: 50yr | B6: =MAX(Hydrographs!BV2:BV578) -> 2379.246 | C6: =MAX(Hydrographs!BW2:BW578) -> 2142.707 | D6: =MAX(Hydrographs!BX2:BX578) -> 1591.155 | E6: =MAX(Hydrographs!BY2:BY578) -> 0 | F6: =MAX(Hydrographs!BZ2:BZ578) -> 1975.312 | G6: =MAX(Hydrographs!CA2:CA578) -> 0 | H6: =MAX(Hydrographs!CB2:CB578) -> 1772.895 | I6: =MAX(Hydrographs!CC2:CC578) -> 0 | ... S6: =MAX(Hydrographs!CM2:CM578) -> 91.456
A7: 100yr | B7: =MAX(Hydrographs!CN2:CN578) -> 3093.109 | C7: =MAX(Hydrographs!CO2:CO578) -> 2952.924 | D7: =MAX(Hydrographs!CP2:CP578) -> 2042.438 | E7: =MAX(Hydrographs!CQ2:CQ578) -> 14.824 | F7: =MAX(Hydrographs!CR2:CR578) -> 2936.004 | G7: =MAX(Hydrographs!CS2:CS578) -> 0 | H7: =MAX(Hydrographs!CT2:CT578) -> 2283.27 | I7: =MAX(Hydrographs!CU2:CU578) -> 0 | ... S7: =MAX(Hydrographs!DE2:DE578) -> 241.478
A8: 200yr | B8: =MAX(Hydrographs!DF2:DF578) -> 3970.854 | C8: =MAX(Hydrographs!DG2:DG578) -> 3886.947 | D8: =MAX(Hydrographs!DH2:DH578) -> 2601.948 | E8: =MAX(Hydrographs!DI2:DI578) -> 325.354 | F8: =MAX(Hydrographs!DJ2:DJ578) -> 4109.481 | G8: =MAX(Hydrographs!DK2:DK578) -> 158.563 | H8: =MAX(Hydrographs!DL2:DL578) -> 2890.121 | I8: =MAX(Hydrographs!DM2:DM578) -> 0 | ... S8: =MAX(Hydrographs!DW2:DW578) -> 468.128
A9: 500yr | B9: =MAX(Hydrographs!DX2:DX578) -> 5450.715 | C9: =MAX(Hydrographs!DY2:DY578) -> 5369.392 | D9: =MAX(Hydrographs!DZ2:DZ578) -> 3539.115 | E9: =MAX(Hydrographs!EA2:EA578) -> 1403.867 | F9: =MAX(Hydrographs!EB2:EB578) -> 6015.831 | G9: =MAX(Hydrographs!EC2:EC578) -> 1618.26 | H9: =MAX(Hydrographs!ED2:ED578) -> 3888.475 | I9: =MAX(Hydrographs!EE2:EE578) -> 528.003 | ... S9: =MAX(Hydrographs!EO2:EO578) -> 879.577
A10: 1000yr | B10: =MAX(Hydrographs!EP2:EP578) -> 6862.859 | C10: =MAX(Hydrographs!EQ2:EQ578) -> 6772.181 | D10: =MAX(Hydrographs!ER2:ER578) -> 4465.275 | E10: =MAX(Hydrographs!ES2:ES578) -> 2756.711 | F10: =MAX(Hydrographs!ET2:ET578) -> 7726.682 | G10: =MAX(Hydrographs!EU2:EU578) -> 3726.109 | H10: =MAX(Hydrographs!EV2:EV578) -> 4830.088 | I10: =MAX(Hydrographs!EW2:EW578) -> 1398.304 | ... S10: =MAX(Hydrographs!FG2:FG578) -> 1253.655
A11: 2000yr | B11: =MAX(Hydrographs!FH2:FH578) -> 7821.014 | C11: =MAX(Hydrographs!FI2:FI578) -> 7729.882 | D11: =MAX(Hydrographs!FJ2:FJ578) -> 5083.416 | E11: =MAX(Hydrographs!FK2:FK578) -> 4087.077 | F11: =MAX(Hydrographs!FL2:FL578) -> 10004.047 | G11: =MAX(Hydrographs!FM2:FM578) -> 6442.087 | H11: =MAX(Hydrographs!FN2:FN578) -> 5416.32 | I11: =MAX(Hydrographs!FO2:FO578) -> 2484.65 | ... S11: =MAX(Hydrographs!FY2:FY578) -> 1563.277
A12: 5000yr | B12: =MAX(Hydrographs!FZ2:FZ578) -> 10481.969 | C12: =MAX(Hydrographs!GA2:GA578) -> 10371.475 | D12: =MAX(Hydrographs!GB2:GB578) -> 6916.565 | E12: =MAX(Hydrographs!GC2:GC578) -> 6400.333 | F12: =MAX(Hydrographs!GD2:GD578) -> 16545.717 | G12: =MAX(Hydrographs!GE2:GE578) -> 11984.103 | H12: =MAX(Hydrographs!GF2:GF578) -> 7169.841 | I12: =MAX(Hydrographs!GG2:GG578) -> 4754.651 | ... S12: =MAX(Hydrographs!GQ2:GQ578) -> 2188.898
A13: 10000yr | B13: =MAX(Hydrographs!GR2:GR578) -> 11301.827 | C13: =MAX(Hydrographs!GS2:GS578) -> 11183.735 | D13: =MAX(Hydrographs!GT2:GT578) -> 7474.054 | E13: =MAX(Hydrographs!GU2:GU578) -> 7039.194 | F13: =MAX(Hydrographs!GV2:GV578) -> 18212.382 | G13: =MAX(Hydrographs!GW2:GW578) -> 13740.964 | H13: =MAX(Hydrographs!GX2:GX578) -> 7704.531 | I13: =MAX(Hydrographs!GY2:GY578) -> 5446.861 | ... S13: =MAX(Hydrographs!HI2:HI578) -> 2372.978
A14: PMP | B14: =MAX(Hydrographs!HJ2:HJ578) -> 17808.84 | C14: =MAX(Hydrographs!HK2:HK578) -> 17750.549 | D14: =MAX(Hydrographs!HL2:HL578) -> 11766.526 | E14: =MAX(Hydrographs!HM2:HM578) -> 11608.056 | F14: =MAX(Hydrographs!HN2:HN578) -> 34602.776 | G14: =MAX(Hydrographs!HO2:HO578) -> 32933.203 | H14: =MAX(Hydrographs!HP2:HP578) -> 11086.118 | I14: =MAX(Hydrographs!HQ2:HQ578) -> 10556.296 | ... S14: =MAX(Hydrographs!IA2:IA578) -> 4681.343

Sheet Inflow Outflow Volumes
A1: return_period | B1: Hawasinah 02 Reservoir Inflow Vol (Mm3) | C1: Hawasinah 02 Reservoir Outflow Vol (Mm3) | D1: Hawasinah 11 Reservoir Inflow Vol (Mm3) | E1: Hawasinah 11 Reservoir Outflow Vol (Mm3) | F1: Hawasinah UP Reservoir Inflow Vol (Mm3) | G1: Hawasinah UP Reservoir Outflow Vol (Mm3) | H1: Shafan 02 Reservoir Inflow Vol (Mm3) | I1: Shafan 02 Reservoir Outflow Vol (Mm3) | J1: Shafan 08 Reservoir Inflow Vol (Mm3) | K1: Shafan 08 Reservoir Outflow Vol (Mm3) | L1: Sarami 03 Reservoir Inflow Vol (Mm3) | M1: Sarami 03 Reservoir Outflow Vol (Mm3) | N1: Sarami 05 Reservoir Inflow Vol (Mm3) | O1: Sarami 05 Reservoir Outflow Vol (Mm3) | P1: Sakhin 04 Reservoir Inflow Vol (Mm3) | Q1: Sakhin 04 Reservoir Outflow Vol (Mm3) | R1: Sakhin 08 (Mehmum) Reservoir Inflow Vol (Mm3) | S1: Sakhin 08 (Mehmum) Reservoir Outflow Vol (Mm3)
A2: 2yr | B2: =SUM(Hydrographs!B2:B578)*300/1000000 -> 2.6710737 | C2: =SUM(Hydrographs!C2:C578)*300/1000000 -> 0 | D2: =SUM(Hydrographs!D2:D578)*300/1000000 -> 1.751691 | E2: =SUM(Hydrographs!E2:E578)*300/1000000 -> 0 | F2: =SUM(Hydrographs!F2:F578)*300/1000000 -> 0.5859189 | G2: =SUM(Hydrographs!G2:G578)*300/1000000 -> 0 | H2: =SUM(Hydrographs!H2:H578)*300/1000000 -> 1.6692699 | I2: =SUM(Hydrographs!I2:I578)*300/1000000 -> 0 | ... S2: =SUM(Hydrographs!S2:S578)*300/1000000 -> 0
A3: 5yr | B3: =SUM(Hydrographs!T2:T578)*300/1000000 -> 9.5263287 | C3: =SUM(Hydrographs!U2:U578)*300/1000000 -> 0 | D3: =SUM(Hydrographs!V2:V578)*300/1000000 -> 5.8798341 | E3: =SUM(Hydrographs!W2:W578)*300/1000000 -> 0 | F3: =SUM(Hydrographs!X2:X578)*300/1000000 -> 2.9728623 | G3: =SUM(Hydrographs!Y2:Y578)*300/1000000 -> 0 | H3: =SUM(Hydrographs!Z2:Z578)*300/1000000 -> 5.7164736 | I3: =SUM(Hydrographs!AA2:AA578)*300/1000000 -> 0 | ... S3: =SUM(Hydrographs!AK2:AK578)*300/1000000 -> 0
A4: 10yr | B4: =SUM(Hydrographs!AL2:AL578)*300/1000000 -> 24.481785 | C4: =SUM(Hydrographs!AM2:AM578)*300/1000000 -> 14.069481 | D4: =SUM(Hydrographs!AN2:AN578)*300/1000000 -> 14.667293 | E4: =SUM(Hydrographs!AO2:AO578)*300/1000000 -> 0 | F4: =SUM(Hydrographs!AP2:AP578)*300/1000000 -> 19.747565 | G4: =SUM(Hydrographs!AQ2:AQ578)*300/1000000 -> 0 | H4: =SUM(Hydrographs!AR2:AR578)*300/1000000 -> 14.397707 | I4: =SUM(Hydrographs!AS2:AS578)*300/1000000 -> 0 | ... S4: =SUM(Hydrographs!BC2:BC578)*300/1000000 -> 0
A5: 25yr | B5: =SUM(Hydrographs!BD2:BD578)*300/1000000 -> 34.603101 | C5: =SUM(Hydrographs!BE2:BE578)*300/1000000 -> 24.190792 | D5: =SUM(Hydrographs!BF2:BF578)*300/1000000 -> 20.560718 | E5: =SUM(Hydrographs!BG2:BG578)*300/1000000 -> 0 | F5: =SUM(Hydrographs!BH2:BH578)*300/1000000 -> 32.934798 | G5: =SUM(Hydrographs!BI2:BI578)*300/1000000 -> 0 | H5: =SUM(Hydrographs!BJ2:BJ578)*300/1000000 -> 20.222669 | I5: =SUM(Hydrographs!BK2:BK578)*300/1000000 -> 0 | ... S5: =SUM(Hydrographs!BU2:BU578)*300/1000000 -> 0.3085746
A6: 50yr | B6: =SUM(Hydrographs!BV2:BV578)*300/1000000 -> 44.473407 | C6: =SUM(Hydrographs!BW2:BW578)*300/1000000 -> 34.061104 | D6: =SUM(Hydrographs!BX2:BX578)*300/1000000 -> 26.289586 | E6: =SUM(Hydrographs!BY2:BY578)*300/1000000 -> 0 | F6: =SUM(Hydrographs!BZ2:BZ578)*300/1000000 -> 45.774253 | G6: =SUM(Hydrographs!CA2:CA578)*300/1000000 -> 0 | H6: =SUM(Hydrographs!CB2:CB578)*300/1000000 -> 25.880548 | I6: =SUM(Hydrographs!CC2:CC578)*300/1000000 -> 0 | ... S6: =SUM(Hydrographs!CM2:CM578)*300/1000000 -> 2.5250061
A7: 100yr | B7: =SUM(Hydrographs!CN2:CN578)*300/1000000 -> 56.638612 | C7: =SUM(Hydrographs!CO2:CO578)*300/1000000 -> 46.226304 | D7: =SUM(Hydrographs!CP2:CP578)*300/1000000 -> 33.343353 | E7: =SUM(Hydrographs!CQ2:CQ578)*300/1000000 -> 0.1705062 | F7: =SUM(Hydrographs!CR2:CR578)*300/1000000 -> 61.86189 | G7: =SUM(Hydrographs!CS2:CS578)*300/1000000 -> 0 | H7: =SUM(Hydrographs!CT2:CT578)*300/1000000 -> 32.862919 | I7: =SUM(Hydrographs!CU2:CU578)*300/1000000 -> 0 | ... S7: =SUM(Hydrographs!DE2:DE578)*300/1000000 -> 5.2575765
A8: 200yr | B8: =SUM(Hydrographs!DF2:DF578)*300/1000000 -> 71.629888 | C8: =SUM(Hydrographs!DG2:DG578)*300/1000000 -> 61.217579 | D8: =SUM(Hydrographs!DH2:DH578)*300/1000000 -> 42.026875 | E8: =SUM(Hydrographs!DI2:DI578)*300/1000000 -> 8.8540323 | F8: =SUM(Hydrographs!DJ2:DJ578)*300/1000000 -> 82.829743 | G8: =SUM(Hydrographs!DK2:DK578)*300/1000000 -> 3.6022443 | H8: =SUM(Hydrographs!DL2:DL578)*300/1000000 -> 41.470256 | I8: =SUM(Hydrographs!DM2:DM578)*300/1000000 -> 0 | ... S8: =SUM(Hydrographs!DW2:DW578)*300/1000000 -> 8.62551
A9: 500yr | B9: =SUM(Hydrographs!DX2:DX578)*300/1000000 -> 96.847398 | C9: =SUM(Hydrographs!DY2:DY578)*300/1000000 -> 86.43508 | D9: =SUM(Hydrographs!DZ2:DZ578)*300/1000000 -> 56.617125 | E9: =SUM(Hydrographs!EA2:EA578)*300/1000000 -> 23.444282 | F9: =SUM(Hydrographs!EB2:EB578)*300/1000000 -> 128.57606 | G9: =SUM(Hydrographs!EC2:EC578)*300/1000000 -> 49.346984 | H9: =SUM(Hydrographs!ED2:ED578)*300/1000000 -> 55.942484 | I9: =SUM(Hydrographs!EE2:EE578)*300/1000000 -> 14.33525 | ... S9: =SUM(Hydrographs!EO2:EO578)*300/1000000 -> 14.290561
A10: 1000yr | B10: =SUM(Hydrographs!EP2:EP578)*300/1000000 -> 121.01005 | C10: =SUM(Hydrographs!EQ2:EQ578)*300/1000000 -> 110.59774 | D10: =SUM(Hydrographs!ER2:ER578)*300/1000000 -> 70.587133 | E10: =SUM(Hydrographs!ES2:ES578)*300/1000000 -> 37.41429 | F10: =SUM(Hydrographs!ET2:ET578)*300/1000000 -> 172.42081 | G10: =SUM(Hydrographs!EU2:EU578)*300/1000000 -> 93.190484 | H10: =SUM(Hydrographs!EV2:EV578)*300/1000000 -> 69.803968 | I10: =SUM(Hydrographs!EW2:EW578)*300/1000000 -> 28.196734 | ... S10: =SUM(Hydrographs!FG2:FG578)*300/1000000 -> 19.719021
A11: 2000yr | B11: =SUM(Hydrographs!FH2:FH578)*300/1000000 -> 150.65987 | C11: =SUM(Hydrographs!FI2:FI578)*300/1000000 -> 140.24755 | D11: =SUM(Hydrographs!FJ2:FJ578)*300/1000000 -> 87.701794 | E11: =SUM(Hydrographs!FK2:FK578)*300/1000000 -> 54.528952 | F11: =SUM(Hydrographs!FL2:FL578)*300/1000000 -> 226.36031 | G11: =SUM(Hydrographs!FM2:FM578)*300/1000000 -> 147.12728 | H11: =SUM(Hydrographs!FN2:FN578)*300/1000000 -> 86.800455 | I11: =SUM(Hydrographs!FO2:FO578)*300/1000000 -> 45.193216 | ... S11: =SUM(Hydrographs!FY2:FY578)*300/1000000 -> 26.368833
A12: 5000yr | B12: =SUM(Hydrographs!FZ2:FZ578)*300/1000000 -> 200.88869 | C12: =SUM(Hydrographs!GA2:GA578)*300/1000000 -> 190.47636 | D12: =SUM(Hydrographs!GB2:GB578)*300/1000000 -> 116.71368 | E12: =SUM(Hydrographs!GC2:GC578)*300/1000000 -> 83.540831 | F12: =SUM(Hydrographs!GD2:GD578)*300/1000000 -> 317.70102 | G12: =SUM(Hydrographs!GE2:GE578)*300/1000000 -> 238.46591 | H12: =SUM(Hydrographs!GF2:GF578)*300/1000000 -> 115.59757 | I12: =SUM(Hydrographs!GG2:GG578)*300/1000000 -> 73.990324 | ... S12: =SUM(Hydrographs!GQ2:GQ578)*300/1000000 -> 37.650684
A13: 10000yr | B13: =SUM(Hydrographs!GR2:GR578)*300/1000000 -> 216.26726 | C13: =SUM(Hydrographs!GS2:GS578)*300/1000000 -> 205.85493 | D13: =SUM(Hydrographs!GT2:GT578)*300/1000000 -> 125.59405 | E13: =SUM(Hydrographs!GU2:GU578)*300/1000000 -> 92.421207 | F13: =SUM(Hydrographs!GV2:GV578)*300/1000000 -> 345.62305 | G13: =SUM(Hydrographs!GW2:GW578)*300/1000000 -> 266.38737 | H13: =SUM(Hydrographs!GX2:GX578)*300/1000000 -> 124.41098 | I13: =SUM(Hydrographs!GY2:GY578)*300/1000000 -> 82.803731 | ... S13: =SUM(Hydrographs!HI2:HI578)*300/1000000 -> 41.104657
A14: PMP | B14: =SUM(Hydrographs!HJ2:HJ578)*300/1000000 -> 365.36566 | C14: =SUM(Hydrographs!HK2:HK578)*300/1000000 -> 354.95335 | D14: =SUM(Hydrographs!HL2:HL578)*300/1000000 -> 217.68798 | E14: =SUM(Hydrographs!HM2:HM578)*300/1000000 -> 184.51514 | F14: =SUM(Hydrographs!HN2:HN578)*300/1000000 -> 681.36476 | G14: =SUM(Hydrographs!HO2:HO578)*300/1000000 -> 602.14507 | H14: =SUM(Hydrographs!HP2:HP578)*300/1000000 -> 212.70866 | I14: =SUM(Hydrographs!HQ2:HQ578)*300/1000000 -> 171.10145 | ... S14: =SUM(Hydrographs!IA2:IA578)*300/1000000 -> 89.798089

Sheet Peak Level Attenuation
A1: return_period | B1: Hawasinah 02 peak level (m) | C1: Hawasinah 11 peak level (m) | D1: Hawasinah UP peak level (m) | E1: Shafan 02 peak level (m) | F1: Shafan 08 peak level (m) | G1: Sarami 03 peak level (m) | H1: Sarami 05 peak level (m) | I1: Sakhin 04 peak level (m) | J1: Sakhin 08 (Mehmum) peak level (m) | K1: Hawasinah 02 attenuation (%) | L1: Hawasinah 11 attenuation (%) | M1: Hawasinah UP attenuation (%) | N1: Shafan 02 attenuation (%) | O1: Shafan 08 attenuation (%) | P1: Sarami 03 attenuation (%) | Q1: Sarami 05 attenuation (%) | R1: Sakhin 04 attenuation (%) | S1: Sakhin 08 (Mehmum) attenuation (%)
A2: 2yr | B2: 137.71 | C2: 227.09 | D2: 46.23 | E2: 213.73 | F2: 158.04 | G2: 212.33 | H2: 168.1 | I2: 106.72 | J2: 132.03 | K2: =IF('Peak Inflow Outflow'!B2>0,1-'Peak Inflow Outflow'!C2/'Peak Inflow Outflow'!B2,"-") -> 1 | L2: =IF('Peak Inflow Outflow'!D2>0,1-'Peak Inflow Outflow'!E2/'Peak Inflow Outflow'!D2,"-") -> 1 | M2: =IF('Peak Inflow Outflow'!F2>0,1-'Peak Inflow Outflow'!G2/'Peak Inflow Outflow'!F2,"-") -> 1 | N2: =IF('Peak Inflow Outflow'!H2>0,1-'Peak Inflow Outflow'!I2/'Peak Inflow Outflow'!H2,"-") -> 1 | O2: =IF('Peak Inflow Outflow'!J2>0,1-'Peak Inflow Outflow'!K2/'Peak Inflow Outflow'!J2,"-") -> 1 | P2: =IF('Peak Inflow Outflow'!L2>0,1-'Peak Inflow Outflow'!M2/'Peak Inflow Outflow'!L2,"-") -> 1 | Q2: =IF('Peak Inflow Outflow'!N2>0,1-'Peak Inflow Outflow'!O2/'Peak Inflow Outflow'!N2,"-") -> 1 | R2: =IF('Peak Inflow Outflow'!P2>0,1-'Peak Inflow Outflow'!Q2/'Peak Inflow Outflow'!P2,"-") -> 1 | S2: =IF('Peak Inflow Outflow'!R2>0,1-'Peak Inflow Outflow'!S2/'Peak Inflow Outflow'!R2,"-") -> 1
A3: 5yr | B3: 143.47 | C3: 234.19 | D3: 47.86 | E3: 219.69 | F3: 160.98 | G3: 219.81 | H3: 171.51 | I3: 110.48 | J3: 134.72 | K3: =IF('Peak Inflow Outflow'!B3>0,1-'Peak Inflow Outflow'!C3/'Peak Inflow Outflow'!B3,"-") -> 1 | L3: =IF('Peak Inflow Outflow'!D3>0,1-'Peak Inflow Outflow'!E3/'Peak Inflow Outflow'!D3,"-") -> 1 | M3: =IF('Peak Inflow Outflow'!F3>0,1-'Peak Inflow Outflow'!G3/'Peak Inflow Outflow'!F3,"-") -> 1 | N3: =IF('Peak Inflow Outflow'!H3>0,1-'Peak Inflow Outflow'!I3/'Peak Inflow Outflow'!H3,"-") -> 1 | O3: =IF('Peak Inflow Outflow'!J3>0,1-'Peak Inflow Outflow'!K3/'Peak Inflow Outflow'!J3,"-") -> 1 | P3: =IF('Peak Inflow Outflow'!L3>0,1-'Peak Inflow Outflow'!M3/'Peak Inflow Outflow'!L3,"-") -> 1 | Q3: =IF('Peak Inflow Outflow'!N3>0,1-'Peak Inflow Outflow'!O3/'Peak Inflow Outflow'!N3,"-") -> 1 | R3: =IF('Peak Inflow Outflow'!P3>0,1-'Peak Inflow Outflow'!Q3/'Peak Inflow Outflow'!P3,"-") -> 1 | S3: =IF('Peak Inflow Outflow'!R3>0,1-'Peak Inflow Outflow'!S3/'Peak Inflow Outflow'!R3,"-") -> 1
A4: 10yr | B4: 144.58 | C4: 241.7 | D4: 52.53 | E4: 225.29 | F4: 163.99 | G4: 226.48 | H4: 175.16 | I4: 114.66 | J4: 137.74 | K4: =IF('Peak Inflow Outflow'!B4>0,1-'Peak Inflow Outflow'!C4/'Peak Inflow Outflow'!B4,"-") -> 0.40239549 | L4: =IF('Peak Inflow Outflow'!D4>0,1-'Peak Inflow Outflow'!E4/'Peak Inflow Outflow'!D4,"-") -> 1 | M4: =IF('Peak Inflow Outflow'!F4>0,1-'Peak Inflow Outflow'!G4/'Peak Inflow Outflow'!F4,"-") -> 1 | N4: =IF('Peak Inflow Outflow'!H4>0,1-'Peak Inflow Outflow'!I4/'Peak Inflow Outflow'!H4,"-") -> 1 | O4: =IF('Peak Inflow Outflow'!J4>0,1-'Peak Inflow Outflow'!K4/'Peak Inflow Outflow'!J4,"-") -> 1 | P4: =IF('Peak Inflow Outflow'!L4>0,1-'Peak Inflow Outflow'!M4/'Peak Inflow Outflow'!L4,"-") -> 1 | Q4: =IF('Peak Inflow Outflow'!N4>0,1-'Peak Inflow Outflow'!O4/'Peak Inflow Outflow'!N4,"-") -> 1 | R4: =IF('Peak Inflow Outflow'!P4>0,1-'Peak Inflow Outflow'!Q4/'Peak Inflow Outflow'!P4,"-") -> 1 | S4: =IF('Peak Inflow Outflow'!R4>0,1-'Peak Inflow Outflow'!S4/'Peak Inflow Outflow'!R4,"-") -> 1
A5: 25yr | B5: 144.92 | C5: 245.2 | D5: 54.72 | E5: 227.89 | F5: 165.29 | G5: 229.37 | H5: 176.92 | I5: 116.54 | J5: 139.06 | K5: =IF('Peak Inflow Outflow'!B5>0,1-'Peak Inflow Outflow'!C5/'Peak Inflow Outflow'!B5,"-") -> 0.20666183 | L5: =IF('Peak Inflow Outflow'!D5>0,1-'Peak Inflow Outflow'!E5/'Peak Inflow Outflow'!D5,"-") -> 1 | M5: =IF('Peak Inflow Outflow'!F5>0,1-'Peak Inflow Outflow'!G5/'Peak Inflow Outflow'!F5,"-") -> 1 | N5: =IF('Peak Inflow Outflow'!H5>0,1-'Peak Inflow Outflow'!I5/'Peak Inflow Outflow'!H5,"-") -> 1 | O5: =IF('Peak Inflow Outflow'!J5>0,1-'Peak Inflow Outflow'!K5/'Peak Inflow Outflow'!J5,"-") -> 1 | P5: =IF('Peak Inflow Outflow'!L5>0,1-'Peak Inflow Outflow'!M5/'Peak Inflow Outflow'!L5,"-") -> 1 | Q5: =IF('Peak Inflow Outflow'!N5>0,1-'Peak Inflow Outflow'!O5/'Peak Inflow Outflow'!N5,"-") -> 1 | R5: =IF('Peak Inflow Outflow'!P5>0,1-'Peak Inflow Outflow'!Q5/'Peak Inflow Outflow'!P5,"-") -> 1 | S5: =IF('Peak Inflow Outflow'!R5>0,1-'Peak Inflow Outflow'!S5/'Peak Inflow Outflow'!R5,"-") -> 0.96228883
A6: 50yr | B6: 145.21 | C6: 248.07 | D6: 56.44 | E6: 230.07 | F6: 166.32 | G6: 231.71 | H6: 178.39 | I6: 118.06 | J6: 139.29 | K6: =IF('Peak Inflow Outflow'!B6>0,1-'Peak Inflow Outflow'!C6/'Peak Inflow Outflow'!B6,"-") -> 0.099417631 | L6: =IF('Peak Inflow Outflow'!D6>0,1-'Peak Inflow Outflow'!E6/'Peak Inflow Outflow'!D6,"-") -> 1 | M6: =IF('Peak Inflow Outflow'!F6>0,1-'Peak Inflow Outflow'!G6/'Peak Inflow Outflow'!F6,"-") -> 1 | N6: =IF('Peak Inflow Outflow'!H6>0,1-'Peak Inflow Outflow'!I6/'Peak Inflow Outflow'!H6,"-") -> 1 | O6: =IF('Peak Inflow Outflow'!J6>0,1-'Peak Inflow Outflow'!K6/'Peak Inflow Outflow'!J6,"-") -> 1 | P6: =IF('Peak Inflow Outflow'!L6>0,1-'Peak Inflow Outflow'!M6/'Peak Inflow Outflow'!L6,"-") -> 1 | Q6: =IF('Peak Inflow Outflow'!N6>0,1-'Peak Inflow Outflow'!O6/'Peak Inflow Outflow'!N6,"-") -> 1 | R6: =IF('Peak Inflow Outflow'!P6>0,1-'Peak Inflow Outflow'!Q6/'Peak Inflow Outflow'!P6,"-") -> 1 | S6: =IF('Peak Inflow Outflow'!R6>0,1-'Peak Inflow Outflow'!S6/'Peak Inflow Outflow'!R6,"-") -> 0.84871653
